[I 2022-04-25 14:43:43.532 ServerApp] jupyterlab | extension was successfully linked.
[W 2022-04-25 14:43:43.534 NotebookApp] 'password' has moved from NotebookApp to ServerApp. This config will be passed to ServerApp. Be sure to update your config before our next release.
[I 2022-04-25 14:43:43.616 ServerApp] nbclassic | extension was successfully linked.
[I 2022-04-25 14:43:43.640 ServerApp] nbclassic | extension was successfully loaded.
[I 2022-04-25 14:43:43.641 LabApp] JupyterLab extension loaded from /home/martinm/nib_ckn/venv/lib/python3.8/site-packages/jupyterlab
[I 2022-04-25 14:43:43.641 LabApp] JupyterLab application directory is /home/martinm/nib_ckn/venv/share/jupyter/lab
[I 2022-04-25 14:43:43.643 ServerApp] jupyterlab | extension was successfully loaded.
[I 2022-04-25 14:43:43.643 ServerApp] Serving notebooks from local directory: /home/martinm/nib_ckn
[I 2022-04-25 14:43:43.643 ServerApp] Jupyter Server 1.11.2 is running at:
[I 2022-04-25 14:43:43.643 ServerApp] http://localhost:8889/lab
[I 2022-04-25 14:43:43.643 ServerApp]  or http://127.0.0.1:8889/lab
[I 2022-04-25 14:43:43.643 ServerApp] Use Control-C to stop this server and shut down all kernels (twice to skip confirmation).
[W 2022-04-25 14:45:21.281 LabApp] Could not determine jupyterlab build status without nodejs
[I 2022-04-25 14:45:22.905 ServerApp] Kernel started: aa9c2b36-e3fe-4c2b-88d3-91ff76e1852c
[I 2022-04-25 14:47:44.843 ServerApp] Kernel restarted: aa9c2b36-e3fe-4c2b-88d3-91ff76e1852c
2022-04-25 14:47:49.606550: I tensorflow/core/platform/cpu_feature_guard.cc:151] This TensorFlow binary is optimized with oneAPI Deep Neural Network Library (oneDNN) to use the following CPU instructions in performance-critical operations:  AVX2 FMA
To enable them in other operations, rebuild TensorFlow with the appropriate compiler flags.
[I 2022-04-25 14:48:08.966 ServerApp] Creating new directory in /notebooks
[W 2022-04-25 14:48:15.535 ServerApp] delete /notebooks/Untitled Folder
[I 2022-04-25 14:49:04.021 ServerApp] New terminal with automatic name: 1
TermSocket.open: 1
not able to serialize: expected string or bytes-like object
TermSocket.open: Opened 1
[I 2022-04-25 14:49:22.468 ServerApp] Saving file at /notebooks/CKN-LinkPred_5_0.ipynb
[I 2022-04-25 15:11:22.648 ServerApp] Saving file at /notebooks/CKN-LinkPred_5_0.ipynb
[I 2022-04-25 15:13:22.806 ServerApp] Saving file at /notebooks/CKN-LinkPred_5_0.ipynb
[I 2022-04-25 15:25:22.968 ServerApp] Saving file at /notebooks/CKN-LinkPred_5_0.ipynb
[I 2022-04-25 16:01:23.137 ServerApp] Saving file at /notebooks/CKN-LinkPred_5_0.ipynb
[I 2022-04-25 16:03:23.756 ServerApp] Saving file at /notebooks/CKN-LinkPred_5_0.ipynb
[I 2022-04-25 16:05:24.077 ServerApp] Saving file at /notebooks/CKN-LinkPred_5_0.ipynb
[I 2022-04-25 16:07:24.414 ServerApp] Saving file at /notebooks/CKN-LinkPred_5_0.ipynb
[W 2022-04-25 16:09:20.353 ServerApp] Notebook notebooks/MPS_CKN-LinkPred_3_1.ipynb is not trusted
[I 2022-04-25 16:09:21.295 ServerApp] Kernel started: 77aaaf1d-c075-4e5e-9648-aea8a693a00d
[I 2022-04-25 16:09:25.160 ServerApp] Saving file at /notebooks/CKN-LinkPred_5_0.ipynb
[W 2022-04-25 16:10:30.658 ServerApp] Notebook notebooks/CKN-LinkPred_4_1.ipynb is not trusted
[I 2022-04-25 16:10:31.554 ServerApp] Kernel started: cd078e93-ae5b-45fa-a577-cbc56f758b9e
[I 2022-04-25 16:12:31.932 ServerApp] Saving file at /notebooks/CKN-LinkPred_4_1.ipynb
[W 2022-04-25 16:12:31.933 ServerApp] Notebook notebooks/CKN-LinkPred_4_1.ipynb is not trusted
[I 2022-04-25 16:23:25.559 ServerApp] Saving file at /notebooks/CKN-LinkPred_5_0.ipynb
[I 2022-04-25 16:25:25.866 ServerApp] Saving file at /notebooks/CKN-LinkPred_5_0.ipynb
[I 2022-04-25 16:31:26.160 ServerApp] Saving file at /notebooks/CKN-LinkPred_5_0.ipynb
[I 2022-04-25 16:32:05.700 ServerApp] Copying notebooks/CKN-LinkPred_5_0.ipynb to /notebooks
[I 2022-04-25 16:32:20.108 ServerApp] Kernel started: 6c439cfd-703e-45d9-8a48-582745948072
[I 2022-04-25 16:33:26.487 ServerApp] Saving file at /notebooks/CKN-LinkPred_5_0.ipynb
[I 2022-04-25 16:34:20.776 ServerApp] Saving file at /notebooks/CKN-LinkPred_5_1.ipynb
2022-04-25 16:35:53.049082: I tensorflow/core/platform/cpu_feature_guard.cc:151] This TensorFlow binary is optimized with oneAPI Deep Neural Network Library (oneDNN) to use the following CPU instructions in performance-critical operations:  AVX2 FMA
To enable them in other operations, rebuild TensorFlow with the appropriate compiler flags.
[I 2022-04-25 16:36:22.658 ServerApp] Saving file at /notebooks/CKN-LinkPred_5_1.ipynb
[I 2022-04-25 16:38:22.989 ServerApp] Saving file at /notebooks/CKN-LinkPred_5_1.ipynb
[I 2022-04-25 16:41:28.603 ServerApp] Saving file at /notebooks/CKN-LinkPred_5_0.ipynb
[I 2022-04-25 16:45:32.031 ServerApp] Saving file at /data/AtCKN_2022-01-26.tsv
[W 2022-04-25 16:45:45.153 ServerApp] delete /data/AtCKN_2022-01-26_fully-undirected.tsv.gz
[W 2022-04-25 16:45:45.172 ServerApp] delete /data/AtCKN_2022-01-26.tsv.gz
[I 2022-04-25 16:46:08.262 ServerApp] Saving file at /data/AtCKN_2022-01-26_fully-undirected.tsv
[I 2022-04-25 17:02:18.213 ServerApp] Kernel restarted: 6c439cfd-703e-45d9-8a48-582745948072
[I 2022-04-25 17:02:20.832 ServerApp] Starting buffering for 6c439cfd-703e-45d9-8a48-582745948072:cec7849d-c939-43e6-b644-8162a543af62
[I 2022-04-25 17:02:20.843 ServerApp] Restoring connection for 6c439cfd-703e-45d9-8a48-582745948072:cec7849d-c939-43e6-b644-8162a543af62
[I 2022-04-25 17:02:23.204 ServerApp] Saving file at /notebooks/CKN-LinkPred_5_1.ipynb
2022-04-25 17:02:25.131656: I tensorflow/core/platform/cpu_feature_guard.cc:151] This TensorFlow binary is optimized with oneAPI Deep Neural Network Library (oneDNN) to use the following CPU instructions in performance-critical operations:  AVX2 FMA
To enable them in other operations, rebuild TensorFlow with the appropriate compiler flags.
[I 2022-04-25 17:04:24.464 ServerApp] Saving file at /notebooks/CKN-LinkPred_5_1.ipynb
[I 2022-04-25 17:05:47.557 ServerApp] Starting buffering for 77aaaf1d-c075-4e5e-9648-aea8a693a00d:9595c8b6-93b9-4d97-8e47-265fcdc62b88
[I 2022-04-25 17:05:50.388 ServerApp] Starting buffering for cd078e93-ae5b-45fa-a577-cbc56f758b9e:78ed5742-391a-4ab0-bbd2-ef304f2b636d
[I 2022-04-25 17:14:29.603 ServerApp] Starting buffering for 6c439cfd-703e-45d9-8a48-582745948072:cec7849d-c939-43e6-b644-8162a543af62
Websocket closed
[I 2022-04-25 17:14:29.611 ServerApp] Starting buffering for aa9c2b36-e3fe-4c2b-88d3-91ff76e1852c:6f3851a6-f21b-44b4-bdce-1e9235192a9c
[I 2022-04-25 17:14:29.741 ServerApp] Restoring connection for 6c439cfd-703e-45d9-8a48-582745948072:cec7849d-c939-43e6-b644-8162a543af62
TermSocket.open: 1
not able to serialize: expected string or bytes-like object
TermSocket.open: Opened 1
[I 2022-04-25 17:14:29.773 ServerApp] Restoring connection for aa9c2b36-e3fe-4c2b-88d3-91ff76e1852c:6f3851a6-f21b-44b4-bdce-1e9235192a9c
[W 2022-04-25 17:14:34.249 ServerApp] Nudge: attempt 10 on kernel 6c439cfd-703e-45d9-8a48-582745948072
[W 2022-04-25 17:14:39.260 ServerApp] Nudge: attempt 20 on kernel 6c439cfd-703e-45d9-8a48-582745948072
[W 2022-04-25 17:14:44.269 ServerApp] Nudge: attempt 30 on kernel 6c439cfd-703e-45d9-8a48-582745948072
[W 2022-04-25 17:14:49.277 ServerApp] Nudge: attempt 40 on kernel 6c439cfd-703e-45d9-8a48-582745948072
[W 2022-04-25 17:14:54.286 ServerApp] Nudge: attempt 50 on kernel 6c439cfd-703e-45d9-8a48-582745948072
[W 2022-04-25 17:14:59.294 ServerApp] Nudge: attempt 60 on kernel 6c439cfd-703e-45d9-8a48-582745948072
[W 2022-04-25 17:15:04.301 ServerApp] Nudge: attempt 70 on kernel 6c439cfd-703e-45d9-8a48-582745948072
[W 2022-04-25 17:15:09.309 ServerApp] Nudge: attempt 80 on kernel 6c439cfd-703e-45d9-8a48-582745948072
[W 2022-04-25 17:15:14.318 ServerApp] Nudge: attempt 90 on kernel 6c439cfd-703e-45d9-8a48-582745948072
[W 2022-04-25 17:15:19.325 ServerApp] Nudge: attempt 100 on kernel 6c439cfd-703e-45d9-8a48-582745948072
[W 2022-04-25 17:15:24.332 ServerApp] Nudge: attempt 110 on kernel 6c439cfd-703e-45d9-8a48-582745948072
[W 2022-04-25 17:15:29.342 ServerApp] Nudge: attempt 120 on kernel 6c439cfd-703e-45d9-8a48-582745948072
[E 2022-04-25 17:15:29.741 ServerApp] Uncaught exception GET /api/kernels/6c439cfd-703e-45d9-8a48-582745948072/channels?session_id=cec7849d-c939-43e6-b644-8162a543af62 (127.0.0.1)
    HTTPServerRequest(protocol='http', host='localhost:9001', method='GET', uri='/api/kernels/6c439cfd-703e-45d9-8a48-582745948072/channels?session_id=cec7849d-c939-43e6-b644-8162a543af62', version='HTTP/1.1', remote_ip='127.0.0.1')
    Traceback (most recent call last):
      File "/home/martinm/nib_ckn/venv/lib/python3.8/site-packages/tornado/websocket.py", line 956, in _accept_connection
        await open_result
      File "/usr/lib/python3.8/asyncio/tasks.py", line 349, in __wakeup
        future.result()
    tornado.util.TimeoutError: Timeout
[W 2022-04-25 17:15:59.742 ServerApp] WebSocket ping timeout after 90001 ms.
[W 2022-04-25 17:15:59.757 ServerApp] WebSocket ping timeout after 90000 ms.
[W 2022-04-25 17:15:59.774 ServerApp] WebSocket ping timeout after 90000 ms.
Exception in callback BaseAsyncIOLoop._handle_events(41, 1)
handle: <Handle BaseAsyncIOLoop._handle_events(41, 1)>
Traceback (most recent call last):
  File "/usr/lib/python3.8/asyncio/events.py", line 81, in _run
    self._context.run(self._callback, *self._args)
  File "/home/martinm/nib_ckn/venv/lib/python3.8/site-packages/tornado/platform/asyncio.py", line 189, in _handle_events
    handler_func(fileobj, events)
  File "/home/martinm/nib_ckn/venv/lib/python3.8/site-packages/terminado/management.py", line 239, in pty_read
    client.on_pty_read(s)
  File "/home/martinm/nib_ckn/venv/lib/python3.8/site-packages/terminado/websocket.py", line 77, in on_pty_read
    self.send_json_message(['stdout', text])
  File "/home/martinm/nib_ckn/venv/lib/python3.8/site-packages/terminado/websocket.py", line 87, in send_json_message
    self.write_message(json_msg)
  File "/home/martinm/nib_ckn/venv/lib/python3.8/site-packages/jupyter_server/terminal/handlers.py", line 32, in write_message
    super(TermSocket, self).write_message(message, binary=binary)
  File "/home/martinm/nib_ckn/venv/lib/python3.8/site-packages/tornado/websocket.py", line 337, in write_message
    raise WebSocketClosedError()
tornado.websocket.WebSocketClosedError
Exception in callback BaseAsyncIOLoop._handle_events(41, 1)
handle: <Handle BaseAsyncIOLoop._handle_events(41, 1)>
Traceback (most recent call last):
  File "/usr/lib/python3.8/asyncio/events.py", line 81, in _run
    self._context.run(self._callback, *self._args)
  File "/home/martinm/nib_ckn/venv/lib/python3.8/site-packages/tornado/platform/asyncio.py", line 189, in _handle_events
    handler_func(fileobj, events)
  File "/home/martinm/nib_ckn/venv/lib/python3.8/site-packages/terminado/management.py", line 239, in pty_read
    client.on_pty_read(s)
  File "/home/martinm/nib_ckn/venv/lib/python3.8/site-packages/terminado/websocket.py", line 77, in on_pty_read
    self.send_json_message(['stdout', text])
  File "/home/martinm/nib_ckn/venv/lib/python3.8/site-packages/terminado/websocket.py", line 87, in send_json_message
    self.write_message(json_msg)
  File "/home/martinm/nib_ckn/venv/lib/python3.8/site-packages/jupyter_server/terminal/handlers.py", line 32, in write_message
    super(TermSocket, self).write_message(message, binary=binary)
  File "/home/martinm/nib_ckn/venv/lib/python3.8/site-packages/tornado/websocket.py", line 337, in write_message
    raise WebSocketClosedError()
tornado.websocket.WebSocketClosedError
Exception in callback BaseAsyncIOLoop._handle_events(41, 1)
handle: <Handle BaseAsyncIOLoop._handle_events(41, 1)>
Traceback (most recent call last):
  File "/usr/lib/python3.8/asyncio/events.py", line 81, in _run
    self._context.run(self._callback, *self._args)
  File "/home/martinm/nib_ckn/venv/lib/python3.8/site-packages/tornado/platform/asyncio.py", line 189, in _handle_events
    handler_func(fileobj, events)
  File "/home/martinm/nib_ckn/venv/lib/python3.8/site-packages/terminado/management.py", line 239, in pty_read
    client.on_pty_read(s)
  File "/home/martinm/nib_ckn/venv/lib/python3.8/site-packages/terminado/websocket.py", line 77, in on_pty_read
    self.send_json_message(['stdout', text])
  File "/home/martinm/nib_ckn/venv/lib/python3.8/site-packages/terminado/websocket.py", line 87, in send_json_message
    self.write_message(json_msg)
  File "/home/martinm/nib_ckn/venv/lib/python3.8/site-packages/jupyter_server/terminal/handlers.py", line 32, in write_message
    super(TermSocket, self).write_message(message, binary=binary)
  File "/home/martinm/nib_ckn/venv/lib/python3.8/site-packages/tornado/websocket.py", line 337, in write_message
    raise WebSocketClosedError()
tornado.websocket.WebSocketClosedError
Exception in callback BaseAsyncIOLoop._handle_events(41, 1)
handle: <Handle BaseAsyncIOLoop._handle_events(41, 1)>
Traceback (most recent call last):
  File "/usr/lib/python3.8/asyncio/events.py", line 81, in _run
    self._context.run(self._callback, *self._args)
  File "/home/martinm/nib_ckn/venv/lib/python3.8/site-packages/tornado/platform/asyncio.py", line 189, in _handle_events
    handler_func(fileobj, events)
  File "/home/martinm/nib_ckn/venv/lib/python3.8/site-packages/terminado/management.py", line 239, in pty_read
    client.on_pty_read(s)
  File "/home/martinm/nib_ckn/venv/lib/python3.8/site-packages/terminado/websocket.py", line 77, in on_pty_read
    self.send_json_message(['stdout', text])
  File "/home/martinm/nib_ckn/venv/lib/python3.8/site-packages/terminado/websocket.py", line 87, in send_json_message
    self.write_message(json_msg)
  File "/home/martinm/nib_ckn/venv/lib/python3.8/site-packages/jupyter_server/terminal/handlers.py", line 32, in write_message
    super(TermSocket, self).write_message(message, binary=binary)
  File "/home/martinm/nib_ckn/venv/lib/python3.8/site-packages/tornado/websocket.py", line 337, in write_message
    raise WebSocketClosedError()
tornado.websocket.WebSocketClosedError
Websocket closed
[I 2022-04-25 17:16:04.775 ServerApp] Starting buffering for aa9c2b36-e3fe-4c2b-88d3-91ff76e1852c:6f3851a6-f21b-44b4-bdce-1e9235192a9c
[W 2022-04-25 17:16:51.762 ServerApp] Replacing stale connection: 6c439cfd-703e-45d9-8a48-582745948072:cec7849d-c939-43e6-b644-8162a543af62
TermSocket.open: 1
not able to serialize: expected string or bytes-like object
TermSocket.open: Opened 1
[I 2022-04-25 17:16:52.085 ServerApp] Restoring connection for aa9c2b36-e3fe-4c2b-88d3-91ff76e1852c:6f3851a6-f21b-44b4-bdce-1e9235192a9c
[W 2022-04-25 17:18:22.067 ServerApp] WebSocket ping timeout after 90001 ms.
[W 2022-04-25 17:18:22.087 ServerApp] WebSocket ping timeout after 90001 ms.
Exception in callback BaseAsyncIOLoop._handle_events(41, 1)
handle: <Handle BaseAsyncIOLoop._handle_events(41, 1)>
Traceback (most recent call last):
  File "/usr/lib/python3.8/asyncio/events.py", line 81, in _run
    self._context.run(self._callback, *self._args)
  File "/home/martinm/nib_ckn/venv/lib/python3.8/site-packages/tornado/platform/asyncio.py", line 189, in _handle_events
    handler_func(fileobj, events)
  File "/home/martinm/nib_ckn/venv/lib/python3.8/site-packages/terminado/management.py", line 239, in pty_read
    client.on_pty_read(s)
  File "/home/martinm/nib_ckn/venv/lib/python3.8/site-packages/terminado/websocket.py", line 77, in on_pty_read
    self.send_json_message(['stdout', text])
  File "/home/martinm/nib_ckn/venv/lib/python3.8/site-packages/terminado/websocket.py", line 87, in send_json_message
    self.write_message(json_msg)
  File "/home/martinm/nib_ckn/venv/lib/python3.8/site-packages/jupyter_server/terminal/handlers.py", line 32, in write_message
    super(TermSocket, self).write_message(message, binary=binary)
  File "/home/martinm/nib_ckn/venv/lib/python3.8/site-packages/tornado/websocket.py", line 337, in write_message
    raise WebSocketClosedError()
tornado.websocket.WebSocketClosedError
Exception in callback BaseAsyncIOLoop._handle_events(41, 1)
handle: <Handle BaseAsyncIOLoop._handle_events(41, 1)>
Traceback (most recent call last):
  File "/usr/lib/python3.8/asyncio/events.py", line 81, in _run
    self._context.run(self._callback, *self._args)
  File "/home/martinm/nib_ckn/venv/lib/python3.8/site-packages/tornado/platform/asyncio.py", line 189, in _handle_events
    handler_func(fileobj, events)
  File "/home/martinm/nib_ckn/venv/lib/python3.8/site-packages/terminado/management.py", line 239, in pty_read
    client.on_pty_read(s)
  File "/home/martinm/nib_ckn/venv/lib/python3.8/site-packages/terminado/websocket.py", line 77, in on_pty_read
    self.send_json_message(['stdout', text])
  File "/home/martinm/nib_ckn/venv/lib/python3.8/site-packages/terminado/websocket.py", line 87, in send_json_message
    self.write_message(json_msg)
  File "/home/martinm/nib_ckn/venv/lib/python3.8/site-packages/jupyter_server/terminal/handlers.py", line 32, in write_message
    super(TermSocket, self).write_message(message, binary=binary)
  File "/home/martinm/nib_ckn/venv/lib/python3.8/site-packages/tornado/websocket.py", line 337, in write_message
    raise WebSocketClosedError()
tornado.websocket.WebSocketClosedError
Exception in callback BaseAsyncIOLoop._handle_events(41, 1)
handle: <Handle BaseAsyncIOLoop._handle_events(41, 1)>
Traceback (most recent call last):
  File "/usr/lib/python3.8/asyncio/events.py", line 81, in _run
    self._context.run(self._callback, *self._args)
  File "/home/martinm/nib_ckn/venv/lib/python3.8/site-packages/tornado/platform/asyncio.py", line 189, in _handle_events
    handler_func(fileobj, events)
  File "/home/martinm/nib_ckn/venv/lib/python3.8/site-packages/terminado/management.py", line 239, in pty_read
    client.on_pty_read(s)
  File "/home/martinm/nib_ckn/venv/lib/python3.8/site-packages/terminado/websocket.py", line 77, in on_pty_read
    self.send_json_message(['stdout', text])
  File "/home/martinm/nib_ckn/venv/lib/python3.8/site-packages/terminado/websocket.py", line 87, in send_json_message
    self.write_message(json_msg)
  File "/home/martinm/nib_ckn/venv/lib/python3.8/site-packages/jupyter_server/terminal/handlers.py", line 32, in write_message
    super(TermSocket, self).write_message(message, binary=binary)
  File "/home/martinm/nib_ckn/venv/lib/python3.8/site-packages/tornado/websocket.py", line 337, in write_message
    raise WebSocketClosedError()
tornado.websocket.WebSocketClosedError
Exception in callback BaseAsyncIOLoop._handle_events(41, 1)
handle: <Handle BaseAsyncIOLoop._handle_events(41, 1)>
Traceback (most recent call last):
  File "/usr/lib/python3.8/asyncio/events.py", line 81, in _run
    self._context.run(self._callback, *self._args)
  File "/home/martinm/nib_ckn/venv/lib/python3.8/site-packages/tornado/platform/asyncio.py", line 189, in _handle_events
    handler_func(fileobj, events)
  File "/home/martinm/nib_ckn/venv/lib/python3.8/site-packages/terminado/management.py", line 239, in pty_read
    client.on_pty_read(s)
  File "/home/martinm/nib_ckn/venv/lib/python3.8/site-packages/terminado/websocket.py", line 77, in on_pty_read
    self.send_json_message(['stdout', text])
  File "/home/martinm/nib_ckn/venv/lib/python3.8/site-packages/terminado/websocket.py", line 87, in send_json_message
    self.write_message(json_msg)
  File "/home/martinm/nib_ckn/venv/lib/python3.8/site-packages/jupyter_server/terminal/handlers.py", line 32, in write_message
    super(TermSocket, self).write_message(message, binary=binary)
  File "/home/martinm/nib_ckn/venv/lib/python3.8/site-packages/tornado/websocket.py", line 337, in write_message
    raise WebSocketClosedError()
tornado.websocket.WebSocketClosedError
Websocket closed
[I 2022-04-25 17:18:27.088 ServerApp] Starting buffering for aa9c2b36-e3fe-4c2b-88d3-91ff76e1852c:6f3851a6-f21b-44b4-bdce-1e9235192a9c
[I 2022-04-25 17:32:52.180 ServerApp] Starting buffering for 6c439cfd-703e-45d9-8a48-582745948072:cec7849d-c939-43e6-b644-8162a543af62
[W 2022-04-25 17:38:28.713 ServerApp] zmq message arrived on closed channel
[W 2022-04-25 17:38:28.718 ServerApp] zmq message arrived on closed channel
[W 2022-04-25 17:38:28.735 ServerApp] zmq message arrived on closed channel
[W 2022-04-25 17:38:28.884 ServerApp] zmq message arrived on closed channel
[W 2022-04-25 17:38:28.887 ServerApp] zmq message arrived on closed channel
[W 2022-04-25 17:38:28.888 ServerApp] zmq message arrived on closed channel
[W 2022-04-25 17:38:28.890 ServerApp] zmq message arrived on closed channel
[W 2022-04-25 17:38:28.891 ServerApp] zmq message arrived on closed channel
[W 2022-04-25 17:38:28.892 ServerApp] zmq message arrived on closed channel
[W 2022-04-25 17:38:28.893 ServerApp] zmq message arrived on closed channel
[W 2022-04-25 17:38:28.894 ServerApp] zmq message arrived on closed channel
[W 2022-04-25 17:38:28.895 ServerApp] zmq message arrived on closed channel
[W 2022-04-25 17:38:28.896 ServerApp] zmq message arrived on closed channel
[W 2022-04-25 17:38:28.897 ServerApp] zmq message arrived on closed channel
[W 2022-04-25 17:38:28.898 ServerApp] zmq message arrived on closed channel
[W 2022-04-25 17:38:28.899 ServerApp] zmq message arrived on closed channel
[W 2022-04-25 17:38:28.901 ServerApp] zmq message arrived on closed channel
[W 2022-04-25 17:38:28.902 ServerApp] zmq message arrived on closed channel
[W 2022-04-25 17:38:28.903 ServerApp] zmq message arrived on closed channel
[W 2022-04-25 17:38:28.904 ServerApp] zmq message arrived on closed channel
[W 2022-04-25 17:38:28.905 ServerApp] zmq message arrived on closed channel
[W 2022-04-25 17:38:28.906 ServerApp] zmq message arrived on closed channel
[W 2022-04-25 17:38:28.907 ServerApp] zmq message arrived on closed channel
[W 2022-04-25 17:38:28.909 ServerApp] zmq message arrived on closed channel
[W 2022-04-25 17:38:28.910 ServerApp] zmq message arrived on closed channel
[W 2022-04-25 17:38:28.911 ServerApp] zmq message arrived on closed channel
[W 2022-04-25 17:38:28.912 ServerApp] zmq message arrived on closed channel
[W 2022-04-25 17:38:28.913 ServerApp] zmq message arrived on closed channel
[W 2022-04-25 17:38:28.914 ServerApp] zmq message arrived on closed channel
[I 2022-04-26 11:30:35.580 ServerApp] 302 GET / (127.0.0.1) 0.39ms
[W 2022-04-26 11:30:37.334 LabApp] Could not determine jupyterlab build status without nodejs
TermSocket.open: 1
not able to serialize: expected string or bytes-like object
TermSocket.open: Opened 1
[W 2022-04-26 11:33:09.848 ServerApp] WebSocket ping timeout after 119990 ms.
[I 2022-04-26 11:33:14.850 ServerApp] Starting buffering for 6c439cfd-703e-45d9-8a48-582745948072:3ffd592b-5d48-4157-af12-34e63dadc381
[W 2022-04-26 11:33:37.757 ServerApp] WebSocket ping timeout after 119906 ms.
Exception in callback BaseAsyncIOLoop._handle_events(41, 1)
handle: <Handle BaseAsyncIOLoop._handle_events(41, 1)>
Traceback (most recent call last):
  File "/usr/lib/python3.8/asyncio/events.py", line 81, in _run
    self._context.run(self._callback, *self._args)
  File "/home/martinm/nib_ckn/venv/lib/python3.8/site-packages/tornado/platform/asyncio.py", line 189, in _handle_events
    handler_func(fileobj, events)
  File "/home/martinm/nib_ckn/venv/lib/python3.8/site-packages/terminado/management.py", line 239, in pty_read
    client.on_pty_read(s)
  File "/home/martinm/nib_ckn/venv/lib/python3.8/site-packages/terminado/websocket.py", line 77, in on_pty_read
    self.send_json_message(['stdout', text])
  File "/home/martinm/nib_ckn/venv/lib/python3.8/site-packages/terminado/websocket.py", line 87, in send_json_message
    self.write_message(json_msg)
  File "/home/martinm/nib_ckn/venv/lib/python3.8/site-packages/jupyter_server/terminal/handlers.py", line 32, in write_message
    super(TermSocket, self).write_message(message, binary=binary)
  File "/home/martinm/nib_ckn/venv/lib/python3.8/site-packages/tornado/websocket.py", line 337, in write_message
    raise WebSocketClosedError()
tornado.websocket.WebSocketClosedError
Exception in callback BaseAsyncIOLoop._handle_events(41, 1)
handle: <Handle BaseAsyncIOLoop._handle_events(41, 1)>
Traceback (most recent call last):
  File "/usr/lib/python3.8/asyncio/events.py", line 81, in _run
    self._context.run(self._callback, *self._args)
  File "/home/martinm/nib_ckn/venv/lib/python3.8/site-packages/tornado/platform/asyncio.py", line 189, in _handle_events
    handler_func(fileobj, events)
  File "/home/martinm/nib_ckn/venv/lib/python3.8/site-packages/terminado/management.py", line 239, in pty_read
    client.on_pty_read(s)
  File "/home/martinm/nib_ckn/venv/lib/python3.8/site-packages/terminado/websocket.py", line 77, in on_pty_read
    self.send_json_message(['stdout', text])
  File "/home/martinm/nib_ckn/venv/lib/python3.8/site-packages/terminado/websocket.py", line 87, in send_json_message
    self.write_message(json_msg)
  File "/home/martinm/nib_ckn/venv/lib/python3.8/site-packages/jupyter_server/terminal/handlers.py", line 32, in write_message
    super(TermSocket, self).write_message(message, binary=binary)
  File "/home/martinm/nib_ckn/venv/lib/python3.8/site-packages/tornado/websocket.py", line 337, in write_message
    raise WebSocketClosedError()
tornado.websocket.WebSocketClosedError
Exception in callback BaseAsyncIOLoop._handle_events(41, 1)
handle: <Handle BaseAsyncIOLoop._handle_events(41, 1)>
Traceback (most recent call last):
  File "/usr/lib/python3.8/asyncio/events.py", line 81, in _run
    self._context.run(self._callback, *self._args)
  File "/home/martinm/nib_ckn/venv/lib/python3.8/site-packages/tornado/platform/asyncio.py", line 189, in _handle_events
    handler_func(fileobj, events)
  File "/home/martinm/nib_ckn/venv/lib/python3.8/site-packages/terminado/management.py", line 239, in pty_read
    client.on_pty_read(s)
  File "/home/martinm/nib_ckn/venv/lib/python3.8/site-packages/terminado/websocket.py", line 77, in on_pty_read
    self.send_json_message(['stdout', text])
  File "/home/martinm/nib_ckn/venv/lib/python3.8/site-packages/terminado/websocket.py", line 87, in send_json_message
    self.write_message(json_msg)
  File "/home/martinm/nib_ckn/venv/lib/python3.8/site-packages/jupyter_server/terminal/handlers.py", line 32, in write_message
    super(TermSocket, self).write_message(message, binary=binary)
  File "/home/martinm/nib_ckn/venv/lib/python3.8/site-packages/tornado/websocket.py", line 337, in write_message
    raise WebSocketClosedError()
tornado.websocket.WebSocketClosedError
Websocket closed
[I 2022-04-26 11:34:56.118 ServerApp] 302 GET / (127.0.0.1) 0.43ms
[W 2022-04-26 11:34:58.026 LabApp] Could not determine jupyterlab build status without nodejs
TermSocket.open: 1
not able to serialize: expected string or bytes-like object
TermSocket.open: Opened 1
[I 2022-04-26 11:36:17.777 ServerApp] Starting buffering for 6c439cfd-703e-45d9-8a48-582745948072:ee55ce4f-8c9a-4c28-9fc9-43a1e02cfab7
Websocket closed
[I 2022-04-26 12:21:54.623 ServerApp] 302 GET / (127.0.0.1) 0.43ms
[W 2022-04-26 12:21:56.202 LabApp] Could not determine jupyterlab build status without nodejs
TermSocket.open: 1
not able to serialize: expected string or bytes-like object
TermSocket.open: Opened 1
[I 2022-04-26 12:22:29.414 ServerApp] Kernel restarted: 6c439cfd-703e-45d9-8a48-582745948072
[I 2022-04-26 12:22:32.031 ServerApp] Starting buffering for 6c439cfd-703e-45d9-8a48-582745948072:ab02e11c-d02f-4689-8fc8-17f61028fc10
[I 2022-04-26 12:22:32.042 ServerApp] Restoring connection for 6c439cfd-703e-45d9-8a48-582745948072:ab02e11c-d02f-4689-8fc8-17f61028fc10
2022-04-26 12:22:36.390909: I tensorflow/core/platform/cpu_feature_guard.cc:151] This TensorFlow binary is optimized with oneAPI Deep Neural Network Library (oneDNN) to use the following CPU instructions in performance-critical operations:  AVX2 FMA
To enable them in other operations, rebuild TensorFlow with the appropriate compiler flags.
[I 2022-04-26 12:23:57.681 ServerApp] Saving file at /notebooks/CKN-LinkPred_5_1.ipynb
[I 2022-04-26 12:32:11.186 ServerApp] Starting buffering for 6c439cfd-703e-45d9-8a48-582745948072:ab02e11c-d02f-4689-8fc8-17f61028fc10
Websocket closed
[I 2022-04-26 12:32:11.217 ServerApp] Restoring connection for 6c439cfd-703e-45d9-8a48-582745948072:ab02e11c-d02f-4689-8fc8-17f61028fc10
TermSocket.open: 1
not able to serialize: expected string or bytes-like object
TermSocket.open: Opened 1
[I 2022-04-26 12:58:20.883 ServerApp] Saving file at /notebooks/CKN-LinkPred_5_1.ipynb
[I 2022-04-26 13:00:21.101 ServerApp] Saving file at /notebooks/CKN-LinkPred_5_1.ipynb
[I 2022-04-26 13:08:21.440 ServerApp] Saving file at /notebooks/CKN-LinkPred_5_1.ipynb
[I 2022-04-26 13:08:24.635 ServerApp] New terminal with automatic name: 2
TermSocket.open: 2
not able to serialize: expected string or bytes-like object
TermSocket.open: Opened 2
[I 2022-04-26 13:30:47.864 ServerApp] Starting buffering for 6c439cfd-703e-45d9-8a48-582745948072:ab02e11c-d02f-4689-8fc8-17f61028fc10
Websocket closed
Websocket closed
TermSocket.open: 2
not able to serialize: expected string or bytes-like object
TermSocket.open: Opened 2
TermSocket.open: 1
not able to serialize: expected string or bytes-like object
TermSocket.open: Opened 1
[I 2022-04-26 13:30:47.922 ServerApp] Restoring connection for 6c439cfd-703e-45d9-8a48-582745948072:ab02e11c-d02f-4689-8fc8-17f61028fc10
[W 2022-04-26 13:30:52.431 ServerApp] Nudge: attempt 10 on kernel 6c439cfd-703e-45d9-8a48-582745948072
[W 2022-04-26 13:30:57.440 ServerApp] Nudge: attempt 20 on kernel 6c439cfd-703e-45d9-8a48-582745948072
[W 2022-04-26 13:31:02.451 ServerApp] Nudge: attempt 30 on kernel 6c439cfd-703e-45d9-8a48-582745948072
[W 2022-04-26 13:31:07.462 ServerApp] Nudge: attempt 40 on kernel 6c439cfd-703e-45d9-8a48-582745948072
[W 2022-04-26 13:31:12.473 ServerApp] Nudge: attempt 50 on kernel 6c439cfd-703e-45d9-8a48-582745948072
[W 2022-04-26 13:31:17.483 ServerApp] Nudge: attempt 60 on kernel 6c439cfd-703e-45d9-8a48-582745948072
[W 2022-04-26 13:31:22.492 ServerApp] Nudge: attempt 70 on kernel 6c439cfd-703e-45d9-8a48-582745948072
[W 2022-04-26 13:31:27.501 ServerApp] Nudge: attempt 80 on kernel 6c439cfd-703e-45d9-8a48-582745948072
[W 2022-04-26 13:31:32.510 ServerApp] Nudge: attempt 90 on kernel 6c439cfd-703e-45d9-8a48-582745948072
[W 2022-04-26 13:31:37.520 ServerApp] Nudge: attempt 100 on kernel 6c439cfd-703e-45d9-8a48-582745948072
[W 2022-04-26 13:31:42.531 ServerApp] Nudge: attempt 110 on kernel 6c439cfd-703e-45d9-8a48-582745948072
[W 2022-04-26 13:31:47.538 ServerApp] Nudge: attempt 120 on kernel 6c439cfd-703e-45d9-8a48-582745948072
[E 2022-04-26 13:31:47.923 ServerApp] Uncaught exception GET /api/kernels/6c439cfd-703e-45d9-8a48-582745948072/channels?session_id=ab02e11c-d02f-4689-8fc8-17f61028fc10 (127.0.0.1)
    HTTPServerRequest(protocol='http', host='localhost:9001', method='GET', uri='/api/kernels/6c439cfd-703e-45d9-8a48-582745948072/channels?session_id=ab02e11c-d02f-4689-8fc8-17f61028fc10', version='HTTP/1.1', remote_ip='127.0.0.1')
    Traceback (most recent call last):
      File "/home/martinm/nib_ckn/venv/lib/python3.8/site-packages/tornado/websocket.py", line 956, in _accept_connection
        await open_result
      File "/usr/lib/python3.8/asyncio/tasks.py", line 349, in __wakeup
        future.result()
    tornado.util.TimeoutError: Timeout
[W 2022-04-26 13:32:17.890 ServerApp] WebSocket ping timeout after 90001 ms.
[W 2022-04-26 13:32:17.905 ServerApp] WebSocket ping timeout after 90001 ms.
[W 2022-04-26 13:32:17.922 ServerApp] WebSocket ping timeout after 90000 ms.
Exception in callback BaseAsyncIOLoop._handle_events(36, 1)
handle: <Handle BaseAsyncIOLoop._handle_events(36, 1)>
Traceback (most recent call last):
  File "/usr/lib/python3.8/asyncio/events.py", line 81, in _run
    self._context.run(self._callback, *self._args)
  File "/home/martinm/nib_ckn/venv/lib/python3.8/site-packages/tornado/platform/asyncio.py", line 189, in _handle_events
    handler_func(fileobj, events)
  File "/home/martinm/nib_ckn/venv/lib/python3.8/site-packages/terminado/management.py", line 239, in pty_read
    client.on_pty_read(s)
  File "/home/martinm/nib_ckn/venv/lib/python3.8/site-packages/terminado/websocket.py", line 77, in on_pty_read
    self.send_json_message(['stdout', text])
  File "/home/martinm/nib_ckn/venv/lib/python3.8/site-packages/terminado/websocket.py", line 87, in send_json_message
    self.write_message(json_msg)
  File "/home/martinm/nib_ckn/venv/lib/python3.8/site-packages/jupyter_server/terminal/handlers.py", line 32, in write_message
    super(TermSocket, self).write_message(message, binary=binary)
  File "/home/martinm/nib_ckn/venv/lib/python3.8/site-packages/tornado/websocket.py", line 337, in write_message
    raise WebSocketClosedError()
tornado.websocket.WebSocketClosedError
Exception in callback BaseAsyncIOLoop._handle_events(36, 1)
handle: <Handle BaseAsyncIOLoop._handle_events(36, 1)>
Traceback (most recent call last):
  File "/usr/lib/python3.8/asyncio/events.py", line 81, in _run
    self._context.run(self._callback, *self._args)
  File "/home/martinm/nib_ckn/venv/lib/python3.8/site-packages/tornado/platform/asyncio.py", line 189, in _handle_events
    handler_func(fileobj, events)
  File "/home/martinm/nib_ckn/venv/lib/python3.8/site-packages/terminado/management.py", line 239, in pty_read
    client.on_pty_read(s)
  File "/home/martinm/nib_ckn/venv/lib/python3.8/site-packages/terminado/websocket.py", line 77, in on_pty_read
    self.send_json_message(['stdout', text])
  File "/home/martinm/nib_ckn/venv/lib/python3.8/site-packages/terminado/websocket.py", line 87, in send_json_message
    self.write_message(json_msg)
  File "/home/martinm/nib_ckn/venv/lib/python3.8/site-packages/jupyter_server/terminal/handlers.py", line 32, in write_message
    super(TermSocket, self).write_message(message, binary=binary)
  File "/home/martinm/nib_ckn/venv/lib/python3.8/site-packages/tornado/websocket.py", line 337, in write_message
    raise WebSocketClosedError()
tornado.websocket.WebSocketClosedError
Exception in callback BaseAsyncIOLoop._handle_events(36, 1)
handle: <Handle BaseAsyncIOLoop._handle_events(36, 1)>
Traceback (most recent call last):
  File "/usr/lib/python3.8/asyncio/events.py", line 81, in _run
    self._context.run(self._callback, *self._args)
  File "/home/martinm/nib_ckn/venv/lib/python3.8/site-packages/tornado/platform/asyncio.py", line 189, in _handle_events
    handler_func(fileobj, events)
  File "/home/martinm/nib_ckn/venv/lib/python3.8/site-packages/terminado/management.py", line 239, in pty_read
    client.on_pty_read(s)
  File "/home/martinm/nib_ckn/venv/lib/python3.8/site-packages/terminado/websocket.py", line 77, in on_pty_read
    self.send_json_message(['stdout', text])
  File "/home/martinm/nib_ckn/venv/lib/python3.8/site-packages/terminado/websocket.py", line 87, in send_json_message
    self.write_message(json_msg)
  File "/home/martinm/nib_ckn/venv/lib/python3.8/site-packages/jupyter_server/terminal/handlers.py", line 32, in write_message
    super(TermSocket, self).write_message(message, binary=binary)
  File "/home/martinm/nib_ckn/venv/lib/python3.8/site-packages/tornado/websocket.py", line 337, in write_message
    raise WebSocketClosedError()
tornado.websocket.WebSocketClosedError
Websocket closed
Websocket closed
[W 2022-04-26 13:37:07.714 ServerApp] Replacing stale connection: 6c439cfd-703e-45d9-8a48-582745948072:ab02e11c-d02f-4689-8fc8-17f61028fc10
TermSocket.open: 2
not able to serialize: expected string or bytes-like object
TermSocket.open: Opened 2
TermSocket.open: 1
not able to serialize: expected string or bytes-like object
TermSocket.open: Opened 1
[I 2022-04-26 13:41:07.706 ServerApp] Starting buffering for 6c439cfd-703e-45d9-8a48-582745948072:ab02e11c-d02f-4689-8fc8-17f61028fc10
[W 2022-04-26 13:41:08.299 ServerApp] Replacing stale connection: 6c439cfd-703e-45d9-8a48-582745948072:ab02e11c-d02f-4689-8fc8-17f61028fc10
[W 2022-04-26 13:45:08.436 ServerApp] Replacing stale connection: 6c439cfd-703e-45d9-8a48-582745948072:ab02e11c-d02f-4689-8fc8-17f61028fc10
[W 2022-04-26 13:45:31.873 ServerApp] zmq message arrived on closed channel
[W 2022-04-26 13:45:33.411 ServerApp] zmq message arrived on closed channel
[W 2022-04-26 13:45:33.413 ServerApp] zmq message arrived on closed channel
[W 2022-04-26 13:45:33.432 ServerApp] zmq message arrived on closed channel
[W 2022-04-26 13:45:33.448 ServerApp] zmq message arrived on closed channel
[W 2022-04-26 13:45:33.486 ServerApp] zmq message arrived on closed channel
[W 2022-04-26 13:45:33.513 ServerApp] zmq message arrived on closed channel
[W 2022-04-26 13:45:33.518 ServerApp] zmq message arrived on closed channel
[W 2022-04-26 13:45:35.178 ServerApp] zmq message arrived on closed channel
[W 2022-04-26 13:45:35.181 ServerApp] zmq message arrived on closed channel
[W 2022-04-26 13:45:35.370 ServerApp] zmq message arrived on closed channel
[W 2022-04-26 13:45:48.177 ServerApp] zmq message arrived on closed channel
[W 2022-04-26 13:45:49.128 ServerApp] zmq message arrived on closed channel
[W 2022-04-26 13:45:49.131 ServerApp] zmq message arrived on closed channel
[W 2022-04-26 13:45:49.220 ServerApp] zmq message arrived on closed channel
[W 2022-04-26 13:45:49.250 ServerApp] zmq message arrived on closed channel
[W 2022-04-26 13:45:49.275 ServerApp] zmq message arrived on closed channel
[W 2022-04-26 13:45:49.291 ServerApp] zmq message arrived on closed channel
[W 2022-04-26 13:45:49.330 ServerApp] zmq message arrived on closed channel
[W 2022-04-26 13:45:49.339 ServerApp] zmq message arrived on closed channel
[W 2022-04-26 13:45:49.509 ServerApp] zmq message arrived on closed channel
[W 2022-04-26 13:45:49.569 ServerApp] zmq message arrived on closed channel
[W 2022-04-26 13:45:50.067 ServerApp] zmq message arrived on closed channel
[W 2022-04-26 13:49:10.656 ServerApp] Replacing stale connection: 6c439cfd-703e-45d9-8a48-582745948072:ab02e11c-d02f-4689-8fc8-17f61028fc10
[W 2022-04-26 13:53:22.803 ServerApp] Replacing stale connection: 6c439cfd-703e-45d9-8a48-582745948072:ab02e11c-d02f-4689-8fc8-17f61028fc10
[W 2022-04-26 13:57:37.587 ServerApp] Replacing stale connection: 6c439cfd-703e-45d9-8a48-582745948072:ab02e11c-d02f-4689-8fc8-17f61028fc10
[I 2022-05-06 10:32:50.278 ServerApp] jupyterlab | extension was successfully linked.
[W 2022-05-06 10:32:50.279 NotebookApp] 'password' has moved from NotebookApp to ServerApp. This config will be passed to ServerApp. Be sure to update your config before our next release.
[I 2022-05-06 10:32:50.363 ServerApp] nbclassic | extension was successfully linked.
[I 2022-05-06 10:32:50.386 ServerApp] nbclassic | extension was successfully loaded.
[I 2022-05-06 10:32:50.386 LabApp] JupyterLab extension loaded from /home/martinm/nib_ckn/venv/lib/python3.8/site-packages/jupyterlab
[I 2022-05-06 10:32:50.386 LabApp] JupyterLab application directory is /home/martinm/nib_ckn/venv/share/jupyter/lab
[I 2022-05-06 10:32:50.388 ServerApp] jupyterlab | extension was successfully loaded.
[I 2022-05-06 10:32:50.388 ServerApp] Serving notebooks from local directory: /home/martinm/nib_ckn
[I 2022-05-06 10:32:50.388 ServerApp] Jupyter Server 1.11.2 is running at:
[I 2022-05-06 10:32:50.388 ServerApp] http://localhost:8889/lab
[I 2022-05-06 10:32:50.388 ServerApp]  or http://127.0.0.1:8889/lab
[I 2022-05-06 10:32:50.388 ServerApp] Use Control-C to stop this server and shut down all kernels (twice to skip confirmation).
[W 2022-05-06 10:33:28.594 LabApp] Could not determine jupyterlab build status without nodejs
[W 2022-05-06 10:33:31.872 ServerApp] Notebook notebooks/CKN-LinkPred_5_3.ipynb is not trusted
[W 2022-05-06 10:33:31.979 ServerApp] Notebook notebooks/CKN-LinkPred_5_2.ipynb is not trusted
[W 2022-05-06 10:33:32.342 ServerApp] Notebook notebooks/CKN-LinkPred-GCN_1_0.ipynb is not trusted
[I 2022-05-06 10:33:36.699 ServerApp] Kernel started: db17d39d-a8a1-416a-bf2d-35f291ba0941
[I 2022-05-06 10:33:36.704 ServerApp] Kernel started: e9aa970e-4e2e-43d1-8505-91d12b8bbc3a
[I 2022-05-06 10:33:36.709 ServerApp] Kernel started: 22cb9088-ff57-4b06-8683-9bc24b4520ea
[I 2022-05-06 10:33:36.947 ServerApp] Kernel started: fe797c7a-c6f5-4b9d-a56a-a198786039b4
[I 2022-05-06 10:33:37.304 ServerApp] Kernel started: 8565f97b-4475-4ca8-b587-6b4f91e58f79
[I 2022-05-06 10:33:37.511 ServerApp] Kernel started: 0b194552-6bc5-44ee-9d3f-289d15cb1a54
[I 2022-05-06 10:33:45.978 ServerApp] Starting buffering for 0b194552-6bc5-44ee-9d3f-289d15cb1a54:6f86d8d4-c1b9-4400-b246-1d06a90ff99e
[I 2022-05-06 10:45:41.875 ServerApp] Saving file at /notebooks/CKN-LinkPred_5_4.ipynb
[I 2022-05-06 10:47:41.132 ServerApp] Saving file at /notebooks/CKN-LinkPred_3_2.ipynb
2022-05-06 10:48:13.413985: I tensorflow/core/platform/cpu_feature_guard.cc:151] This TensorFlow binary is optimized with oneAPI Deep Neural Network Library (oneDNN) to use the following CPU instructions in performance-critical operations:  AVX2 FMA
To enable them in other operations, rebuild TensorFlow with the appropriate compiler flags.
[I 2022-05-06 10:49:44.802 ServerApp] Saving file at /notebooks/CKN-LinkPred_3_2.ipynb
[I 2022-05-06 10:51:46.123 ServerApp] Saving file at /notebooks/CKN-LinkPred_3_2.ipynb
[I 2022-05-06 10:53:42.676 ServerApp] Saving file at /notebooks/CKN-LinkPred_5_5.ipynb
[I 2022-05-06 10:53:52.187 ServerApp] Saving file at /notebooks/CKN-LinkPred_3_2.ipynb
[I 2022-05-06 10:55:43.852 ServerApp] Saving file at /notebooks/CKN-LinkPred_5_5.ipynb
[I 2022-05-06 10:55:53.708 ServerApp] Saving file at /notebooks/CKN-LinkPred_3_2.ipynb
[I 2022-05-06 10:57:44.438 ServerApp] Saving file at /notebooks/CKN-LinkPred_5_5.ipynb
[W 2022-05-06 10:57:44.439 ServerApp] Notebook notebooks/CKN-LinkPred_5_5.ipynb is not trusted
2022-05-06 10:59:25.610588: I tensorflow/core/platform/cpu_feature_guard.cc:151] This TensorFlow binary is optimized with oneAPI Deep Neural Network Library (oneDNN) to use the following CPU instructions in performance-critical operations:  AVX2 FMA
To enable them in other operations, rebuild TensorFlow with the appropriate compiler flags.
[I 2022-05-06 10:59:44.807 ServerApp] Saving file at /notebooks/CKN-LinkPred_5_5.ipynb
[W 2022-05-06 10:59:44.807 ServerApp] Notebook notebooks/CKN-LinkPred_5_5.ipynb is not trusted
[I 2022-05-06 11:01:45.357 ServerApp] Saving file at /notebooks/CKN-LinkPred_5_5.ipynb
[W 2022-05-06 11:01:45.358 ServerApp] Notebook notebooks/CKN-LinkPred_5_5.ipynb is not trusted
[I 2022-05-06 11:03:18.445 ServerApp] New terminal with automatic name: 1
TermSocket.open: 1
not able to serialize: expected string or bytes-like object
TermSocket.open: Opened 1
[I 2022-05-06 11:04:14.275 ServerApp] Copying notebooks/CKN-LinkPred_3_2.ipynb to /notebooks
[I 2022-05-06 11:04:31.894 ServerApp] Kernel started: 647008f7-aa33-44dd-ade0-50cc70575078
[I 2022-05-06 11:06:15.413 ServerApp] Kernel restarted: 22cb9088-ff57-4b06-8683-9bc24b4520ea
[I 2022-05-06 11:06:19.165 ServerApp] Starting buffering for 22cb9088-ff57-4b06-8683-9bc24b4520ea:86fb94d3-d20d-4d24-b1be-a0fe6d50f6f1
[I 2022-05-06 11:06:19.508 ServerApp] Restoring connection for 22cb9088-ff57-4b06-8683-9bc24b4520ea:86fb94d3-d20d-4d24-b1be-a0fe6d50f6f1
2022-05-06 11:06:25.284638: I tensorflow/core/platform/cpu_feature_guard.cc:151] This TensorFlow binary is optimized with oneAPI Deep Neural Network Library (oneDNN) to use the following CPU instructions in performance-critical operations:  AVX2 FMA
To enable them in other operations, rebuild TensorFlow with the appropriate compiler flags.
[I 2022-05-06 11:06:32.049 ServerApp] Saving file at /notebooks/CKN-LinkPred_3_2-corrected.ipynb
[I 2022-05-06 11:07:12.485 ServerApp] Kernel restarted: 647008f7-aa33-44dd-ade0-50cc70575078
[I 2022-05-06 11:07:12.632 ServerApp] Starting buffering for 647008f7-aa33-44dd-ade0-50cc70575078:1866dd8a-fe15-4cc9-ae82-196a4d6731f2
[I 2022-05-06 11:07:12.638 ServerApp] Restoring connection for 647008f7-aa33-44dd-ade0-50cc70575078:1866dd8a-fe15-4cc9-ae82-196a4d6731f2
2022-05-06 11:07:17.186286: I tensorflow/core/platform/cpu_feature_guard.cc:151] This TensorFlow binary is optimized with oneAPI Deep Neural Network Library (oneDNN) to use the following CPU instructions in performance-critical operations:  AVX2 FMA
To enable them in other operations, rebuild TensorFlow with the appropriate compiler flags.
[I 2022-05-06 11:07:27.549 ServerApp] Kernel restarted: 22cb9088-ff57-4b06-8683-9bc24b4520ea
[I 2022-05-06 11:07:32.867 ServerApp] Starting buffering for 22cb9088-ff57-4b06-8683-9bc24b4520ea:86fb94d3-d20d-4d24-b1be-a0fe6d50f6f1
[I 2022-05-06 11:07:32.882 ServerApp] Restoring connection for 22cb9088-ff57-4b06-8683-9bc24b4520ea:86fb94d3-d20d-4d24-b1be-a0fe6d50f6f1
2022-05-06 11:07:37.849193: I tensorflow/core/platform/cpu_feature_guard.cc:151] This TensorFlow binary is optimized with oneAPI Deep Neural Network Library (oneDNN) to use the following CPU instructions in performance-critical operations:  AVX2 FMA
To enable them in other operations, rebuild TensorFlow with the appropriate compiler flags.
[I 2022-05-06 11:07:54.073 ServerApp] Saving file at /notebooks/CKN-LinkPred_3_2.ipynb
[I 2022-05-06 11:08:32.318 ServerApp] Saving file at /notebooks/CKN-LinkPred_3_2-corrected.ipynb
[I 2022-05-06 11:09:38.997 ServerApp] Starting buffering for e9aa970e-4e2e-43d1-8505-91d12b8bbc3a:4a689411-d731-460f-874b-9ca10b16597b
[I 2022-05-06 11:09:45.555 ServerApp] Starting buffering for db17d39d-a8a1-416a-bf2d-35f291ba0941:4b249655-feec-4b96-adde-be4efbf3c4a0
[I 2022-05-06 11:11:46.456 ServerApp] Saving file at /notebooks/CKN-LinkPred_5_5.ipynb
[W 2022-05-06 11:11:46.457 ServerApp] Notebook notebooks/CKN-LinkPred_5_5.ipynb is not trusted
[I 2022-05-06 11:15:46.810 ServerApp] Saving file at /notebooks/CKN-LinkPred_5_5.ipynb
[W 2022-05-06 11:15:46.810 ServerApp] Notebook notebooks/CKN-LinkPred_5_5.ipynb is not trusted
[I 2022-05-06 11:17:47.251 ServerApp] Saving file at /notebooks/CKN-LinkPred_5_5.ipynb
[W 2022-05-06 11:17:47.251 ServerApp] Notebook notebooks/CKN-LinkPred_5_5.ipynb is not trusted
[I 2022-05-06 11:19:47.528 ServerApp] Saving file at /notebooks/CKN-LinkPred_5_5.ipynb
[W 2022-05-06 11:19:47.529 ServerApp] Notebook notebooks/CKN-LinkPred_5_5.ipynb is not trusted
[I 2022-05-06 11:21:48.288 ServerApp] Saving file at /notebooks/CKN-LinkPred_5_5.ipynb
[W 2022-05-06 11:21:48.289 ServerApp] Notebook notebooks/CKN-LinkPred_5_5.ipynb is not trusted
[I 2022-05-06 11:23:48.707 ServerApp] Saving file at /notebooks/CKN-LinkPred_5_5.ipynb
[W 2022-05-06 11:23:48.708 ServerApp] Notebook notebooks/CKN-LinkPred_5_5.ipynb is not trusted
[I 2022-05-06 11:25:49.212 ServerApp] Saving file at /notebooks/CKN-LinkPred_5_5.ipynb
[W 2022-05-06 11:25:49.213 ServerApp] Notebook notebooks/CKN-LinkPred_5_5.ipynb is not trusted
[I 2022-05-06 11:26:32.925 ServerApp] Saving file at /notebooks/CKN-LinkPred_3_2-corrected.ipynb
[I 2022-05-06 11:27:50.043 ServerApp] Saving file at /notebooks/CKN-LinkPred_5_5.ipynb
[W 2022-05-06 11:27:50.043 ServerApp] Notebook notebooks/CKN-LinkPred_5_5.ipynb is not trusted
[I 2022-05-06 11:27:54.370 ServerApp] Saving file at /notebooks/CKN-LinkPred_3_2.ipynb
[I 2022-05-06 11:28:33.469 ServerApp] Saving file at /notebooks/CKN-LinkPred_3_2-corrected.ipynb
[I 2022-05-06 11:29:50.659 ServerApp] Saving file at /notebooks/CKN-LinkPred_5_5.ipynb
[W 2022-05-06 11:29:50.660 ServerApp] Notebook notebooks/CKN-LinkPred_5_5.ipynb is not trusted
[I 2022-05-06 11:30:47.797 ServerApp] Creating new directory in /notebooks
[W 2022-05-06 11:31:47.925 ServerApp] Notebook notebooks/NetworkX_excs.ipynb is not trusted
[I 2022-05-06 11:31:49.752 ServerApp] Kernel started: d03a348f-5ac1-4e98-b92e-5e57062827ab
[I 2022-05-06 11:33:19.547 ServerApp] Starting buffering for d03a348f-5ac1-4e98-b92e-5e57062827ab:7a568d74-26ed-4a9b-a0ce-3b880f972268
[I 2022-05-06 11:34:57.370 ServerApp] Starting buffering for fe797c7a-c6f5-4b9d-a56a-a198786039b4:de5aa9b6-289b-476d-81e0-38466e5797a9
[I 2022-05-06 11:35:24.949 ServerApp] Kernel started: 61583383-730f-45ab-8624-336d68f5d3a2
[I 2022-05-06 11:40:57.863 ServerApp] New terminal with automatic name: 2
TermSocket.open: 2
not able to serialize: expected string or bytes-like object
TermSocket.open: Opened 2
[I 2022-05-06 11:41:51.451 ServerApp] Saving file at /notebooks/CKN-LinkPred_5_5.ipynb
[W 2022-05-06 11:41:51.452 ServerApp] Notebook notebooks/CKN-LinkPred_5_5.ipynb is not trusted
[I 2022-05-06 11:45:51.901 ServerApp] Saving file at /notebooks/CKN-LinkPred_5_5.ipynb
[W 2022-05-06 11:45:51.902 ServerApp] Notebook notebooks/CKN-LinkPred_5_5.ipynb is not trusted
[I 2022-05-06 11:47:52.281 ServerApp] Saving file at /notebooks/CKN-LinkPred_5_5.ipynb
[W 2022-05-06 11:47:52.282 ServerApp] Notebook notebooks/CKN-LinkPred_5_5.ipynb is not trusted
[I 2022-05-06 11:47:54.922 ServerApp] Saving file at /notebooks/CKN-LinkPred_3_2.ipynb
[I 2022-05-06 11:48:34.761 ServerApp] Saving file at /notebooks/CKN-LinkPred_3_2-corrected.ipynb
[I 2022-05-06 11:49:53.017 ServerApp] Saving file at /notebooks/CKN-LinkPred_5_5.ipynb
[W 2022-05-06 11:49:53.018 ServerApp] Notebook notebooks/CKN-LinkPred_5_5.ipynb is not trusted
[I 2022-05-06 11:51:53.802 ServerApp] Saving file at /notebooks/CKN-LinkPred_5_5.ipynb
[W 2022-05-06 11:51:53.803 ServerApp] Notebook notebooks/CKN-LinkPred_5_5.ipynb is not trusted
[I 2022-05-06 11:53:54.221 ServerApp] Saving file at /notebooks/CKN-LinkPred_5_5.ipynb
[W 2022-05-06 11:53:54.222 ServerApp] Notebook notebooks/CKN-LinkPred_5_5.ipynb is not trusted
[I 2022-05-06 11:55:54.695 ServerApp] Saving file at /notebooks/CKN-LinkPred_5_5.ipynb
[W 2022-05-06 11:55:54.696 ServerApp] Notebook notebooks/CKN-LinkPred_5_5.ipynb is not trusted
[I 2022-05-06 11:57:55.035 ServerApp] Saving file at /notebooks/CKN-LinkPred_5_5.ipynb
[W 2022-05-06 11:57:55.036 ServerApp] Notebook notebooks/CKN-LinkPred_5_5.ipynb is not trusted
[I 2022-05-06 11:59:55.380 ServerApp] Saving file at /notebooks/CKN-LinkPred_5_5.ipynb
[W 2022-05-06 11:59:55.381 ServerApp] Notebook notebooks/CKN-LinkPred_5_5.ipynb is not trusted
[I 2022-05-06 12:01:55.865 ServerApp] Saving file at /notebooks/CKN-LinkPred_5_5.ipynb
[W 2022-05-06 12:01:55.865 ServerApp] Notebook notebooks/CKN-LinkPred_5_5.ipynb is not trusted
[I 2022-05-06 12:03:56.324 ServerApp] Saving file at /notebooks/CKN-LinkPred_5_5.ipynb
[W 2022-05-06 12:03:56.325 ServerApp] Notebook notebooks/CKN-LinkPred_5_5.ipynb is not trusted
[I 2022-05-06 12:08:35.601 ServerApp] Saving file at /notebooks/CKN-LinkPred_3_2-corrected.ipynb
[I 2022-05-06 12:08:39.300 ServerApp] Starting buffering for 61583383-730f-45ab-8624-336d68f5d3a2:be974485-e06a-456d-8d10-bd1f45626a73
[I 2022-05-06 12:09:56.146 ServerApp] Saving file at /notebooks/CKN-LinkPred_3_2.ipynb
[I 2022-05-06 12:13:27.885 ServerApp] Copying notebooks/CKN-LinkPred_5_5.ipynb to /notebooks
[W 2022-05-06 12:13:27.949 ServerApp] Notebook notebooks/CKN-LinkPred_5_5.ipynb is not trusted
[W 2022-05-06 12:13:28.004 ServerApp] Notebook notebooks/CKN-LinkPred_5_5-Copy1.ipynb is not trusted
[W 2022-05-06 12:13:42.058 ServerApp] Notebook notebooks/CKN-LinkPred_5_6.ipynb is not trusted
[I 2022-05-06 12:13:43.961 ServerApp] Kernel started: 31dea182-d7ee-4bf1-96de-2879d9a39214
[I 2022-05-06 12:13:56.676 ServerApp] Saving file at /notebooks/CKN-LinkPred_5_5.ipynb
[W 2022-05-06 12:13:56.676 ServerApp] Notebook notebooks/CKN-LinkPred_5_5.ipynb is not trusted
[I 2022-05-06 12:15:43.480 ServerApp] Saving file at /notebooks/CKN-LinkPred_5_6.ipynb
[W 2022-05-06 12:15:43.481 ServerApp] Notebook notebooks/CKN-LinkPred_5_6.ipynb is not trusted
[I 2022-05-06 12:16:45.219 ServerApp] Kernel restarted: 31dea182-d7ee-4bf1-96de-2879d9a39214
[I 2022-05-06 12:16:45.351 ServerApp] Starting buffering for 31dea182-d7ee-4bf1-96de-2879d9a39214:c072890e-751c-469a-805a-8243c22925e0
[I 2022-05-06 12:16:45.359 ServerApp] Restoring connection for 31dea182-d7ee-4bf1-96de-2879d9a39214:c072890e-751c-469a-805a-8243c22925e0
2022-05-06 12:16:49.958886: I tensorflow/core/platform/cpu_feature_guard.cc:151] This TensorFlow binary is optimized with oneAPI Deep Neural Network Library (oneDNN) to use the following CPU instructions in performance-critical operations:  AVX2 FMA
To enable them in other operations, rebuild TensorFlow with the appropriate compiler flags.
[I 2022-05-06 12:17:43.908 ServerApp] Saving file at /notebooks/CKN-LinkPred_5_6.ipynb
[I 2022-05-06 12:19:44.271 ServerApp] Saving file at /notebooks/CKN-LinkPred_5_6.ipynb
[I 2022-05-06 13:09:25.270 ServerApp] Saving file at /notebooks/CKN-LinkPred_5_6.ipynb
[I 2022-05-06 14:01:29.501 ServerApp] Saving file at /notebooks/CKN-LinkPred_5_6.ipynb
[I 2022-05-06 14:03:29.748 ServerApp] Saving file at /notebooks/CKN-LinkPred_5_6.ipynb
[I 2022-05-06 14:05:30.019 ServerApp] Saving file at /notebooks/CKN-LinkPred_5_6.ipynb
[I 2022-05-06 14:07:30.332 ServerApp] Saving file at /notebooks/CKN-LinkPred_5_6.ipynb
[I 2022-05-06 14:09:30.590 ServerApp] Saving file at /notebooks/CKN-LinkPred_5_6.ipynb
[I 2022-05-06 14:13:30.883 ServerApp] Saving file at /notebooks/CKN-LinkPred_5_6.ipynb
[I 2022-05-06 14:15:31.237 ServerApp] Saving file at /notebooks/CKN-LinkPred_5_6.ipynb
Websocket closed
[I 2022-05-06 17:00:54.492 ServerApp] Starting buffering for 22cb9088-ff57-4b06-8683-9bc24b4520ea:86fb94d3-d20d-4d24-b1be-a0fe6d50f6f1
Websocket closed
[I 2022-05-06 17:00:54.492 ServerApp] Starting buffering for 8565f97b-4475-4ca8-b587-6b4f91e58f79:d48e4a23-1a91-4536-be53-22bbae98187d
[I 2022-05-06 17:00:54.492 ServerApp] Starting buffering for 31dea182-d7ee-4bf1-96de-2879d9a39214:c072890e-751c-469a-805a-8243c22925e0
[I 2022-05-06 17:00:54.492 ServerApp] Starting buffering for 0b194552-6bc5-44ee-9d3f-289d15cb1a54:0e97016b-79ac-4e56-b21a-e929f9f5a31a
[I 2022-05-06 17:00:54.492 ServerApp] Starting buffering for 647008f7-aa33-44dd-ade0-50cc70575078:1866dd8a-fe15-4cc9-ae82-196a4d6731f2
[I 2022-05-06 17:00:54.528 ServerApp] Restoring connection for 31dea182-d7ee-4bf1-96de-2879d9a39214:c072890e-751c-469a-805a-8243c22925e0
TermSocket.open: 2
not able to serialize: expected string or bytes-like object
TermSocket.open: Opened 2
[I 2022-05-06 17:00:54.589 ServerApp] Restoring connection for 22cb9088-ff57-4b06-8683-9bc24b4520ea:86fb94d3-d20d-4d24-b1be-a0fe6d50f6f1
[I 2022-05-06 17:00:54.670 ServerApp] Restoring connection for 647008f7-aa33-44dd-ade0-50cc70575078:1866dd8a-fe15-4cc9-ae82-196a4d6731f2
[I 2022-05-06 17:00:54.692 ServerApp] Restoring connection for 0b194552-6bc5-44ee-9d3f-289d15cb1a54:0e97016b-79ac-4e56-b21a-e929f9f5a31a
TermSocket.open: 1
not able to serialize: expected string or bytes-like object
TermSocket.open: Opened 1
[I 2022-05-06 17:00:54.774 ServerApp] Restoring connection for 8565f97b-4475-4ca8-b587-6b4f91e58f79:d48e4a23-1a91-4536-be53-22bbae98187d
[W 2022-05-06 17:03:24.529 ServerApp] WebSocket ping timeout after 119991 ms.
[W 2022-05-06 17:03:24.567 ServerApp] WebSocket ping timeout after 119991 ms.
[W 2022-05-06 17:03:24.589 ServerApp] WebSocket ping timeout after 119850 ms.
[W 2022-05-06 17:03:24.670 ServerApp] WebSocket ping timeout after 119931 ms.
[W 2022-05-06 17:03:24.693 ServerApp] WebSocket ping timeout after 119954 ms.
[W 2022-05-06 17:03:24.745 ServerApp] WebSocket ping timeout after 119991 ms.
[W 2022-05-06 17:03:24.774 ServerApp] WebSocket ping timeout after 119821 ms.
Exception in callback BaseAsyncIOLoop._handle_events(11, 1)
handle: <Handle BaseAsyncIOLoop._handle_events(11, 1)>
Traceback (most recent call last):
  File "/usr/lib/python3.8/asyncio/events.py", line 81, in _run
    self._context.run(self._callback, *self._args)
  File "/home/martinm/nib_ckn/venv/lib/python3.8/site-packages/tornado/platform/asyncio.py", line 189, in _handle_events
    handler_func(fileobj, events)
  File "/home/martinm/nib_ckn/venv/lib/python3.8/site-packages/terminado/management.py", line 239, in pty_read
    client.on_pty_read(s)
  File "/home/martinm/nib_ckn/venv/lib/python3.8/site-packages/terminado/websocket.py", line 77, in on_pty_read
    self.send_json_message(['stdout', text])
  File "/home/martinm/nib_ckn/venv/lib/python3.8/site-packages/terminado/websocket.py", line 87, in send_json_message
    self.write_message(json_msg)
  File "/home/martinm/nib_ckn/venv/lib/python3.8/site-packages/jupyter_server/terminal/handlers.py", line 32, in write_message
    super(TermSocket, self).write_message(message, binary=binary)
  File "/home/martinm/nib_ckn/venv/lib/python3.8/site-packages/tornado/websocket.py", line 337, in write_message
    raise WebSocketClosedError()
tornado.websocket.WebSocketClosedError
Exception in callback BaseAsyncIOLoop._handle_events(11, 1)
handle: <Handle BaseAsyncIOLoop._handle_events(11, 1)>
Traceback (most recent call last):
  File "/usr/lib/python3.8/asyncio/events.py", line 81, in _run
    self._context.run(self._callback, *self._args)
  File "/home/martinm/nib_ckn/venv/lib/python3.8/site-packages/tornado/platform/asyncio.py", line 189, in _handle_events
    handler_func(fileobj, events)
  File "/home/martinm/nib_ckn/venv/lib/python3.8/site-packages/terminado/management.py", line 239, in pty_read
    client.on_pty_read(s)
  File "/home/martinm/nib_ckn/venv/lib/python3.8/site-packages/terminado/websocket.py", line 77, in on_pty_read
    self.send_json_message(['stdout', text])
  File "/home/martinm/nib_ckn/venv/lib/python3.8/site-packages/terminado/websocket.py", line 87, in send_json_message
    self.write_message(json_msg)
  File "/home/martinm/nib_ckn/venv/lib/python3.8/site-packages/jupyter_server/terminal/handlers.py", line 32, in write_message
    super(TermSocket, self).write_message(message, binary=binary)
  File "/home/martinm/nib_ckn/venv/lib/python3.8/site-packages/tornado/websocket.py", line 337, in write_message
    raise WebSocketClosedError()
tornado.websocket.WebSocketClosedError
Exception in callback BaseAsyncIOLoop._handle_events(11, 1)
handle: <Handle BaseAsyncIOLoop._handle_events(11, 1)>
Traceback (most recent call last):
  File "/usr/lib/python3.8/asyncio/events.py", line 81, in _run
    self._context.run(self._callback, *self._args)
  File "/home/martinm/nib_ckn/venv/lib/python3.8/site-packages/tornado/platform/asyncio.py", line 189, in _handle_events
    handler_func(fileobj, events)
  File "/home/martinm/nib_ckn/venv/lib/python3.8/site-packages/terminado/management.py", line 239, in pty_read
    client.on_pty_read(s)
  File "/home/martinm/nib_ckn/venv/lib/python3.8/site-packages/terminado/websocket.py", line 77, in on_pty_read
    self.send_json_message(['stdout', text])
  File "/home/martinm/nib_ckn/venv/lib/python3.8/site-packages/terminado/websocket.py", line 87, in send_json_message
    self.write_message(json_msg)
  File "/home/martinm/nib_ckn/venv/lib/python3.8/site-packages/jupyter_server/terminal/handlers.py", line 32, in write_message
    super(TermSocket, self).write_message(message, binary=binary)
  File "/home/martinm/nib_ckn/venv/lib/python3.8/site-packages/tornado/websocket.py", line 337, in write_message
    raise WebSocketClosedError()
tornado.websocket.WebSocketClosedError
[I 2022-05-06 17:03:29.532 ServerApp] Starting buffering for 31dea182-d7ee-4bf1-96de-2879d9a39214:c072890e-751c-469a-805a-8243c22925e0
Websocket closed
[I 2022-05-06 17:03:29.591 ServerApp] Starting buffering for 22cb9088-ff57-4b06-8683-9bc24b4520ea:86fb94d3-d20d-4d24-b1be-a0fe6d50f6f1
[I 2022-05-06 17:03:29.672 ServerApp] Starting buffering for 647008f7-aa33-44dd-ade0-50cc70575078:1866dd8a-fe15-4cc9-ae82-196a4d6731f2
[I 2022-05-06 17:03:29.695 ServerApp] Starting buffering for 0b194552-6bc5-44ee-9d3f-289d15cb1a54:0e97016b-79ac-4e56-b21a-e929f9f5a31a
Websocket closed
[I 2022-05-06 17:03:29.776 ServerApp] Starting buffering for 8565f97b-4475-4ca8-b587-6b4f91e58f79:d48e4a23-1a91-4536-be53-22bbae98187d
[W 2022-05-10 09:59:03.831 LabApp] Could not determine jupyterlab build status without nodejs
TermSocket.open: 1
not able to serialize: expected string or bytes-like object
TermSocket.open: Opened 1
[W 2022-05-10 09:59:08.584 ServerApp] Notebook notebooks/CKN-LinkPred-GCN_1_0.ipynb is not trusted
TermSocket.open: 2
not able to serialize: expected string or bytes-like object
TermSocket.open: Opened 2
[I 2022-05-10 10:05:10.009 ServerApp] Saving file at /notebooks/CKN-LinkPred_5_6.ipynb
[I 2022-05-10 10:58:18.052 ServerApp] Saving file at /notebooks/CKN-LinkPred_5_6.ipynb
[I 2022-05-10 11:17:16.942 ServerApp] Saving file at /notebooks/CKN-LinkPred_5_6.ipynb
[I 2022-05-10 11:19:17.220 ServerApp] Saving file at /notebooks/CKN-LinkPred_5_6.ipynb
[I 2022-05-10 11:21:17.501 ServerApp] Saving file at /notebooks/CKN-LinkPred_5_6.ipynb
[I 2022-05-10 11:25:17.874 ServerApp] Saving file at /notebooks/CKN-LinkPred_5_6.ipynb
Websocket closed
Websocket closed
[I 2022-05-10 11:46:15.848 ServerApp] Starting buffering for 22cb9088-ff57-4b06-8683-9bc24b4520ea:29c2332b-065f-434f-9c74-5085d9975c2c
[I 2022-05-10 11:46:15.848 ServerApp] Starting buffering for 8565f97b-4475-4ca8-b587-6b4f91e58f79:6e2e461b-5c9a-4855-8899-fc62fd665bf0
[I 2022-05-10 11:46:15.848 ServerApp] Starting buffering for 647008f7-aa33-44dd-ade0-50cc70575078:6fe7fbd8-5272-49e9-8343-1b412220b9a0
[I 2022-05-10 11:46:15.848 ServerApp] Starting buffering for 31dea182-d7ee-4bf1-96de-2879d9a39214:f2fc3452-9f7b-49b1-a442-bd3c499d9009
[I 2022-05-10 11:46:15.872 ServerApp] Restoring connection for 8565f97b-4475-4ca8-b587-6b4f91e58f79:6e2e461b-5c9a-4855-8899-fc62fd665bf0
[I 2022-05-10 11:46:15.889 ServerApp] Restoring connection for 22cb9088-ff57-4b06-8683-9bc24b4520ea:29c2332b-065f-434f-9c74-5085d9975c2c
TermSocket.open: 2
not able to serialize: expected string or bytes-like object
TermSocket.open: Opened 2
TermSocket.open: 1
not able to serialize: expected string or bytes-like object
TermSocket.open: Opened 1
[I 2022-05-10 11:46:15.942 ServerApp] Restoring connection for 31dea182-d7ee-4bf1-96de-2879d9a39214:f2fc3452-9f7b-49b1-a442-bd3c499d9009
[I 2022-05-10 11:46:15.966 ServerApp] Restoring connection for 647008f7-aa33-44dd-ade0-50cc70575078:6fe7fbd8-5272-49e9-8343-1b412220b9a0
[I 2022-05-10 11:47:46.522 ServerApp] Starting buffering for 8565f97b-4475-4ca8-b587-6b4f91e58f79:6e2e461b-5c9a-4855-8899-fc62fd665bf0
[I 2022-05-10 11:47:46.522 ServerApp] Starting buffering for 22cb9088-ff57-4b06-8683-9bc24b4520ea:29c2332b-065f-434f-9c74-5085d9975c2c
Websocket closed
Websocket closed
[I 2022-05-10 11:47:46.523 ServerApp] Starting buffering for 31dea182-d7ee-4bf1-96de-2879d9a39214:f2fc3452-9f7b-49b1-a442-bd3c499d9009
[I 2022-05-10 11:47:46.523 ServerApp] Starting buffering for 647008f7-aa33-44dd-ade0-50cc70575078:6fe7fbd8-5272-49e9-8343-1b412220b9a0
[I 2022-05-10 11:47:46.543 ServerApp] Restoring connection for 647008f7-aa33-44dd-ade0-50cc70575078:6fe7fbd8-5272-49e9-8343-1b412220b9a0
[I 2022-05-10 11:47:46.567 ServerApp] Restoring connection for 31dea182-d7ee-4bf1-96de-2879d9a39214:f2fc3452-9f7b-49b1-a442-bd3c499d9009
TermSocket.open: 1
not able to serialize: expected string or bytes-like object
TermSocket.open: Opened 1
TermSocket.open: 2
not able to serialize: expected string or bytes-like object
TermSocket.open: Opened 2
[I 2022-05-10 11:47:46.637 ServerApp] Restoring connection for 22cb9088-ff57-4b06-8683-9bc24b4520ea:29c2332b-065f-434f-9c74-5085d9975c2c
[I 2022-05-10 11:47:46.652 ServerApp] Restoring connection for 8565f97b-4475-4ca8-b587-6b4f91e58f79:6e2e461b-5c9a-4855-8899-fc62fd665bf0
[W 2022-05-10 11:50:16.543 ServerApp] WebSocket ping timeout after 119986 ms.
[W 2022-05-10 11:50:16.568 ServerApp] WebSocket ping timeout after 119996 ms.
[W 2022-05-10 11:50:16.587 ServerApp] WebSocket ping timeout after 119998 ms.
[W 2022-05-10 11:50:16.614 ServerApp] WebSocket ping timeout after 119878 ms.
[W 2022-05-10 11:50:16.637 ServerApp] WebSocket ping timeout after 119900 ms.
[W 2022-05-10 11:50:16.652 ServerApp] WebSocket ping timeout after 119915 ms.
Exception in callback BaseAsyncIOLoop._handle_events(11, 1)
handle: <Handle BaseAsyncIOLoop._handle_events(11, 1)>
Traceback (most recent call last):
  File "/usr/lib/python3.8/asyncio/events.py", line 81, in _run
    self._context.run(self._callback, *self._args)
  File "/home/martinm/nib_ckn/venv/lib/python3.8/site-packages/tornado/platform/asyncio.py", line 189, in _handle_events
    handler_func(fileobj, events)
  File "/home/martinm/nib_ckn/venv/lib/python3.8/site-packages/terminado/management.py", line 239, in pty_read
    client.on_pty_read(s)
  File "/home/martinm/nib_ckn/venv/lib/python3.8/site-packages/terminado/websocket.py", line 77, in on_pty_read
    self.send_json_message(['stdout', text])
  File "/home/martinm/nib_ckn/venv/lib/python3.8/site-packages/terminado/websocket.py", line 87, in send_json_message
    self.write_message(json_msg)
  File "/home/martinm/nib_ckn/venv/lib/python3.8/site-packages/jupyter_server/terminal/handlers.py", line 32, in write_message
    super(TermSocket, self).write_message(message, binary=binary)
  File "/home/martinm/nib_ckn/venv/lib/python3.8/site-packages/tornado/websocket.py", line 337, in write_message
    raise WebSocketClosedError()
tornado.websocket.WebSocketClosedError
Exception in callback BaseAsyncIOLoop._handle_events(11, 1)
handle: <Handle BaseAsyncIOLoop._handle_events(11, 1)>
Traceback (most recent call last):
  File "/usr/lib/python3.8/asyncio/events.py", line 81, in _run
    self._context.run(self._callback, *self._args)
  File "/home/martinm/nib_ckn/venv/lib/python3.8/site-packages/tornado/platform/asyncio.py", line 189, in _handle_events
    handler_func(fileobj, events)
  File "/home/martinm/nib_ckn/venv/lib/python3.8/site-packages/terminado/management.py", line 239, in pty_read
    client.on_pty_read(s)
  File "/home/martinm/nib_ckn/venv/lib/python3.8/site-packages/terminado/websocket.py", line 77, in on_pty_read
    self.send_json_message(['stdout', text])
  File "/home/martinm/nib_ckn/venv/lib/python3.8/site-packages/terminado/websocket.py", line 87, in send_json_message
    self.write_message(json_msg)
  File "/home/martinm/nib_ckn/venv/lib/python3.8/site-packages/jupyter_server/terminal/handlers.py", line 32, in write_message
    super(TermSocket, self).write_message(message, binary=binary)
  File "/home/martinm/nib_ckn/venv/lib/python3.8/site-packages/tornado/websocket.py", line 337, in write_message
    raise WebSocketClosedError()
tornado.websocket.WebSocketClosedError
Exception in callback BaseAsyncIOLoop._handle_events(11, 1)
handle: <Handle BaseAsyncIOLoop._handle_events(11, 1)>
Traceback (most recent call last):
  File "/usr/lib/python3.8/asyncio/events.py", line 81, in _run
    self._context.run(self._callback, *self._args)
  File "/home/martinm/nib_ckn/venv/lib/python3.8/site-packages/tornado/platform/asyncio.py", line 189, in _handle_events
    handler_func(fileobj, events)
  File "/home/martinm/nib_ckn/venv/lib/python3.8/site-packages/terminado/management.py", line 239, in pty_read
    client.on_pty_read(s)
  File "/home/martinm/nib_ckn/venv/lib/python3.8/site-packages/terminado/websocket.py", line 77, in on_pty_read
    self.send_json_message(['stdout', text])
  File "/home/martinm/nib_ckn/venv/lib/python3.8/site-packages/terminado/websocket.py", line 87, in send_json_message
    self.write_message(json_msg)
  File "/home/martinm/nib_ckn/venv/lib/python3.8/site-packages/jupyter_server/terminal/handlers.py", line 32, in write_message
    super(TermSocket, self).write_message(message, binary=binary)
  File "/home/martinm/nib_ckn/venv/lib/python3.8/site-packages/tornado/websocket.py", line 337, in write_message
    raise WebSocketClosedError()
tornado.websocket.WebSocketClosedError
Exception in callback BaseAsyncIOLoop._handle_events(11, 1)
handle: <Handle BaseAsyncIOLoop._handle_events(11, 1)>
Traceback (most recent call last):
  File "/usr/lib/python3.8/asyncio/events.py", line 81, in _run
    self._context.run(self._callback, *self._args)
  File "/home/martinm/nib_ckn/venv/lib/python3.8/site-packages/tornado/platform/asyncio.py", line 189, in _handle_events
    handler_func(fileobj, events)
  File "/home/martinm/nib_ckn/venv/lib/python3.8/site-packages/terminado/management.py", line 239, in pty_read
    client.on_pty_read(s)
  File "/home/martinm/nib_ckn/venv/lib/python3.8/site-packages/terminado/websocket.py", line 77, in on_pty_read
    self.send_json_message(['stdout', text])
  File "/home/martinm/nib_ckn/venv/lib/python3.8/site-packages/terminado/websocket.py", line 87, in send_json_message
    self.write_message(json_msg)
  File "/home/martinm/nib_ckn/venv/lib/python3.8/site-packages/jupyter_server/terminal/handlers.py", line 32, in write_message
    super(TermSocket, self).write_message(message, binary=binary)
  File "/home/martinm/nib_ckn/venv/lib/python3.8/site-packages/tornado/websocket.py", line 337, in write_message
    raise WebSocketClosedError()
tornado.websocket.WebSocketClosedError
Exception in callback BaseAsyncIOLoop._handle_events(11, 1)
handle: <Handle BaseAsyncIOLoop._handle_events(11, 1)>
Traceback (most recent call last):
  File "/usr/lib/python3.8/asyncio/events.py", line 81, in _run
    self._context.run(self._callback, *self._args)
  File "/home/martinm/nib_ckn/venv/lib/python3.8/site-packages/tornado/platform/asyncio.py", line 189, in _handle_events
    handler_func(fileobj, events)
  File "/home/martinm/nib_ckn/venv/lib/python3.8/site-packages/terminado/management.py", line 239, in pty_read
    client.on_pty_read(s)
  File "/home/martinm/nib_ckn/venv/lib/python3.8/site-packages/terminado/websocket.py", line 77, in on_pty_read
    self.send_json_message(['stdout', text])
  File "/home/martinm/nib_ckn/venv/lib/python3.8/site-packages/terminado/websocket.py", line 87, in send_json_message
    self.write_message(json_msg)
  File "/home/martinm/nib_ckn/venv/lib/python3.8/site-packages/jupyter_server/terminal/handlers.py", line 32, in write_message
    super(TermSocket, self).write_message(message, binary=binary)
  File "/home/martinm/nib_ckn/venv/lib/python3.8/site-packages/tornado/websocket.py", line 337, in write_message
    raise WebSocketClosedError()
tornado.websocket.WebSocketClosedError
Exception in callback BaseAsyncIOLoop._handle_events(11, 1)
handle: <Handle BaseAsyncIOLoop._handle_events(11, 1)>
Traceback (most recent call last):
  File "/usr/lib/python3.8/asyncio/events.py", line 81, in _run
    self._context.run(self._callback, *self._args)
  File "/home/martinm/nib_ckn/venv/lib/python3.8/site-packages/tornado/platform/asyncio.py", line 189, in _handle_events
    handler_func(fileobj, events)
  File "/home/martinm/nib_ckn/venv/lib/python3.8/site-packages/terminado/management.py", line 239, in pty_read
    client.on_pty_read(s)
  File "/home/martinm/nib_ckn/venv/lib/python3.8/site-packages/terminado/websocket.py", line 77, in on_pty_read
    self.send_json_message(['stdout', text])
  File "/home/martinm/nib_ckn/venv/lib/python3.8/site-packages/terminado/websocket.py", line 87, in send_json_message
    self.write_message(json_msg)
  File "/home/martinm/nib_ckn/venv/lib/python3.8/site-packages/jupyter_server/terminal/handlers.py", line 32, in write_message
    super(TermSocket, self).write_message(message, binary=binary)
  File "/home/martinm/nib_ckn/venv/lib/python3.8/site-packages/tornado/websocket.py", line 337, in write_message
    raise WebSocketClosedError()
tornado.websocket.WebSocketClosedError
Exception in callback BaseAsyncIOLoop._handle_events(11, 1)
handle: <Handle BaseAsyncIOLoop._handle_events(11, 1)>
Traceback (most recent call last):
  File "/usr/lib/python3.8/asyncio/events.py", line 81, in _run
    self._context.run(self._callback, *self._args)
  File "/home/martinm/nib_ckn/venv/lib/python3.8/site-packages/tornado/platform/asyncio.py", line 189, in _handle_events
    handler_func(fileobj, events)
  File "/home/martinm/nib_ckn/venv/lib/python3.8/site-packages/terminado/management.py", line 239, in pty_read
    client.on_pty_read(s)
  File "/home/martinm/nib_ckn/venv/lib/python3.8/site-packages/terminado/websocket.py", line 77, in on_pty_read
    self.send_json_message(['stdout', text])
  File "/home/martinm/nib_ckn/venv/lib/python3.8/site-packages/terminado/websocket.py", line 87, in send_json_message
    self.write_message(json_msg)
  File "/home/martinm/nib_ckn/venv/lib/python3.8/site-packages/jupyter_server/terminal/handlers.py", line 32, in write_message
    super(TermSocket, self).write_message(message, binary=binary)
  File "/home/martinm/nib_ckn/venv/lib/python3.8/site-packages/tornado/websocket.py", line 337, in write_message
    raise WebSocketClosedError()
tornado.websocket.WebSocketClosedError
Exception in callback BaseAsyncIOLoop._handle_events(11, 1)
handle: <Handle BaseAsyncIOLoop._handle_events(11, 1)>
Traceback (most recent call last):
  File "/usr/lib/python3.8/asyncio/events.py", line 81, in _run
    self._context.run(self._callback, *self._args)
  File "/home/martinm/nib_ckn/venv/lib/python3.8/site-packages/tornado/platform/asyncio.py", line 189, in _handle_events
    handler_func(fileobj, events)
  File "/home/martinm/nib_ckn/venv/lib/python3.8/site-packages/terminado/management.py", line 239, in pty_read
    client.on_pty_read(s)
  File "/home/martinm/nib_ckn/venv/lib/python3.8/site-packages/terminado/websocket.py", line 77, in on_pty_read
    self.send_json_message(['stdout', text])
  File "/home/martinm/nib_ckn/venv/lib/python3.8/site-packages/terminado/websocket.py", line 87, in send_json_message
    self.write_message(json_msg)
  File "/home/martinm/nib_ckn/venv/lib/python3.8/site-packages/jupyter_server/terminal/handlers.py", line 32, in write_message
    super(TermSocket, self).write_message(message, binary=binary)
  File "/home/martinm/nib_ckn/venv/lib/python3.8/site-packages/tornado/websocket.py", line 337, in write_message
    raise WebSocketClosedError()
tornado.websocket.WebSocketClosedError
Exception in callback BaseAsyncIOLoop._handle_events(11, 1)
handle: <Handle BaseAsyncIOLoop._handle_events(11, 1)>
Traceback (most recent call last):
  File "/usr/lib/python3.8/asyncio/events.py", line 81, in _run
    self._context.run(self._callback, *self._args)
  File "/home/martinm/nib_ckn/venv/lib/python3.8/site-packages/tornado/platform/asyncio.py", line 189, in _handle_events
    handler_func(fileobj, events)
  File "/home/martinm/nib_ckn/venv/lib/python3.8/site-packages/terminado/management.py", line 239, in pty_read
    client.on_pty_read(s)
  File "/home/martinm/nib_ckn/venv/lib/python3.8/site-packages/terminado/websocket.py", line 77, in on_pty_read
    self.send_json_message(['stdout', text])
  File "/home/martinm/nib_ckn/venv/lib/python3.8/site-packages/terminado/websocket.py", line 87, in send_json_message
    self.write_message(json_msg)
  File "/home/martinm/nib_ckn/venv/lib/python3.8/site-packages/jupyter_server/terminal/handlers.py", line 32, in write_message
    super(TermSocket, self).write_message(message, binary=binary)
  File "/home/martinm/nib_ckn/venv/lib/python3.8/site-packages/tornado/websocket.py", line 337, in write_message
    raise WebSocketClosedError()
tornado.websocket.WebSocketClosedError
Exception in callback BaseAsyncIOLoop._handle_events(11, 1)
handle: <Handle BaseAsyncIOLoop._handle_events(11, 1)>
Traceback (most recent call last):
  File "/usr/lib/python3.8/asyncio/events.py", line 81, in _run
    self._context.run(self._callback, *self._args)
  File "/home/martinm/nib_ckn/venv/lib/python3.8/site-packages/tornado/platform/asyncio.py", line 189, in _handle_events
    handler_func(fileobj, events)
  File "/home/martinm/nib_ckn/venv/lib/python3.8/site-packages/terminado/management.py", line 239, in pty_read
    client.on_pty_read(s)
  File "/home/martinm/nib_ckn/venv/lib/python3.8/site-packages/terminado/websocket.py", line 77, in on_pty_read
    self.send_json_message(['stdout', text])
  File "/home/martinm/nib_ckn/venv/lib/python3.8/site-packages/terminado/websocket.py", line 87, in send_json_message
    self.write_message(json_msg)
  File "/home/martinm/nib_ckn/venv/lib/python3.8/site-packages/jupyter_server/terminal/handlers.py", line 32, in write_message
    super(TermSocket, self).write_message(message, binary=binary)
  File "/home/martinm/nib_ckn/venv/lib/python3.8/site-packages/tornado/websocket.py", line 337, in write_message
    raise WebSocketClosedError()
tornado.websocket.WebSocketClosedError
Exception in callback BaseAsyncIOLoop._handle_events(11, 1)
handle: <Handle BaseAsyncIOLoop._handle_events(11, 1)>
Traceback (most recent call last):
  File "/usr/lib/python3.8/asyncio/events.py", line 81, in _run
    self._context.run(self._callback, *self._args)
  File "/home/martinm/nib_ckn/venv/lib/python3.8/site-packages/tornado/platform/asyncio.py", line 189, in _handle_events
    handler_func(fileobj, events)
  File "/home/martinm/nib_ckn/venv/lib/python3.8/site-packages/terminado/management.py", line 239, in pty_read
    client.on_pty_read(s)
  File "/home/martinm/nib_ckn/venv/lib/python3.8/site-packages/terminado/websocket.py", line 77, in on_pty_read
    self.send_json_message(['stdout', text])
  File "/home/martinm/nib_ckn/venv/lib/python3.8/site-packages/terminado/websocket.py", line 87, in send_json_message
    self.write_message(json_msg)
  File "/home/martinm/nib_ckn/venv/lib/python3.8/site-packages/jupyter_server/terminal/handlers.py", line 32, in write_message
    super(TermSocket, self).write_message(message, binary=binary)
  File "/home/martinm/nib_ckn/venv/lib/python3.8/site-packages/tornado/websocket.py", line 337, in write_message
    raise WebSocketClosedError()
tornado.websocket.WebSocketClosedError
[I 2022-05-10 11:50:21.546 ServerApp] Starting buffering for 647008f7-aa33-44dd-ade0-50cc70575078:6fe7fbd8-5272-49e9-8343-1b412220b9a0
[I 2022-05-10 11:50:21.569 ServerApp] Starting buffering for 31dea182-d7ee-4bf1-96de-2879d9a39214:f2fc3452-9f7b-49b1-a442-bd3c499d9009
Websocket closed
Websocket closed
[I 2022-05-10 11:50:21.638 ServerApp] Starting buffering for 22cb9088-ff57-4b06-8683-9bc24b4520ea:29c2332b-065f-434f-9c74-5085d9975c2c
[I 2022-05-10 11:50:21.653 ServerApp] Starting buffering for 8565f97b-4475-4ca8-b587-6b4f91e58f79:6e2e461b-5c9a-4855-8899-fc62fd665bf0
[I 2022-05-10 13:03:10.600 ServerApp] Restoring connection for 8565f97b-4475-4ca8-b587-6b4f91e58f79:6e2e461b-5c9a-4855-8899-fc62fd665bf0
[I 2022-05-10 13:03:10.664 ServerApp] Restoring connection for 647008f7-aa33-44dd-ade0-50cc70575078:6fe7fbd8-5272-49e9-8343-1b412220b9a0
[I 2022-05-10 13:03:10.854 ServerApp] Restoring connection for 22cb9088-ff57-4b06-8683-9bc24b4520ea:29c2332b-065f-434f-9c74-5085d9975c2c
TermSocket.open: 2
not able to serialize: expected string or bytes-like object
TermSocket.open: Opened 2
[I 2022-05-10 13:03:11.945 ServerApp] Restoring connection for 31dea182-d7ee-4bf1-96de-2879d9a39214:f2fc3452-9f7b-49b1-a442-bd3c499d9009
[I 2022-05-10 13:03:12.044 ServerApp] Starting buffering for 22cb9088-ff57-4b06-8683-9bc24b4520ea:29c2332b-065f-434f-9c74-5085d9975c2c
[I 2022-05-10 13:03:12.045 ServerApp] Starting buffering for 8565f97b-4475-4ca8-b587-6b4f91e58f79:6e2e461b-5c9a-4855-8899-fc62fd665bf0
[I 2022-05-10 13:03:12.045 ServerApp] Starting buffering for 31dea182-d7ee-4bf1-96de-2879d9a39214:f2fc3452-9f7b-49b1-a442-bd3c499d9009
[I 2022-05-10 13:03:12.045 ServerApp] Starting buffering for 647008f7-aa33-44dd-ade0-50cc70575078:6fe7fbd8-5272-49e9-8343-1b412220b9a0
Websocket closed
[W 2022-05-10 13:03:13.668 LabApp] Could not determine jupyterlab build status without nodejs
TermSocket.open: 1
not able to serialize: expected string or bytes-like object
TermSocket.open: Opened 1
TermSocket.open: 2
not able to serialize: expected string or bytes-like object
TermSocket.open: Opened 2
[W 2022-05-10 13:03:15.012 ServerApp] Notebook notebooks/CKN-LinkPred-GCN_1_0.ipynb is not trusted
[I 2022-05-10 13:15:16.745 ServerApp] Saving file at /notebooks/CKN-LinkPred_5_6.ipynb
[I 2022-05-10 13:17:16.993 ServerApp] Saving file at /notebooks/CKN-LinkPred_5_6.ipynb
[I 2022-05-10 13:39:17.270 ServerApp] Saving file at /notebooks/CKN-LinkPred_5_6.ipynb
[I 2022-05-10 14:13:17.552 ServerApp] Saving file at /notebooks/CKN-LinkPred_5_6.ipynb
Websocket closed
Websocket closed
[I 2022-05-10 14:16:09.886 ServerApp] Starting buffering for 22cb9088-ff57-4b06-8683-9bc24b4520ea:1cae8674-ac42-4e04-803e-5bca0dad3ca0
[I 2022-05-10 14:16:09.886 ServerApp] Starting buffering for 647008f7-aa33-44dd-ade0-50cc70575078:402826f6-f0e7-4998-9baa-a149f0ad60f1
[I 2022-05-10 14:16:09.886 ServerApp] Starting buffering for 8565f97b-4475-4ca8-b587-6b4f91e58f79:11ef63cb-e919-4a04-b685-2f4ea43d14e9
[I 2022-05-10 14:16:09.886 ServerApp] Starting buffering for 31dea182-d7ee-4bf1-96de-2879d9a39214:fb9b83bd-3664-4824-a681-ff5f42fa96e8
[I 2022-05-10 14:16:09.908 ServerApp] Restoring connection for 31dea182-d7ee-4bf1-96de-2879d9a39214:fb9b83bd-3664-4824-a681-ff5f42fa96e8
[I 2022-05-10 14:16:09.927 ServerApp] Restoring connection for 8565f97b-4475-4ca8-b587-6b4f91e58f79:11ef63cb-e919-4a04-b685-2f4ea43d14e9
[I 2022-05-10 14:16:09.959 ServerApp] Restoring connection for 647008f7-aa33-44dd-ade0-50cc70575078:402826f6-f0e7-4998-9baa-a149f0ad60f1
[I 2022-05-10 14:16:09.976 ServerApp] Restoring connection for 22cb9088-ff57-4b06-8683-9bc24b4520ea:1cae8674-ac42-4e04-803e-5bca0dad3ca0
TermSocket.open: 2
not able to serialize: expected string or bytes-like object
TermSocket.open: Opened 2
TermSocket.open: 1
not able to serialize: expected string or bytes-like object
TermSocket.open: Opened 1
[W 2022-05-10 14:17:39.908 ServerApp] WebSocket ping timeout after 90000 ms.
[W 2022-05-10 14:17:39.927 ServerApp] WebSocket ping timeout after 90000 ms.
[W 2022-05-10 14:17:39.960 ServerApp] WebSocket ping timeout after 90000 ms.
[W 2022-05-10 14:17:39.976 ServerApp] WebSocket ping timeout after 90000 ms.
[W 2022-05-10 14:17:40.006 ServerApp] WebSocket ping timeout after 90001 ms.
[W 2022-05-10 14:17:40.022 ServerApp] WebSocket ping timeout after 90000 ms.
Exception in callback BaseAsyncIOLoop._handle_events(11, 1)
handle: <Handle BaseAsyncIOLoop._handle_events(11, 1)>
Traceback (most recent call last):
  File "/usr/lib/python3.8/asyncio/events.py", line 81, in _run
    self._context.run(self._callback, *self._args)
  File "/home/martinm/nib_ckn/venv/lib/python3.8/site-packages/tornado/platform/asyncio.py", line 189, in _handle_events
    handler_func(fileobj, events)
  File "/home/martinm/nib_ckn/venv/lib/python3.8/site-packages/terminado/management.py", line 239, in pty_read
    client.on_pty_read(s)
  File "/home/martinm/nib_ckn/venv/lib/python3.8/site-packages/terminado/websocket.py", line 77, in on_pty_read
    self.send_json_message(['stdout', text])
  File "/home/martinm/nib_ckn/venv/lib/python3.8/site-packages/terminado/websocket.py", line 87, in send_json_message
    self.write_message(json_msg)
  File "/home/martinm/nib_ckn/venv/lib/python3.8/site-packages/jupyter_server/terminal/handlers.py", line 32, in write_message
    super(TermSocket, self).write_message(message, binary=binary)
  File "/home/martinm/nib_ckn/venv/lib/python3.8/site-packages/tornado/websocket.py", line 337, in write_message
    raise WebSocketClosedError()
tornado.websocket.WebSocketClosedError
Exception in callback BaseAsyncIOLoop._handle_events(11, 1)
handle: <Handle BaseAsyncIOLoop._handle_events(11, 1)>
Traceback (most recent call last):
  File "/usr/lib/python3.8/asyncio/events.py", line 81, in _run
    self._context.run(self._callback, *self._args)
  File "/home/martinm/nib_ckn/venv/lib/python3.8/site-packages/tornado/platform/asyncio.py", line 189, in _handle_events
    handler_func(fileobj, events)
  File "/home/martinm/nib_ckn/venv/lib/python3.8/site-packages/terminado/management.py", line 239, in pty_read
    client.on_pty_read(s)
  File "/home/martinm/nib_ckn/venv/lib/python3.8/site-packages/terminado/websocket.py", line 77, in on_pty_read
    self.send_json_message(['stdout', text])
  File "/home/martinm/nib_ckn/venv/lib/python3.8/site-packages/terminado/websocket.py", line 87, in send_json_message
    self.write_message(json_msg)
  File "/home/martinm/nib_ckn/venv/lib/python3.8/site-packages/jupyter_server/terminal/handlers.py", line 32, in write_message
    super(TermSocket, self).write_message(message, binary=binary)
  File "/home/martinm/nib_ckn/venv/lib/python3.8/site-packages/tornado/websocket.py", line 337, in write_message
    raise WebSocketClosedError()
tornado.websocket.WebSocketClosedError
Exception in callback BaseAsyncIOLoop._handle_events(11, 1)
handle: <Handle BaseAsyncIOLoop._handle_events(11, 1)>
Traceback (most recent call last):
  File "/usr/lib/python3.8/asyncio/events.py", line 81, in _run
    self._context.run(self._callback, *self._args)
  File "/home/martinm/nib_ckn/venv/lib/python3.8/site-packages/tornado/platform/asyncio.py", line 189, in _handle_events
    handler_func(fileobj, events)
  File "/home/martinm/nib_ckn/venv/lib/python3.8/site-packages/terminado/management.py", line 239, in pty_read
    client.on_pty_read(s)
  File "/home/martinm/nib_ckn/venv/lib/python3.8/site-packages/terminado/websocket.py", line 77, in on_pty_read
    self.send_json_message(['stdout', text])
  File "/home/martinm/nib_ckn/venv/lib/python3.8/site-packages/terminado/websocket.py", line 87, in send_json_message
    self.write_message(json_msg)
  File "/home/martinm/nib_ckn/venv/lib/python3.8/site-packages/jupyter_server/terminal/handlers.py", line 32, in write_message
    super(TermSocket, self).write_message(message, binary=binary)
  File "/home/martinm/nib_ckn/venv/lib/python3.8/site-packages/tornado/websocket.py", line 337, in write_message
    raise WebSocketClosedError()
tornado.websocket.WebSocketClosedError
Exception in callback BaseAsyncIOLoop._handle_events(11, 1)
handle: <Handle BaseAsyncIOLoop._handle_events(11, 1)>
Traceback (most recent call last):
  File "/usr/lib/python3.8/asyncio/events.py", line 81, in _run
    self._context.run(self._callback, *self._args)
  File "/home/martinm/nib_ckn/venv/lib/python3.8/site-packages/tornado/platform/asyncio.py", line 189, in _handle_events
    handler_func(fileobj, events)
  File "/home/martinm/nib_ckn/venv/lib/python3.8/site-packages/terminado/management.py", line 239, in pty_read
    client.on_pty_read(s)
  File "/home/martinm/nib_ckn/venv/lib/python3.8/site-packages/terminado/websocket.py", line 77, in on_pty_read
    self.send_json_message(['stdout', text])
  File "/home/martinm/nib_ckn/venv/lib/python3.8/site-packages/terminado/websocket.py", line 87, in send_json_message
    self.write_message(json_msg)
  File "/home/martinm/nib_ckn/venv/lib/python3.8/site-packages/jupyter_server/terminal/handlers.py", line 32, in write_message
    super(TermSocket, self).write_message(message, binary=binary)
  File "/home/martinm/nib_ckn/venv/lib/python3.8/site-packages/tornado/websocket.py", line 337, in write_message
    raise WebSocketClosedError()
tornado.websocket.WebSocketClosedError
Exception in callback BaseAsyncIOLoop._handle_events(11, 1)
handle: <Handle BaseAsyncIOLoop._handle_events(11, 1)>
Traceback (most recent call last):
  File "/usr/lib/python3.8/asyncio/events.py", line 81, in _run
    self._context.run(self._callback, *self._args)
  File "/home/martinm/nib_ckn/venv/lib/python3.8/site-packages/tornado/platform/asyncio.py", line 189, in _handle_events
    handler_func(fileobj, events)
  File "/home/martinm/nib_ckn/venv/lib/python3.8/site-packages/terminado/management.py", line 239, in pty_read
    client.on_pty_read(s)
  File "/home/martinm/nib_ckn/venv/lib/python3.8/site-packages/terminado/websocket.py", line 77, in on_pty_read
    self.send_json_message(['stdout', text])
  File "/home/martinm/nib_ckn/venv/lib/python3.8/site-packages/terminado/websocket.py", line 87, in send_json_message
    self.write_message(json_msg)
  File "/home/martinm/nib_ckn/venv/lib/python3.8/site-packages/jupyter_server/terminal/handlers.py", line 32, in write_message
    super(TermSocket, self).write_message(message, binary=binary)
  File "/home/martinm/nib_ckn/venv/lib/python3.8/site-packages/tornado/websocket.py", line 337, in write_message
    raise WebSocketClosedError()
tornado.websocket.WebSocketClosedError
Exception in callback BaseAsyncIOLoop._handle_events(11, 1)
handle: <Handle BaseAsyncIOLoop._handle_events(11, 1)>
Traceback (most recent call last):
  File "/usr/lib/python3.8/asyncio/events.py", line 81, in _run
    self._context.run(self._callback, *self._args)
  File "/home/martinm/nib_ckn/venv/lib/python3.8/site-packages/tornado/platform/asyncio.py", line 189, in _handle_events
    handler_func(fileobj, events)
  File "/home/martinm/nib_ckn/venv/lib/python3.8/site-packages/terminado/management.py", line 239, in pty_read
    client.on_pty_read(s)
  File "/home/martinm/nib_ckn/venv/lib/python3.8/site-packages/terminado/websocket.py", line 77, in on_pty_read
    self.send_json_message(['stdout', text])
  File "/home/martinm/nib_ckn/venv/lib/python3.8/site-packages/terminado/websocket.py", line 87, in send_json_message
    self.write_message(json_msg)
  File "/home/martinm/nib_ckn/venv/lib/python3.8/site-packages/jupyter_server/terminal/handlers.py", line 32, in write_message
    super(TermSocket, self).write_message(message, binary=binary)
  File "/home/martinm/nib_ckn/venv/lib/python3.8/site-packages/tornado/websocket.py", line 337, in write_message
    raise WebSocketClosedError()
tornado.websocket.WebSocketClosedError
Exception in callback BaseAsyncIOLoop._handle_events(11, 1)
handle: <Handle BaseAsyncIOLoop._handle_events(11, 1)>
Traceback (most recent call last):
  File "/usr/lib/python3.8/asyncio/events.py", line 81, in _run
    self._context.run(self._callback, *self._args)
  File "/home/martinm/nib_ckn/venv/lib/python3.8/site-packages/tornado/platform/asyncio.py", line 189, in _handle_events
    handler_func(fileobj, events)
  File "/home/martinm/nib_ckn/venv/lib/python3.8/site-packages/terminado/management.py", line 239, in pty_read
    client.on_pty_read(s)
  File "/home/martinm/nib_ckn/venv/lib/python3.8/site-packages/terminado/websocket.py", line 77, in on_pty_read
    self.send_json_message(['stdout', text])
  File "/home/martinm/nib_ckn/venv/lib/python3.8/site-packages/terminado/websocket.py", line 87, in send_json_message
    self.write_message(json_msg)
  File "/home/martinm/nib_ckn/venv/lib/python3.8/site-packages/jupyter_server/terminal/handlers.py", line 32, in write_message
    super(TermSocket, self).write_message(message, binary=binary)
  File "/home/martinm/nib_ckn/venv/lib/python3.8/site-packages/tornado/websocket.py", line 337, in write_message
    raise WebSocketClosedError()
tornado.websocket.WebSocketClosedError
Exception in callback BaseAsyncIOLoop._handle_events(11, 1)
handle: <Handle BaseAsyncIOLoop._handle_events(11, 1)>
Traceback (most recent call last):
  File "/usr/lib/python3.8/asyncio/events.py", line 81, in _run
    self._context.run(self._callback, *self._args)
  File "/home/martinm/nib_ckn/venv/lib/python3.8/site-packages/tornado/platform/asyncio.py", line 189, in _handle_events
    handler_func(fileobj, events)
  File "/home/martinm/nib_ckn/venv/lib/python3.8/site-packages/terminado/management.py", line 239, in pty_read
    client.on_pty_read(s)
  File "/home/martinm/nib_ckn/venv/lib/python3.8/site-packages/terminado/websocket.py", line 77, in on_pty_read
    self.send_json_message(['stdout', text])
  File "/home/martinm/nib_ckn/venv/lib/python3.8/site-packages/terminado/websocket.py", line 87, in send_json_message
    self.write_message(json_msg)
  File "/home/martinm/nib_ckn/venv/lib/python3.8/site-packages/jupyter_server/terminal/handlers.py", line 32, in write_message
    super(TermSocket, self).write_message(message, binary=binary)
  File "/home/martinm/nib_ckn/venv/lib/python3.8/site-packages/tornado/websocket.py", line 337, in write_message
    raise WebSocketClosedError()
tornado.websocket.WebSocketClosedError
[I 2022-05-10 14:17:44.909 ServerApp] Starting buffering for 31dea182-d7ee-4bf1-96de-2879d9a39214:fb9b83bd-3664-4824-a681-ff5f42fa96e8
[I 2022-05-10 14:17:44.929 ServerApp] Starting buffering for 8565f97b-4475-4ca8-b587-6b4f91e58f79:11ef63cb-e919-4a04-b685-2f4ea43d14e9
[I 2022-05-10 14:17:44.960 ServerApp] Starting buffering for 647008f7-aa33-44dd-ade0-50cc70575078:402826f6-f0e7-4998-9baa-a149f0ad60f1
[I 2022-05-10 14:17:44.976 ServerApp] Starting buffering for 22cb9088-ff57-4b06-8683-9bc24b4520ea:1cae8674-ac42-4e04-803e-5bca0dad3ca0
Websocket closed
Websocket closed
[I 2022-05-10 14:28:16.002 ServerApp] Restoring connection for 31dea182-d7ee-4bf1-96de-2879d9a39214:fb9b83bd-3664-4824-a681-ff5f42fa96e8
[I 2022-05-10 14:28:16.017 ServerApp] Restoring connection for 8565f97b-4475-4ca8-b587-6b4f91e58f79:11ef63cb-e919-4a04-b685-2f4ea43d14e9
[I 2022-05-10 14:28:16.033 ServerApp] Restoring connection for 647008f7-aa33-44dd-ade0-50cc70575078:402826f6-f0e7-4998-9baa-a149f0ad60f1
[I 2022-05-10 14:28:16.177 ServerApp] Restoring connection for 22cb9088-ff57-4b06-8683-9bc24b4520ea:1cae8674-ac42-4e04-803e-5bca0dad3ca0
TermSocket.open: 2
not able to serialize: expected string or bytes-like object
TermSocket.open: Opened 2
TermSocket.open: 1
not able to serialize: expected string or bytes-like object
TermSocket.open: Opened 1
[I 2022-05-10 15:22:12.949 ServerApp] Starting buffering for 8565f97b-4475-4ca8-b587-6b4f91e58f79:11ef63cb-e919-4a04-b685-2f4ea43d14e9
[I 2022-05-10 15:22:12.950 ServerApp] Starting buffering for 647008f7-aa33-44dd-ade0-50cc70575078:402826f6-f0e7-4998-9baa-a149f0ad60f1
[I 2022-05-10 15:22:12.950 ServerApp] Starting buffering for 22cb9088-ff57-4b06-8683-9bc24b4520ea:1cae8674-ac42-4e04-803e-5bca0dad3ca0
Websocket closed
Websocket closed
[I 2022-05-10 15:22:12.950 ServerApp] Starting buffering for 31dea182-d7ee-4bf1-96de-2879d9a39214:fb9b83bd-3664-4824-a681-ff5f42fa96e8
TermSocket.open: 1
not able to serialize: expected string or bytes-like object
TermSocket.open: Opened 1
[I 2022-05-10 15:22:13.002 ServerApp] Restoring connection for 22cb9088-ff57-4b06-8683-9bc24b4520ea:1cae8674-ac42-4e04-803e-5bca0dad3ca0
[I 2022-05-10 15:22:13.017 ServerApp] Restoring connection for 647008f7-aa33-44dd-ade0-50cc70575078:402826f6-f0e7-4998-9baa-a149f0ad60f1
[I 2022-05-10 15:22:13.035 ServerApp] Restoring connection for 8565f97b-4475-4ca8-b587-6b4f91e58f79:11ef63cb-e919-4a04-b685-2f4ea43d14e9
[I 2022-05-10 15:22:13.051 ServerApp] Restoring connection for 31dea182-d7ee-4bf1-96de-2879d9a39214:fb9b83bd-3664-4824-a681-ff5f42fa96e8
TermSocket.open: 2
not able to serialize: expected string or bytes-like object
TermSocket.open: Opened 2
Websocket closed
[I 2022-05-10 16:06:54.316 ServerApp] Starting buffering for 22cb9088-ff57-4b06-8683-9bc24b4520ea:1cae8674-ac42-4e04-803e-5bca0dad3ca0
[I 2022-05-10 16:06:54.316 ServerApp] Starting buffering for 647008f7-aa33-44dd-ade0-50cc70575078:402826f6-f0e7-4998-9baa-a149f0ad60f1
[I 2022-05-10 16:06:54.316 ServerApp] Starting buffering for 8565f97b-4475-4ca8-b587-6b4f91e58f79:11ef63cb-e919-4a04-b685-2f4ea43d14e9
[I 2022-05-10 16:06:54.317 ServerApp] Starting buffering for 31dea182-d7ee-4bf1-96de-2879d9a39214:fb9b83bd-3664-4824-a681-ff5f42fa96e8
Websocket closed
TermSocket.open: 2
not able to serialize: expected string or bytes-like object
TermSocket.open: Opened 2
[I 2022-05-10 16:06:54.350 ServerApp] Restoring connection for 8565f97b-4475-4ca8-b587-6b4f91e58f79:11ef63cb-e919-4a04-b685-2f4ea43d14e9
[I 2022-05-10 16:06:54.366 ServerApp] Restoring connection for 647008f7-aa33-44dd-ade0-50cc70575078:402826f6-f0e7-4998-9baa-a149f0ad60f1
[I 2022-05-10 16:06:54.381 ServerApp] Restoring connection for 22cb9088-ff57-4b06-8683-9bc24b4520ea:1cae8674-ac42-4e04-803e-5bca0dad3ca0
[I 2022-05-10 16:06:54.398 ServerApp] Restoring connection for 31dea182-d7ee-4bf1-96de-2879d9a39214:fb9b83bd-3664-4824-a681-ff5f42fa96e8
TermSocket.open: 1
not able to serialize: expected string or bytes-like object
TermSocket.open: Opened 1
[W 2022-05-10 16:08:24.334 ServerApp] WebSocket ping timeout after 90000 ms.
[W 2022-05-10 16:08:24.351 ServerApp] WebSocket ping timeout after 90000 ms.
[W 2022-05-10 16:08:24.366 ServerApp] WebSocket ping timeout after 90000 ms.
[W 2022-05-10 16:08:24.381 ServerApp] WebSocket ping timeout after 90000 ms.
[W 2022-05-10 16:08:24.399 ServerApp] WebSocket ping timeout after 90000 ms.
[W 2022-05-10 16:08:24.414 ServerApp] WebSocket ping timeout after 90000 ms.
Exception in callback BaseAsyncIOLoop._handle_events(11, 1)
handle: <Handle BaseAsyncIOLoop._handle_events(11, 1)>
Traceback (most recent call last):
  File "/usr/lib/python3.8/asyncio/events.py", line 81, in _run
    self._context.run(self._callback, *self._args)
  File "/home/martinm/nib_ckn/venv/lib/python3.8/site-packages/tornado/platform/asyncio.py", line 189, in _handle_events
    handler_func(fileobj, events)
  File "/home/martinm/nib_ckn/venv/lib/python3.8/site-packages/terminado/management.py", line 239, in pty_read
    client.on_pty_read(s)
  File "/home/martinm/nib_ckn/venv/lib/python3.8/site-packages/terminado/websocket.py", line 77, in on_pty_read
    self.send_json_message(['stdout', text])
  File "/home/martinm/nib_ckn/venv/lib/python3.8/site-packages/terminado/websocket.py", line 87, in send_json_message
    self.write_message(json_msg)
  File "/home/martinm/nib_ckn/venv/lib/python3.8/site-packages/jupyter_server/terminal/handlers.py", line 32, in write_message
    super(TermSocket, self).write_message(message, binary=binary)
  File "/home/martinm/nib_ckn/venv/lib/python3.8/site-packages/tornado/websocket.py", line 337, in write_message
    raise WebSocketClosedError()
tornado.websocket.WebSocketClosedError
Exception in callback BaseAsyncIOLoop._handle_events(11, 1)
handle: <Handle BaseAsyncIOLoop._handle_events(11, 1)>
Traceback (most recent call last):
  File "/usr/lib/python3.8/asyncio/events.py", line 81, in _run
    self._context.run(self._callback, *self._args)
  File "/home/martinm/nib_ckn/venv/lib/python3.8/site-packages/tornado/platform/asyncio.py", line 189, in _handle_events
    handler_func(fileobj, events)
  File "/home/martinm/nib_ckn/venv/lib/python3.8/site-packages/terminado/management.py", line 239, in pty_read
    client.on_pty_read(s)
  File "/home/martinm/nib_ckn/venv/lib/python3.8/site-packages/terminado/websocket.py", line 77, in on_pty_read
    self.send_json_message(['stdout', text])
  File "/home/martinm/nib_ckn/venv/lib/python3.8/site-packages/terminado/websocket.py", line 87, in send_json_message
    self.write_message(json_msg)
  File "/home/martinm/nib_ckn/venv/lib/python3.8/site-packages/jupyter_server/terminal/handlers.py", line 32, in write_message
    super(TermSocket, self).write_message(message, binary=binary)
  File "/home/martinm/nib_ckn/venv/lib/python3.8/site-packages/tornado/websocket.py", line 337, in write_message
    raise WebSocketClosedError()
tornado.websocket.WebSocketClosedError
Exception in callback BaseAsyncIOLoop._handle_events(11, 1)
handle: <Handle BaseAsyncIOLoop._handle_events(11, 1)>
Traceback (most recent call last):
  File "/usr/lib/python3.8/asyncio/events.py", line 81, in _run
    self._context.run(self._callback, *self._args)
  File "/home/martinm/nib_ckn/venv/lib/python3.8/site-packages/tornado/platform/asyncio.py", line 189, in _handle_events
    handler_func(fileobj, events)
  File "/home/martinm/nib_ckn/venv/lib/python3.8/site-packages/terminado/management.py", line 239, in pty_read
    client.on_pty_read(s)
  File "/home/martinm/nib_ckn/venv/lib/python3.8/site-packages/terminado/websocket.py", line 77, in on_pty_read
    self.send_json_message(['stdout', text])
  File "/home/martinm/nib_ckn/venv/lib/python3.8/site-packages/terminado/websocket.py", line 87, in send_json_message
    self.write_message(json_msg)
  File "/home/martinm/nib_ckn/venv/lib/python3.8/site-packages/jupyter_server/terminal/handlers.py", line 32, in write_message
    super(TermSocket, self).write_message(message, binary=binary)
  File "/home/martinm/nib_ckn/venv/lib/python3.8/site-packages/tornado/websocket.py", line 337, in write_message
    raise WebSocketClosedError()
tornado.websocket.WebSocketClosedError
Exception in callback BaseAsyncIOLoop._handle_events(11, 1)
handle: <Handle BaseAsyncIOLoop._handle_events(11, 1)>
Traceback (most recent call last):
  File "/usr/lib/python3.8/asyncio/events.py", line 81, in _run
    self._context.run(self._callback, *self._args)
  File "/home/martinm/nib_ckn/venv/lib/python3.8/site-packages/tornado/platform/asyncio.py", line 189, in _handle_events
    handler_func(fileobj, events)
  File "/home/martinm/nib_ckn/venv/lib/python3.8/site-packages/terminado/management.py", line 239, in pty_read
    client.on_pty_read(s)
  File "/home/martinm/nib_ckn/venv/lib/python3.8/site-packages/terminado/websocket.py", line 77, in on_pty_read
    self.send_json_message(['stdout', text])
  File "/home/martinm/nib_ckn/venv/lib/python3.8/site-packages/terminado/websocket.py", line 87, in send_json_message
    self.write_message(json_msg)
  File "/home/martinm/nib_ckn/venv/lib/python3.8/site-packages/jupyter_server/terminal/handlers.py", line 32, in write_message
    super(TermSocket, self).write_message(message, binary=binary)
  File "/home/martinm/nib_ckn/venv/lib/python3.8/site-packages/tornado/websocket.py", line 337, in write_message
    raise WebSocketClosedError()
tornado.websocket.WebSocketClosedError
Exception in callback BaseAsyncIOLoop._handle_events(11, 1)
handle: <Handle BaseAsyncIOLoop._handle_events(11, 1)>
Traceback (most recent call last):
  File "/usr/lib/python3.8/asyncio/events.py", line 81, in _run
    self._context.run(self._callback, *self._args)
  File "/home/martinm/nib_ckn/venv/lib/python3.8/site-packages/tornado/platform/asyncio.py", line 189, in _handle_events
    handler_func(fileobj, events)
  File "/home/martinm/nib_ckn/venv/lib/python3.8/site-packages/terminado/management.py", line 239, in pty_read
    client.on_pty_read(s)
  File "/home/martinm/nib_ckn/venv/lib/python3.8/site-packages/terminado/websocket.py", line 77, in on_pty_read
    self.send_json_message(['stdout', text])
  File "/home/martinm/nib_ckn/venv/lib/python3.8/site-packages/terminado/websocket.py", line 87, in send_json_message
    self.write_message(json_msg)
  File "/home/martinm/nib_ckn/venv/lib/python3.8/site-packages/jupyter_server/terminal/handlers.py", line 32, in write_message
    super(TermSocket, self).write_message(message, binary=binary)
  File "/home/martinm/nib_ckn/venv/lib/python3.8/site-packages/tornado/websocket.py", line 337, in write_message
    raise WebSocketClosedError()
tornado.websocket.WebSocketClosedError
Exception in callback BaseAsyncIOLoop._handle_events(11, 1)
handle: <Handle BaseAsyncIOLoop._handle_events(11, 1)>
Traceback (most recent call last):
  File "/usr/lib/python3.8/asyncio/events.py", line 81, in _run
    self._context.run(self._callback, *self._args)
  File "/home/martinm/nib_ckn/venv/lib/python3.8/site-packages/tornado/platform/asyncio.py", line 189, in _handle_events
    handler_func(fileobj, events)
  File "/home/martinm/nib_ckn/venv/lib/python3.8/site-packages/terminado/management.py", line 239, in pty_read
    client.on_pty_read(s)
  File "/home/martinm/nib_ckn/venv/lib/python3.8/site-packages/terminado/websocket.py", line 77, in on_pty_read
    self.send_json_message(['stdout', text])
  File "/home/martinm/nib_ckn/venv/lib/python3.8/site-packages/terminado/websocket.py", line 87, in send_json_message
    self.write_message(json_msg)
  File "/home/martinm/nib_ckn/venv/lib/python3.8/site-packages/jupyter_server/terminal/handlers.py", line 32, in write_message
    super(TermSocket, self).write_message(message, binary=binary)
  File "/home/martinm/nib_ckn/venv/lib/python3.8/site-packages/tornado/websocket.py", line 337, in write_message
    raise WebSocketClosedError()
tornado.websocket.WebSocketClosedError
Exception in callback BaseAsyncIOLoop._handle_events(11, 1)
handle: <Handle BaseAsyncIOLoop._handle_events(11, 1)>
Traceback (most recent call last):
  File "/usr/lib/python3.8/asyncio/events.py", line 81, in _run
    self._context.run(self._callback, *self._args)
  File "/home/martinm/nib_ckn/venv/lib/python3.8/site-packages/tornado/platform/asyncio.py", line 189, in _handle_events
    handler_func(fileobj, events)
  File "/home/martinm/nib_ckn/venv/lib/python3.8/site-packages/terminado/management.py", line 239, in pty_read
    client.on_pty_read(s)
  File "/home/martinm/nib_ckn/venv/lib/python3.8/site-packages/terminado/websocket.py", line 77, in on_pty_read
    self.send_json_message(['stdout', text])
  File "/home/martinm/nib_ckn/venv/lib/python3.8/site-packages/terminado/websocket.py", line 87, in send_json_message
    self.write_message(json_msg)
  File "/home/martinm/nib_ckn/venv/lib/python3.8/site-packages/jupyter_server/terminal/handlers.py", line 32, in write_message
    super(TermSocket, self).write_message(message, binary=binary)
  File "/home/martinm/nib_ckn/venv/lib/python3.8/site-packages/tornado/websocket.py", line 337, in write_message
    raise WebSocketClosedError()
tornado.websocket.WebSocketClosedError
Exception in callback BaseAsyncIOLoop._handle_events(11, 1)
handle: <Handle BaseAsyncIOLoop._handle_events(11, 1)>
Traceback (most recent call last):
  File "/usr/lib/python3.8/asyncio/events.py", line 81, in _run
    self._context.run(self._callback, *self._args)
  File "/home/martinm/nib_ckn/venv/lib/python3.8/site-packages/tornado/platform/asyncio.py", line 189, in _handle_events
    handler_func(fileobj, events)
  File "/home/martinm/nib_ckn/venv/lib/python3.8/site-packages/terminado/management.py", line 239, in pty_read
    client.on_pty_read(s)
  File "/home/martinm/nib_ckn/venv/lib/python3.8/site-packages/terminado/websocket.py", line 77, in on_pty_read
    self.send_json_message(['stdout', text])
  File "/home/martinm/nib_ckn/venv/lib/python3.8/site-packages/terminado/websocket.py", line 87, in send_json_message
    self.write_message(json_msg)
  File "/home/martinm/nib_ckn/venv/lib/python3.8/site-packages/jupyter_server/terminal/handlers.py", line 32, in write_message
    super(TermSocket, self).write_message(message, binary=binary)
  File "/home/martinm/nib_ckn/venv/lib/python3.8/site-packages/tornado/websocket.py", line 337, in write_message
    raise WebSocketClosedError()
tornado.websocket.WebSocketClosedError
Exception in callback BaseAsyncIOLoop._handle_events(11, 1)
handle: <Handle BaseAsyncIOLoop._handle_events(11, 1)>
Traceback (most recent call last):
  File "/usr/lib/python3.8/asyncio/events.py", line 81, in _run
    self._context.run(self._callback, *self._args)
  File "/home/martinm/nib_ckn/venv/lib/python3.8/site-packages/tornado/platform/asyncio.py", line 189, in _handle_events
    handler_func(fileobj, events)
  File "/home/martinm/nib_ckn/venv/lib/python3.8/site-packages/terminado/management.py", line 239, in pty_read
    client.on_pty_read(s)
  File "/home/martinm/nib_ckn/venv/lib/python3.8/site-packages/terminado/websocket.py", line 77, in on_pty_read
    self.send_json_message(['stdout', text])
  File "/home/martinm/nib_ckn/venv/lib/python3.8/site-packages/terminado/websocket.py", line 87, in send_json_message
    self.write_message(json_msg)
  File "/home/martinm/nib_ckn/venv/lib/python3.8/site-packages/jupyter_server/terminal/handlers.py", line 32, in write_message
    super(TermSocket, self).write_message(message, binary=binary)
  File "/home/martinm/nib_ckn/venv/lib/python3.8/site-packages/tornado/websocket.py", line 337, in write_message
    raise WebSocketClosedError()
tornado.websocket.WebSocketClosedError
Websocket closed
[I 2022-05-10 16:08:29.352 ServerApp] Starting buffering for 8565f97b-4475-4ca8-b587-6b4f91e58f79:11ef63cb-e919-4a04-b685-2f4ea43d14e9
[I 2022-05-10 16:08:29.367 ServerApp] Starting buffering for 647008f7-aa33-44dd-ade0-50cc70575078:402826f6-f0e7-4998-9baa-a149f0ad60f1
[I 2022-05-10 16:08:29.383 ServerApp] Starting buffering for 22cb9088-ff57-4b06-8683-9bc24b4520ea:1cae8674-ac42-4e04-803e-5bca0dad3ca0
[I 2022-05-10 16:08:29.399 ServerApp] Starting buffering for 31dea182-d7ee-4bf1-96de-2879d9a39214:fb9b83bd-3664-4824-a681-ff5f42fa96e8
Websocket closed
[W 2022-05-16 11:54:43.295 ServerApp] Forbidden
[W 2022-05-16 11:54:43.295 ServerApp] 403 GET /api/contents/data?content=1&1652694915079 (127.0.0.1) 0.88ms referer=http://localhost:9001/lab/tree/notebooks/CKN-LinkPred_5_6.ipynb
[W 2022-05-16 11:54:45.390 ServerApp] Forbidden
[W 2022-05-16 11:54:45.391 ServerApp] 403 GET /api/terminals?1652694917182 (127.0.0.1) 0.64ms referer=http://localhost:9001/lab/tree/notebooks/CKN-LinkPred_5_6.ipynb
[I 2022-05-16 11:54:46.576 LabApp] 302 GET /lab/tree/notebooks/CKN-LinkPred_5_6.ipynb (127.0.0.1) 0.56ms
[I 2022-05-16 11:54:54.582 ServerApp] 302 POST /login?next=%2Flab%2Ftree%2Fnotebooks%2FCKN-LinkPred_5_6.ipynb (127.0.0.1) 18.29ms
[W 2022-05-16 11:54:58.013 LabApp] Could not determine jupyterlab build status without nodejs
TermSocket.open: 1
not able to serialize: expected string or bytes-like object
TermSocket.open: Opened 1
[W 2022-05-16 11:55:01.900 ServerApp] Notebook notebooks/CKN-LinkPred-GCN_1_0.ipynb is not trusted
TermSocket.open: 2
not able to serialize: expected string or bytes-like object
TermSocket.open: Opened 2
[I 2022-05-16 11:56:02.546 ServerApp] New terminal with automatic name: 3
TermSocket.open: 3
not able to serialize: expected string or bytes-like object
TermSocket.open: Opened 3
[W 2022-05-16 11:56:29.210 ServerApp] WebSocket ping timeout after 90000 ms.
Exception in callback BaseAsyncIOLoop._handle_events(11, 1)
handle: <Handle BaseAsyncIOLoop._handle_events(11, 1)>
Traceback (most recent call last):
  File "/usr/lib/python3.8/asyncio/events.py", line 81, in _run
    self._context.run(self._callback, *self._args)
  File "/home/martinm/nib_ckn/venv/lib/python3.8/site-packages/tornado/platform/asyncio.py", line 189, in _handle_events
    handler_func(fileobj, events)
  File "/home/martinm/nib_ckn/venv/lib/python3.8/site-packages/terminado/management.py", line 239, in pty_read
    client.on_pty_read(s)
  File "/home/martinm/nib_ckn/venv/lib/python3.8/site-packages/terminado/websocket.py", line 77, in on_pty_read
    self.send_json_message(['stdout', text])
  File "/home/martinm/nib_ckn/venv/lib/python3.8/site-packages/terminado/websocket.py", line 87, in send_json_message
    self.write_message(json_msg)
  File "/home/martinm/nib_ckn/venv/lib/python3.8/site-packages/jupyter_server/terminal/handlers.py", line 32, in write_message
    super(TermSocket, self).write_message(message, binary=binary)
  File "/home/martinm/nib_ckn/venv/lib/python3.8/site-packages/tornado/websocket.py", line 337, in write_message
    raise WebSocketClosedError()
tornado.websocket.WebSocketClosedError
Exception in callback BaseAsyncIOLoop._handle_events(11, 1)
handle: <Handle BaseAsyncIOLoop._handle_events(11, 1)>
Traceback (most recent call last):
  File "/usr/lib/python3.8/asyncio/events.py", line 81, in _run
    self._context.run(self._callback, *self._args)
  File "/home/martinm/nib_ckn/venv/lib/python3.8/site-packages/tornado/platform/asyncio.py", line 189, in _handle_events
    handler_func(fileobj, events)
  File "/home/martinm/nib_ckn/venv/lib/python3.8/site-packages/terminado/management.py", line 239, in pty_read
    client.on_pty_read(s)
  File "/home/martinm/nib_ckn/venv/lib/python3.8/site-packages/terminado/websocket.py", line 77, in on_pty_read
    self.send_json_message(['stdout', text])
  File "/home/martinm/nib_ckn/venv/lib/python3.8/site-packages/terminado/websocket.py", line 87, in send_json_message
    self.write_message(json_msg)
  File "/home/martinm/nib_ckn/venv/lib/python3.8/site-packages/jupyter_server/terminal/handlers.py", line 32, in write_message
    super(TermSocket, self).write_message(message, binary=binary)
  File "/home/martinm/nib_ckn/venv/lib/python3.8/site-packages/tornado/websocket.py", line 337, in write_message
    raise WebSocketClosedError()
tornado.websocket.WebSocketClosedError
Exception in callback BaseAsyncIOLoop._handle_events(11, 1)
handle: <Handle BaseAsyncIOLoop._handle_events(11, 1)>
Traceback (most recent call last):
  File "/usr/lib/python3.8/asyncio/events.py", line 81, in _run
    self._context.run(self._callback, *self._args)
  File "/home/martinm/nib_ckn/venv/lib/python3.8/site-packages/tornado/platform/asyncio.py", line 189, in _handle_events
    handler_func(fileobj, events)
  File "/home/martinm/nib_ckn/venv/lib/python3.8/site-packages/terminado/management.py", line 239, in pty_read
    client.on_pty_read(s)
  File "/home/martinm/nib_ckn/venv/lib/python3.8/site-packages/terminado/websocket.py", line 77, in on_pty_read
    self.send_json_message(['stdout', text])
  File "/home/martinm/nib_ckn/venv/lib/python3.8/site-packages/terminado/websocket.py", line 87, in send_json_message
    self.write_message(json_msg)
  File "/home/martinm/nib_ckn/venv/lib/python3.8/site-packages/jupyter_server/terminal/handlers.py", line 32, in write_message
    super(TermSocket, self).write_message(message, binary=binary)
  File "/home/martinm/nib_ckn/venv/lib/python3.8/site-packages/tornado/websocket.py", line 337, in write_message
    raise WebSocketClosedError()
tornado.websocket.WebSocketClosedError
Exception in callback BaseAsyncIOLoop._handle_events(11, 1)
handle: <Handle BaseAsyncIOLoop._handle_events(11, 1)>
Traceback (most recent call last):
  File "/usr/lib/python3.8/asyncio/events.py", line 81, in _run
    self._context.run(self._callback, *self._args)
  File "/home/martinm/nib_ckn/venv/lib/python3.8/site-packages/tornado/platform/asyncio.py", line 189, in _handle_events
    handler_func(fileobj, events)
  File "/home/martinm/nib_ckn/venv/lib/python3.8/site-packages/terminado/management.py", line 239, in pty_read
    client.on_pty_read(s)
  File "/home/martinm/nib_ckn/venv/lib/python3.8/site-packages/terminado/websocket.py", line 77, in on_pty_read
    self.send_json_message(['stdout', text])
  File "/home/martinm/nib_ckn/venv/lib/python3.8/site-packages/terminado/websocket.py", line 87, in send_json_message
    self.write_message(json_msg)
  File "/home/martinm/nib_ckn/venv/lib/python3.8/site-packages/jupyter_server/terminal/handlers.py", line 32, in write_message
    super(TermSocket, self).write_message(message, binary=binary)
  File "/home/martinm/nib_ckn/venv/lib/python3.8/site-packages/tornado/websocket.py", line 337, in write_message
    raise WebSocketClosedError()
tornado.websocket.WebSocketClosedError
Websocket closed
TermSocket.open: 1
not able to serialize: expected string or bytes-like object
TermSocket.open: Opened 1
[I 2022-05-16 12:03:04.238 ServerApp] Saving file at /notebooks/CKN-LinkPred_5_6.ipynb
[I 2022-05-16 12:05:50.206 ServerApp] Copying notebooks/CKN-LinkPred_5_6.ipynb to /notebooks
[I 2022-05-16 12:06:13.959 ServerApp] Copying notebooks/CKN-LinkPred_5_7.ipynb to /notebooks
Task exception was never retrieved
future: <Task finished name='Task-2971602' coro=<WebSocketProtocol13.write_message.<locals>.wrapper() done, defined at /home/martinm/nib_ckn/venv/lib/python3.8/site-packages/tornado/websocket.py:1100> exception=WebSocketClosedError()>
Traceback (most recent call last):
  File "/home/martinm/nib_ckn/venv/lib/python3.8/site-packages/tornado/websocket.py", line 1102, in wrapper
    await fut
  File "/usr/lib/python3.8/asyncio/tasks.py", line 349, in __wakeup
    future.result()
tornado.iostream.StreamClosedError: Stream is closed

During handling of the above exception, another exception occurred:

Traceback (most recent call last):
  File "/usr/lib/python3.8/asyncio/tasks.py", line 282, in __step
    result = coro.throw(exc)
  File "/home/martinm/nib_ckn/venv/lib/python3.8/site-packages/tornado/websocket.py", line 1104, in wrapper
    raise WebSocketClosedError()
tornado.websocket.WebSocketClosedError
Task exception was never retrieved
future: <Task finished name='Task-2971624' coro=<WebSocketProtocol13.write_message.<locals>.wrapper() done, defined at /home/martinm/nib_ckn/venv/lib/python3.8/site-packages/tornado/websocket.py:1100> exception=WebSocketClosedError()>
Traceback (most recent call last):
  File "/home/martinm/nib_ckn/venv/lib/python3.8/site-packages/tornado/websocket.py", line 1102, in wrapper
    await fut
  File "/usr/lib/python3.8/asyncio/tasks.py", line 349, in __wakeup
    future.result()
tornado.iostream.StreamClosedError: Stream is closed

During handling of the above exception, another exception occurred:

Traceback (most recent call last):
  File "/usr/lib/python3.8/asyncio/tasks.py", line 282, in __step
    result = coro.throw(exc)
  File "/home/martinm/nib_ckn/venv/lib/python3.8/site-packages/tornado/websocket.py", line 1104, in wrapper
    raise WebSocketClosedError()
tornado.websocket.WebSocketClosedError
Task exception was never retrieved
future: <Task finished name='Task-2971657' coro=<WebSocketProtocol13.write_message.<locals>.wrapper() done, defined at /home/martinm/nib_ckn/venv/lib/python3.8/site-packages/tornado/websocket.py:1100> exception=WebSocketClosedError()>
Traceback (most recent call last):
  File "/home/martinm/nib_ckn/venv/lib/python3.8/site-packages/tornado/websocket.py", line 1102, in wrapper
    await fut
  File "/usr/lib/python3.8/asyncio/tasks.py", line 349, in __wakeup
    future.result()
tornado.iostream.StreamClosedError: Stream is closed

During handling of the above exception, another exception occurred:

Traceback (most recent call last):
  File "/usr/lib/python3.8/asyncio/tasks.py", line 282, in __step
    result = coro.throw(exc)
  File "/home/martinm/nib_ckn/venv/lib/python3.8/site-packages/tornado/websocket.py", line 1104, in wrapper
    raise WebSocketClosedError()
tornado.websocket.WebSocketClosedError
Task exception was never retrieved
future: <Task finished name='Task-2971658' coro=<WebSocketProtocol13.write_message.<locals>.wrapper() done, defined at /home/martinm/nib_ckn/venv/lib/python3.8/site-packages/tornado/websocket.py:1100> exception=WebSocketClosedError()>
Traceback (most recent call last):
  File "/home/martinm/nib_ckn/venv/lib/python3.8/site-packages/tornado/websocket.py", line 1102, in wrapper
    await fut
  File "/usr/lib/python3.8/asyncio/tasks.py", line 349, in __wakeup
    future.result()
tornado.iostream.StreamClosedError: Stream is closed

During handling of the above exception, another exception occurred:

Traceback (most recent call last):
  File "/usr/lib/python3.8/asyncio/tasks.py", line 282, in __step
    result = coro.throw(exc)
  File "/home/martinm/nib_ckn/venv/lib/python3.8/site-packages/tornado/websocket.py", line 1104, in wrapper
    raise WebSocketClosedError()
tornado.websocket.WebSocketClosedError
Task exception was never retrieved
future: <Task finished name='Task-2971686' coro=<WebSocketProtocol13.write_message.<locals>.wrapper() done, defined at /home/martinm/nib_ckn/venv/lib/python3.8/site-packages/tornado/websocket.py:1100> exception=WebSocketClosedError()>
Traceback (most recent call last):
  File "/home/martinm/nib_ckn/venv/lib/python3.8/site-packages/tornado/websocket.py", line 1102, in wrapper
    await fut
  File "/usr/lib/python3.8/asyncio/tasks.py", line 349, in __wakeup
    future.result()
tornado.iostream.StreamClosedError: Stream is closed

During handling of the above exception, another exception occurred:

Traceback (most recent call last):
  File "/usr/lib/python3.8/asyncio/tasks.py", line 282, in __step
    result = coro.throw(exc)
  File "/home/martinm/nib_ckn/venv/lib/python3.8/site-packages/tornado/websocket.py", line 1104, in wrapper
    raise WebSocketClosedError()
tornado.websocket.WebSocketClosedError
Task exception was never retrieved
future: <Task finished name='Task-2971687' coro=<WebSocketProtocol13.write_message.<locals>.wrapper() done, defined at /home/martinm/nib_ckn/venv/lib/python3.8/site-packages/tornado/websocket.py:1100> exception=WebSocketClosedError()>
Traceback (most recent call last):
  File "/home/martinm/nib_ckn/venv/lib/python3.8/site-packages/tornado/websocket.py", line 1102, in wrapper
    await fut
  File "/usr/lib/python3.8/asyncio/tasks.py", line 349, in __wakeup
    future.result()
tornado.iostream.StreamClosedError: Stream is closed

During handling of the above exception, another exception occurred:

Traceback (most recent call last):
  File "/usr/lib/python3.8/asyncio/tasks.py", line 282, in __step
    result = coro.throw(exc)
  File "/home/martinm/nib_ckn/venv/lib/python3.8/site-packages/tornado/websocket.py", line 1104, in wrapper
    raise WebSocketClosedError()
tornado.websocket.WebSocketClosedError
Task exception was never retrieved
future: <Task finished name='Task-2971693' coro=<WebSocketProtocol13.write_message.<locals>.wrapper() done, defined at /home/martinm/nib_ckn/venv/lib/python3.8/site-packages/tornado/websocket.py:1100> exception=WebSocketClosedError()>
Traceback (most recent call last):
  File "/home/martinm/nib_ckn/venv/lib/python3.8/site-packages/tornado/websocket.py", line 1102, in wrapper
    await fut
  File "/usr/lib/python3.8/asyncio/tasks.py", line 349, in __wakeup
    future.result()
tornado.iostream.StreamClosedError: Stream is closed

During handling of the above exception, another exception occurred:

Traceback (most recent call last):
  File "/usr/lib/python3.8/asyncio/tasks.py", line 282, in __step
    result = coro.throw(exc)
  File "/home/martinm/nib_ckn/venv/lib/python3.8/site-packages/tornado/websocket.py", line 1104, in wrapper
    raise WebSocketClosedError()
tornado.websocket.WebSocketClosedError
Task exception was never retrieved
future: <Task finished name='Task-2971702' coro=<WebSocketProtocol13.write_message.<locals>.wrapper() done, defined at /home/martinm/nib_ckn/venv/lib/python3.8/site-packages/tornado/websocket.py:1100> exception=WebSocketClosedError()>
Traceback (most recent call last):
  File "/home/martinm/nib_ckn/venv/lib/python3.8/site-packages/tornado/websocket.py", line 1102, in wrapper
    await fut
  File "/usr/lib/python3.8/asyncio/tasks.py", line 349, in __wakeup
    future.result()
tornado.iostream.StreamClosedError: Stream is closed

During handling of the above exception, another exception occurred:

Traceback (most recent call last):
  File "/usr/lib/python3.8/asyncio/tasks.py", line 282, in __step
    result = coro.throw(exc)
  File "/home/martinm/nib_ckn/venv/lib/python3.8/site-packages/tornado/websocket.py", line 1104, in wrapper
    raise WebSocketClosedError()
tornado.websocket.WebSocketClosedError
Task exception was never retrieved
future: <Task finished name='Task-2971705' coro=<WebSocketProtocol13.write_message.<locals>.wrapper() done, defined at /home/martinm/nib_ckn/venv/lib/python3.8/site-packages/tornado/websocket.py:1100> exception=WebSocketClosedError()>
Traceback (most recent call last):
  File "/home/martinm/nib_ckn/venv/lib/python3.8/site-packages/tornado/websocket.py", line 1102, in wrapper
    await fut
  File "/usr/lib/python3.8/asyncio/tasks.py", line 349, in __wakeup
    future.result()
tornado.iostream.StreamClosedError: Stream is closed

During handling of the above exception, another exception occurred:

Traceback (most recent call last):
  File "/usr/lib/python3.8/asyncio/tasks.py", line 282, in __step
    result = coro.throw(exc)
  File "/home/martinm/nib_ckn/venv/lib/python3.8/site-packages/tornado/websocket.py", line 1104, in wrapper
    raise WebSocketClosedError()
tornado.websocket.WebSocketClosedError
Task exception was never retrieved
future: <Task finished name='Task-2971706' coro=<WebSocketProtocol13.write_message.<locals>.wrapper() done, defined at /home/martinm/nib_ckn/venv/lib/python3.8/site-packages/tornado/websocket.py:1100> exception=WebSocketClosedError()>
Traceback (most recent call last):
  File "/home/martinm/nib_ckn/venv/lib/python3.8/site-packages/tornado/websocket.py", line 1102, in wrapper
    await fut
  File "/usr/lib/python3.8/asyncio/tasks.py", line 349, in __wakeup
    future.result()
tornado.iostream.StreamClosedError: Stream is closed

During handling of the above exception, another exception occurred:

Traceback (most recent call last):
  File "/usr/lib/python3.8/asyncio/tasks.py", line 282, in __step
    result = coro.throw(exc)
  File "/home/martinm/nib_ckn/venv/lib/python3.8/site-packages/tornado/websocket.py", line 1104, in wrapper
    raise WebSocketClosedError()
tornado.websocket.WebSocketClosedError
Task exception was never retrieved
future: <Task finished name='Task-2971716' coro=<WebSocketProtocol13.write_message.<locals>.wrapper() done, defined at /home/martinm/nib_ckn/venv/lib/python3.8/site-packages/tornado/websocket.py:1100> exception=WebSocketClosedError()>
Traceback (most recent call last):
  File "/home/martinm/nib_ckn/venv/lib/python3.8/site-packages/tornado/websocket.py", line 1102, in wrapper
    await fut
  File "/usr/lib/python3.8/asyncio/tasks.py", line 349, in __wakeup
    future.result()
tornado.iostream.StreamClosedError: Stream is closed

During handling of the above exception, another exception occurred:

Traceback (most recent call last):
  File "/usr/lib/python3.8/asyncio/tasks.py", line 282, in __step
    result = coro.throw(exc)
  File "/home/martinm/nib_ckn/venv/lib/python3.8/site-packages/tornado/websocket.py", line 1104, in wrapper
    raise WebSocketClosedError()
tornado.websocket.WebSocketClosedError
Task exception was never retrieved
future: <Task finished name='Task-2971719' coro=<WebSocketProtocol13.write_message.<locals>.wrapper() done, defined at /home/martinm/nib_ckn/venv/lib/python3.8/site-packages/tornado/websocket.py:1100> exception=WebSocketClosedError()>
Traceback (most recent call last):
  File "/home/martinm/nib_ckn/venv/lib/python3.8/site-packages/tornado/websocket.py", line 1102, in wrapper
    await fut
  File "/usr/lib/python3.8/asyncio/tasks.py", line 349, in __wakeup
    future.result()
tornado.iostream.StreamClosedError: Stream is closed

During handling of the above exception, another exception occurred:

Traceback (most recent call last):
  File "/usr/lib/python3.8/asyncio/tasks.py", line 282, in __step
    result = coro.throw(exc)
  File "/home/martinm/nib_ckn/venv/lib/python3.8/site-packages/tornado/websocket.py", line 1104, in wrapper
    raise WebSocketClosedError()
tornado.websocket.WebSocketClosedError
Task exception was never retrieved
future: <Task finished name='Task-2971730' coro=<WebSocketProtocol13.write_message.<locals>.wrapper() done, defined at /home/martinm/nib_ckn/venv/lib/python3.8/site-packages/tornado/websocket.py:1100> exception=WebSocketClosedError()>
Traceback (most recent call last):
  File "/home/martinm/nib_ckn/venv/lib/python3.8/site-packages/tornado/websocket.py", line 1102, in wrapper
    await fut
  File "/usr/lib/python3.8/asyncio/tasks.py", line 349, in __wakeup
    future.result()
tornado.iostream.StreamClosedError: Stream is closed

During handling of the above exception, another exception occurred:

Traceback (most recent call last):
  File "/usr/lib/python3.8/asyncio/tasks.py", line 282, in __step
    result = coro.throw(exc)
  File "/home/martinm/nib_ckn/venv/lib/python3.8/site-packages/tornado/websocket.py", line 1104, in wrapper
    raise WebSocketClosedError()
tornado.websocket.WebSocketClosedError
Task exception was never retrieved
future: <Task finished name='Task-2971735' coro=<WebSocketProtocol13.write_message.<locals>.wrapper() done, defined at /home/martinm/nib_ckn/venv/lib/python3.8/site-packages/tornado/websocket.py:1100> exception=WebSocketClosedError()>
Traceback (most recent call last):
  File "/home/martinm/nib_ckn/venv/lib/python3.8/site-packages/tornado/websocket.py", line 1102, in wrapper
    await fut
  File "/usr/lib/python3.8/asyncio/tasks.py", line 349, in __wakeup
    future.result()
tornado.iostream.StreamClosedError: Stream is closed

During handling of the above exception, another exception occurred:

Traceback (most recent call last):
  File "/usr/lib/python3.8/asyncio/tasks.py", line 282, in __step
    result = coro.throw(exc)
  File "/home/martinm/nib_ckn/venv/lib/python3.8/site-packages/tornado/websocket.py", line 1104, in wrapper
    raise WebSocketClosedError()
tornado.websocket.WebSocketClosedError
Task exception was never retrieved
future: <Task finished name='Task-2971745' coro=<WebSocketProtocol13.write_message.<locals>.wrapper() done, defined at /home/martinm/nib_ckn/venv/lib/python3.8/site-packages/tornado/websocket.py:1100> exception=WebSocketClosedError()>
Traceback (most recent call last):
  File "/home/martinm/nib_ckn/venv/lib/python3.8/site-packages/tornado/websocket.py", line 1102, in wrapper
    await fut
  File "/usr/lib/python3.8/asyncio/tasks.py", line 349, in __wakeup
    future.result()
tornado.iostream.StreamClosedError: Stream is closed

During handling of the above exception, another exception occurred:

Traceback (most recent call last):
  File "/usr/lib/python3.8/asyncio/tasks.py", line 282, in __step
    result = coro.throw(exc)
  File "/home/martinm/nib_ckn/venv/lib/python3.8/site-packages/tornado/websocket.py", line 1104, in wrapper
    raise WebSocketClosedError()
tornado.websocket.WebSocketClosedError
Task exception was never retrieved
future: <Task finished name='Task-2971747' coro=<WebSocketProtocol13.write_message.<locals>.wrapper() done, defined at /home/martinm/nib_ckn/venv/lib/python3.8/site-packages/tornado/websocket.py:1100> exception=WebSocketClosedError()>
Traceback (most recent call last):
  File "/home/martinm/nib_ckn/venv/lib/python3.8/site-packages/tornado/websocket.py", line 1102, in wrapper
    await fut
  File "/usr/lib/python3.8/asyncio/tasks.py", line 349, in __wakeup
    future.result()
tornado.iostream.StreamClosedError: Stream is closed

During handling of the above exception, another exception occurred:

Traceback (most recent call last):
  File "/usr/lib/python3.8/asyncio/tasks.py", line 282, in __step
    result = coro.throw(exc)
  File "/home/martinm/nib_ckn/venv/lib/python3.8/site-packages/tornado/websocket.py", line 1104, in wrapper
    raise WebSocketClosedError()
tornado.websocket.WebSocketClosedError
Task exception was never retrieved
future: <Task finished name='Task-2971757' coro=<WebSocketProtocol13.write_message.<locals>.wrapper() done, defined at /home/martinm/nib_ckn/venv/lib/python3.8/site-packages/tornado/websocket.py:1100> exception=WebSocketClosedError()>
Traceback (most recent call last):
  File "/home/martinm/nib_ckn/venv/lib/python3.8/site-packages/tornado/websocket.py", line 1102, in wrapper
    await fut
  File "/usr/lib/python3.8/asyncio/tasks.py", line 349, in __wakeup
    future.result()
tornado.iostream.StreamClosedError: Stream is closed

During handling of the above exception, another exception occurred:

Traceback (most recent call last):
  File "/usr/lib/python3.8/asyncio/tasks.py", line 282, in __step
    result = coro.throw(exc)
  File "/home/martinm/nib_ckn/venv/lib/python3.8/site-packages/tornado/websocket.py", line 1104, in wrapper
    raise WebSocketClosedError()
tornado.websocket.WebSocketClosedError
Task exception was never retrieved
future: <Task finished name='Task-2971760' coro=<WebSocketProtocol13.write_message.<locals>.wrapper() done, defined at /home/martinm/nib_ckn/venv/lib/python3.8/site-packages/tornado/websocket.py:1100> exception=WebSocketClosedError()>
Traceback (most recent call last):
  File "/home/martinm/nib_ckn/venv/lib/python3.8/site-packages/tornado/websocket.py", line 1102, in wrapper
    await fut
  File "/usr/lib/python3.8/asyncio/tasks.py", line 349, in __wakeup
    future.result()
tornado.iostream.StreamClosedError: Stream is closed

During handling of the above exception, another exception occurred:

Traceback (most recent call last):
  File "/usr/lib/python3.8/asyncio/tasks.py", line 282, in __step
    result = coro.throw(exc)
  File "/home/martinm/nib_ckn/venv/lib/python3.8/site-packages/tornado/websocket.py", line 1104, in wrapper
    raise WebSocketClosedError()
tornado.websocket.WebSocketClosedError
Task exception was never retrieved
future: <Task finished name='Task-2971770' coro=<WebSocketProtocol13.write_message.<locals>.wrapper() done, defined at /home/martinm/nib_ckn/venv/lib/python3.8/site-packages/tornado/websocket.py:1100> exception=WebSocketClosedError()>
Traceback (most recent call last):
  File "/home/martinm/nib_ckn/venv/lib/python3.8/site-packages/tornado/websocket.py", line 1102, in wrapper
    await fut
  File "/usr/lib/python3.8/asyncio/tasks.py", line 349, in __wakeup
    future.result()
tornado.iostream.StreamClosedError: Stream is closed

During handling of the above exception, another exception occurred:

Traceback (most recent call last):
  File "/usr/lib/python3.8/asyncio/tasks.py", line 282, in __step
    result = coro.throw(exc)
  File "/home/martinm/nib_ckn/venv/lib/python3.8/site-packages/tornado/websocket.py", line 1104, in wrapper
    raise WebSocketClosedError()
tornado.websocket.WebSocketClosedError
Task exception was never retrieved
future: <Task finished name='Task-2971774' coro=<WebSocketProtocol13.write_message.<locals>.wrapper() done, defined at /home/martinm/nib_ckn/venv/lib/python3.8/site-packages/tornado/websocket.py:1100> exception=WebSocketClosedError()>
Traceback (most recent call last):
  File "/home/martinm/nib_ckn/venv/lib/python3.8/site-packages/tornado/websocket.py", line 1102, in wrapper
    await fut
  File "/usr/lib/python3.8/asyncio/tasks.py", line 349, in __wakeup
    future.result()
tornado.iostream.StreamClosedError: Stream is closed

During handling of the above exception, another exception occurred:

Traceback (most recent call last):
  File "/usr/lib/python3.8/asyncio/tasks.py", line 282, in __step
    result = coro.throw(exc)
  File "/home/martinm/nib_ckn/venv/lib/python3.8/site-packages/tornado/websocket.py", line 1104, in wrapper
    raise WebSocketClosedError()
tornado.websocket.WebSocketClosedError
Task exception was never retrieved
future: <Task finished name='Task-2971785' coro=<WebSocketProtocol13.write_message.<locals>.wrapper() done, defined at /home/martinm/nib_ckn/venv/lib/python3.8/site-packages/tornado/websocket.py:1100> exception=WebSocketClosedError()>
Traceback (most recent call last):
  File "/home/martinm/nib_ckn/venv/lib/python3.8/site-packages/tornado/websocket.py", line 1102, in wrapper
    await fut
  File "/usr/lib/python3.8/asyncio/tasks.py", line 349, in __wakeup
    future.result()
tornado.iostream.StreamClosedError: Stream is closed

During handling of the above exception, another exception occurred:

Traceback (most recent call last):
  File "/usr/lib/python3.8/asyncio/tasks.py", line 282, in __step
    result = coro.throw(exc)
  File "/home/martinm/nib_ckn/venv/lib/python3.8/site-packages/tornado/websocket.py", line 1104, in wrapper
    raise WebSocketClosedError()
tornado.websocket.WebSocketClosedError
Task exception was never retrieved
future: <Task finished name='Task-2971791' coro=<WebSocketProtocol13.write_message.<locals>.wrapper() done, defined at /home/martinm/nib_ckn/venv/lib/python3.8/site-packages/tornado/websocket.py:1100> exception=WebSocketClosedError()>
Traceback (most recent call last):
  File "/home/martinm/nib_ckn/venv/lib/python3.8/site-packages/tornado/websocket.py", line 1102, in wrapper
    await fut
  File "/usr/lib/python3.8/asyncio/tasks.py", line 349, in __wakeup
    future.result()
tornado.iostream.StreamClosedError: Stream is closed

During handling of the above exception, another exception occurred:

Traceback (most recent call last):
  File "/usr/lib/python3.8/asyncio/tasks.py", line 282, in __step
    result = coro.throw(exc)
  File "/home/martinm/nib_ckn/venv/lib/python3.8/site-packages/tornado/websocket.py", line 1104, in wrapper
    raise WebSocketClosedError()
tornado.websocket.WebSocketClosedError
Task exception was never retrieved
future: <Task finished name='Task-2971801' coro=<WebSocketProtocol13.write_message.<locals>.wrapper() done, defined at /home/martinm/nib_ckn/venv/lib/python3.8/site-packages/tornado/websocket.py:1100> exception=WebSocketClosedError()>
Traceback (most recent call last):
  File "/home/martinm/nib_ckn/venv/lib/python3.8/site-packages/tornado/websocket.py", line 1102, in wrapper
    await fut
  File "/usr/lib/python3.8/asyncio/tasks.py", line 349, in __wakeup
    future.result()
tornado.iostream.StreamClosedError: Stream is closed

During handling of the above exception, another exception occurred:

Traceback (most recent call last):
  File "/usr/lib/python3.8/asyncio/tasks.py", line 282, in __step
    result = coro.throw(exc)
  File "/home/martinm/nib_ckn/venv/lib/python3.8/site-packages/tornado/websocket.py", line 1104, in wrapper
    raise WebSocketClosedError()
tornado.websocket.WebSocketClosedError
Task exception was never retrieved
future: <Task finished name='Task-2971807' coro=<WebSocketProtocol13.write_message.<locals>.wrapper() done, defined at /home/martinm/nib_ckn/venv/lib/python3.8/site-packages/tornado/websocket.py:1100> exception=WebSocketClosedError()>
Traceback (most recent call last):
  File "/home/martinm/nib_ckn/venv/lib/python3.8/site-packages/tornado/websocket.py", line 1102, in wrapper
    await fut
  File "/usr/lib/python3.8/asyncio/tasks.py", line 349, in __wakeup
    future.result()
tornado.iostream.StreamClosedError: Stream is closed

During handling of the above exception, another exception occurred:

Traceback (most recent call last):
  File "/usr/lib/python3.8/asyncio/tasks.py", line 282, in __step
    result = coro.throw(exc)
  File "/home/martinm/nib_ckn/venv/lib/python3.8/site-packages/tornado/websocket.py", line 1104, in wrapper
    raise WebSocketClosedError()
tornado.websocket.WebSocketClosedError
Task exception was never retrieved
future: <Task finished name='Task-2971813' coro=<WebSocketProtocol13.write_message.<locals>.wrapper() done, defined at /home/martinm/nib_ckn/venv/lib/python3.8/site-packages/tornado/websocket.py:1100> exception=WebSocketClosedError()>
Traceback (most recent call last):
  File "/home/martinm/nib_ckn/venv/lib/python3.8/site-packages/tornado/websocket.py", line 1102, in wrapper
    await fut
  File "/usr/lib/python3.8/asyncio/tasks.py", line 349, in __wakeup
    future.result()
tornado.iostream.StreamClosedError: Stream is closed

During handling of the above exception, another exception occurred:

Traceback (most recent call last):
  File "/usr/lib/python3.8/asyncio/tasks.py", line 282, in __step
    result = coro.throw(exc)
  File "/home/martinm/nib_ckn/venv/lib/python3.8/site-packages/tornado/websocket.py", line 1104, in wrapper
    raise WebSocketClosedError()
tornado.websocket.WebSocketClosedError
Task exception was never retrieved
future: <Task finished name='Task-2971820' coro=<WebSocketProtocol13.write_message.<locals>.wrapper() done, defined at /home/martinm/nib_ckn/venv/lib/python3.8/site-packages/tornado/websocket.py:1100> exception=WebSocketClosedError()>
Traceback (most recent call last):
  File "/home/martinm/nib_ckn/venv/lib/python3.8/site-packages/tornado/websocket.py", line 1102, in wrapper
    await fut
  File "/usr/lib/python3.8/asyncio/tasks.py", line 349, in __wakeup
    future.result()
tornado.iostream.StreamClosedError: Stream is closed

During handling of the above exception, another exception occurred:

Traceback (most recent call last):
  File "/usr/lib/python3.8/asyncio/tasks.py", line 282, in __step
    result = coro.throw(exc)
  File "/home/martinm/nib_ckn/venv/lib/python3.8/site-packages/tornado/websocket.py", line 1104, in wrapper
    raise WebSocketClosedError()
tornado.websocket.WebSocketClosedError
Task exception was never retrieved
future: <Task finished name='Task-2971830' coro=<WebSocketProtocol13.write_message.<locals>.wrapper() done, defined at /home/martinm/nib_ckn/venv/lib/python3.8/site-packages/tornado/websocket.py:1100> exception=WebSocketClosedError()>
Traceback (most recent call last):
  File "/home/martinm/nib_ckn/venv/lib/python3.8/site-packages/tornado/websocket.py", line 1102, in wrapper
    await fut
  File "/usr/lib/python3.8/asyncio/tasks.py", line 349, in __wakeup
    future.result()
tornado.iostream.StreamClosedError: Stream is closed

During handling of the above exception, another exception occurred:

Traceback (most recent call last):
  File "/usr/lib/python3.8/asyncio/tasks.py", line 282, in __step
    result = coro.throw(exc)
  File "/home/martinm/nib_ckn/venv/lib/python3.8/site-packages/tornado/websocket.py", line 1104, in wrapper
    raise WebSocketClosedError()
tornado.websocket.WebSocketClosedError
Task exception was never retrieved
future: <Task finished name='Task-2971831' coro=<WebSocketProtocol13.write_message.<locals>.wrapper() done, defined at /home/martinm/nib_ckn/venv/lib/python3.8/site-packages/tornado/websocket.py:1100> exception=WebSocketClosedError()>
Traceback (most recent call last):
  File "/home/martinm/nib_ckn/venv/lib/python3.8/site-packages/tornado/websocket.py", line 1102, in wrapper
    await fut
  File "/usr/lib/python3.8/asyncio/tasks.py", line 349, in __wakeup
    future.result()
tornado.iostream.StreamClosedError: Stream is closed

During handling of the above exception, another exception occurred:

Traceback (most recent call last):
  File "/usr/lib/python3.8/asyncio/tasks.py", line 282, in __step
    result = coro.throw(exc)
  File "/home/martinm/nib_ckn/venv/lib/python3.8/site-packages/tornado/websocket.py", line 1104, in wrapper
    raise WebSocketClosedError()
tornado.websocket.WebSocketClosedError
Task exception was never retrieved
future: <Task finished name='Task-2971847' coro=<WebSocketProtocol13.write_message.<locals>.wrapper() done, defined at /home/martinm/nib_ckn/venv/lib/python3.8/site-packages/tornado/websocket.py:1100> exception=WebSocketClosedError()>
Traceback (most recent call last):
  File "/home/martinm/nib_ckn/venv/lib/python3.8/site-packages/tornado/websocket.py", line 1102, in wrapper
    await fut
  File "/usr/lib/python3.8/asyncio/tasks.py", line 349, in __wakeup
    future.result()
tornado.iostream.StreamClosedError: Stream is closed

During handling of the above exception, another exception occurred:

Traceback (most recent call last):
  File "/usr/lib/python3.8/asyncio/tasks.py", line 282, in __step
    result = coro.throw(exc)
  File "/home/martinm/nib_ckn/venv/lib/python3.8/site-packages/tornado/websocket.py", line 1104, in wrapper
    raise WebSocketClosedError()
tornado.websocket.WebSocketClosedError
Task exception was never retrieved
future: <Task finished name='Task-2971852' coro=<WebSocketProtocol13.write_message.<locals>.wrapper() done, defined at /home/martinm/nib_ckn/venv/lib/python3.8/site-packages/tornado/websocket.py:1100> exception=WebSocketClosedError()>
Traceback (most recent call last):
  File "/home/martinm/nib_ckn/venv/lib/python3.8/site-packages/tornado/websocket.py", line 1102, in wrapper
    await fut
  File "/usr/lib/python3.8/asyncio/tasks.py", line 349, in __wakeup
    future.result()
tornado.iostream.StreamClosedError: Stream is closed

During handling of the above exception, another exception occurred:

Traceback (most recent call last):
  File "/usr/lib/python3.8/asyncio/tasks.py", line 282, in __step
    result = coro.throw(exc)
  File "/home/martinm/nib_ckn/venv/lib/python3.8/site-packages/tornado/websocket.py", line 1104, in wrapper
    raise WebSocketClosedError()
tornado.websocket.WebSocketClosedError
Task exception was never retrieved
future: <Task finished name='Task-2971860' coro=<WebSocketProtocol13.write_message.<locals>.wrapper() done, defined at /home/martinm/nib_ckn/venv/lib/python3.8/site-packages/tornado/websocket.py:1100> exception=WebSocketClosedError()>
Traceback (most recent call last):
  File "/home/martinm/nib_ckn/venv/lib/python3.8/site-packages/tornado/websocket.py", line 1102, in wrapper
    await fut
  File "/usr/lib/python3.8/asyncio/tasks.py", line 349, in __wakeup
    future.result()
tornado.iostream.StreamClosedError: Stream is closed

During handling of the above exception, another exception occurred:

Traceback (most recent call last):
  File "/usr/lib/python3.8/asyncio/tasks.py", line 282, in __step
    result = coro.throw(exc)
  File "/home/martinm/nib_ckn/venv/lib/python3.8/site-packages/tornado/websocket.py", line 1104, in wrapper
    raise WebSocketClosedError()
tornado.websocket.WebSocketClosedError
Task exception was never retrieved
future: <Task finished name='Task-2971864' coro=<WebSocketProtocol13.write_message.<locals>.wrapper() done, defined at /home/martinm/nib_ckn/venv/lib/python3.8/site-packages/tornado/websocket.py:1100> exception=WebSocketClosedError()>
Traceback (most recent call last):
  File "/home/martinm/nib_ckn/venv/lib/python3.8/site-packages/tornado/websocket.py", line 1102, in wrapper
    await fut
  File "/usr/lib/python3.8/asyncio/tasks.py", line 349, in __wakeup
    future.result()
tornado.iostream.StreamClosedError: Stream is closed

During handling of the above exception, another exception occurred:

Traceback (most recent call last):
  File "/usr/lib/python3.8/asyncio/tasks.py", line 282, in __step
    result = coro.throw(exc)
  File "/home/martinm/nib_ckn/venv/lib/python3.8/site-packages/tornado/websocket.py", line 1104, in wrapper
    raise WebSocketClosedError()
tornado.websocket.WebSocketClosedError
Task exception was never retrieved
future: <Task finished name='Task-2971872' coro=<WebSocketProtocol13.write_message.<locals>.wrapper() done, defined at /home/martinm/nib_ckn/venv/lib/python3.8/site-packages/tornado/websocket.py:1100> exception=WebSocketClosedError()>
Traceback (most recent call last):
  File "/home/martinm/nib_ckn/venv/lib/python3.8/site-packages/tornado/websocket.py", line 1102, in wrapper
    await fut
  File "/usr/lib/python3.8/asyncio/tasks.py", line 349, in __wakeup
    future.result()
tornado.iostream.StreamClosedError: Stream is closed

During handling of the above exception, another exception occurred:

Traceback (most recent call last):
  File "/usr/lib/python3.8/asyncio/tasks.py", line 282, in __step
    result = coro.throw(exc)
  File "/home/martinm/nib_ckn/venv/lib/python3.8/site-packages/tornado/websocket.py", line 1104, in wrapper
    raise WebSocketClosedError()
tornado.websocket.WebSocketClosedError
Task exception was never retrieved
future: <Task finished name='Task-2971877' coro=<WebSocketProtocol13.write_message.<locals>.wrapper() done, defined at /home/martinm/nib_ckn/venv/lib/python3.8/site-packages/tornado/websocket.py:1100> exception=WebSocketClosedError()>
Traceback (most recent call last):
  File "/home/martinm/nib_ckn/venv/lib/python3.8/site-packages/tornado/websocket.py", line 1102, in wrapper
    await fut
  File "/usr/lib/python3.8/asyncio/tasks.py", line 349, in __wakeup
    future.result()
tornado.iostream.StreamClosedError: Stream is closed

During handling of the above exception, another exception occurred:

Traceback (most recent call last):
  File "/usr/lib/python3.8/asyncio/tasks.py", line 282, in __step
    result = coro.throw(exc)
  File "/home/martinm/nib_ckn/venv/lib/python3.8/site-packages/tornado/websocket.py", line 1104, in wrapper
    raise WebSocketClosedError()
tornado.websocket.WebSocketClosedError
Task exception was never retrieved
future: <Task finished name='Task-2971887' coro=<WebSocketProtocol13.write_message.<locals>.wrapper() done, defined at /home/martinm/nib_ckn/venv/lib/python3.8/site-packages/tornado/websocket.py:1100> exception=WebSocketClosedError()>
Traceback (most recent call last):
  File "/home/martinm/nib_ckn/venv/lib/python3.8/site-packages/tornado/websocket.py", line 1102, in wrapper
    await fut
  File "/usr/lib/python3.8/asyncio/tasks.py", line 349, in __wakeup
    future.result()
tornado.iostream.StreamClosedError: Stream is closed

During handling of the above exception, another exception occurred:

Traceback (most recent call last):
  File "/usr/lib/python3.8/asyncio/tasks.py", line 282, in __step
    result = coro.throw(exc)
  File "/home/martinm/nib_ckn/venv/lib/python3.8/site-packages/tornado/websocket.py", line 1104, in wrapper
    raise WebSocketClosedError()
tornado.websocket.WebSocketClosedError
Task exception was never retrieved
future: <Task finished name='Task-2971893' coro=<WebSocketProtocol13.write_message.<locals>.wrapper() done, defined at /home/martinm/nib_ckn/venv/lib/python3.8/site-packages/tornado/websocket.py:1100> exception=WebSocketClosedError()>
Traceback (most recent call last):
  File "/home/martinm/nib_ckn/venv/lib/python3.8/site-packages/tornado/websocket.py", line 1102, in wrapper
    await fut
  File "/usr/lib/python3.8/asyncio/tasks.py", line 349, in __wakeup
    future.result()
tornado.iostream.StreamClosedError: Stream is closed

During handling of the above exception, another exception occurred:

Traceback (most recent call last):
  File "/usr/lib/python3.8/asyncio/tasks.py", line 282, in __step
    result = coro.throw(exc)
  File "/home/martinm/nib_ckn/venv/lib/python3.8/site-packages/tornado/websocket.py", line 1104, in wrapper
    raise WebSocketClosedError()
tornado.websocket.WebSocketClosedError
Task exception was never retrieved
future: <Task finished name='Task-2971903' coro=<WebSocketProtocol13.write_message.<locals>.wrapper() done, defined at /home/martinm/nib_ckn/venv/lib/python3.8/site-packages/tornado/websocket.py:1100> exception=WebSocketClosedError()>
Traceback (most recent call last):
  File "/home/martinm/nib_ckn/venv/lib/python3.8/site-packages/tornado/websocket.py", line 1102, in wrapper
    await fut
  File "/usr/lib/python3.8/asyncio/tasks.py", line 349, in __wakeup
    future.result()
tornado.iostream.StreamClosedError: Stream is closed

During handling of the above exception, another exception occurred:

Traceback (most recent call last):
  File "/usr/lib/python3.8/asyncio/tasks.py", line 282, in __step
    result = coro.throw(exc)
  File "/home/martinm/nib_ckn/venv/lib/python3.8/site-packages/tornado/websocket.py", line 1104, in wrapper
    raise WebSocketClosedError()
tornado.websocket.WebSocketClosedError
Task exception was never retrieved
future: <Task finished name='Task-2971906' coro=<WebSocketProtocol13.write_message.<locals>.wrapper() done, defined at /home/martinm/nib_ckn/venv/lib/python3.8/site-packages/tornado/websocket.py:1100> exception=WebSocketClosedError()>
Traceback (most recent call last):
  File "/home/martinm/nib_ckn/venv/lib/python3.8/site-packages/tornado/websocket.py", line 1102, in wrapper
    await fut
  File "/usr/lib/python3.8/asyncio/tasks.py", line 349, in __wakeup
    future.result()
tornado.iostream.StreamClosedError: Stream is closed

During handling of the above exception, another exception occurred:

Traceback (most recent call last):
  File "/usr/lib/python3.8/asyncio/tasks.py", line 282, in __step
    result = coro.throw(exc)
  File "/home/martinm/nib_ckn/venv/lib/python3.8/site-packages/tornado/websocket.py", line 1104, in wrapper
    raise WebSocketClosedError()
tornado.websocket.WebSocketClosedError
Task exception was never retrieved
future: <Task finished name='Task-2971916' coro=<WebSocketProtocol13.write_message.<locals>.wrapper() done, defined at /home/martinm/nib_ckn/venv/lib/python3.8/site-packages/tornado/websocket.py:1100> exception=WebSocketClosedError()>
Traceback (most recent call last):
  File "/home/martinm/nib_ckn/venv/lib/python3.8/site-packages/tornado/websocket.py", line 1102, in wrapper
    await fut
  File "/usr/lib/python3.8/asyncio/tasks.py", line 349, in __wakeup
    future.result()
tornado.iostream.StreamClosedError: Stream is closed

During handling of the above exception, another exception occurred:

Traceback (most recent call last):
  File "/usr/lib/python3.8/asyncio/tasks.py", line 282, in __step
    result = coro.throw(exc)
  File "/home/martinm/nib_ckn/venv/lib/python3.8/site-packages/tornado/websocket.py", line 1104, in wrapper
    raise WebSocketClosedError()
tornado.websocket.WebSocketClosedError
Task exception was never retrieved
future: <Task finished name='Task-2971923' coro=<WebSocketProtocol13.write_message.<locals>.wrapper() done, defined at /home/martinm/nib_ckn/venv/lib/python3.8/site-packages/tornado/websocket.py:1100> exception=WebSocketClosedError()>
Traceback (most recent call last):
  File "/home/martinm/nib_ckn/venv/lib/python3.8/site-packages/tornado/websocket.py", line 1102, in wrapper
    await fut
  File "/usr/lib/python3.8/asyncio/tasks.py", line 349, in __wakeup
    future.result()
tornado.iostream.StreamClosedError: Stream is closed

During handling of the above exception, another exception occurred:

Traceback (most recent call last):
  File "/usr/lib/python3.8/asyncio/tasks.py", line 282, in __step
    result = coro.throw(exc)
  File "/home/martinm/nib_ckn/venv/lib/python3.8/site-packages/tornado/websocket.py", line 1104, in wrapper
    raise WebSocketClosedError()
tornado.websocket.WebSocketClosedError
Task exception was never retrieved
future: <Task finished name='Task-2971932' coro=<WebSocketProtocol13.write_message.<locals>.wrapper() done, defined at /home/martinm/nib_ckn/venv/lib/python3.8/site-packages/tornado/websocket.py:1100> exception=WebSocketClosedError()>
Traceback (most recent call last):
  File "/home/martinm/nib_ckn/venv/lib/python3.8/site-packages/tornado/websocket.py", line 1102, in wrapper
    await fut
  File "/usr/lib/python3.8/asyncio/tasks.py", line 349, in __wakeup
    future.result()
tornado.iostream.StreamClosedError: Stream is closed

During handling of the above exception, another exception occurred:

Traceback (most recent call last):
  File "/usr/lib/python3.8/asyncio/tasks.py", line 282, in __step
    result = coro.throw(exc)
  File "/home/martinm/nib_ckn/venv/lib/python3.8/site-packages/tornado/websocket.py", line 1104, in wrapper
    raise WebSocketClosedError()
tornado.websocket.WebSocketClosedError
Task exception was never retrieved
future: <Task finished name='Task-2971941' coro=<WebSocketProtocol13.write_message.<locals>.wrapper() done, defined at /home/martinm/nib_ckn/venv/lib/python3.8/site-packages/tornado/websocket.py:1100> exception=WebSocketClosedError()>
Traceback (most recent call last):
  File "/home/martinm/nib_ckn/venv/lib/python3.8/site-packages/tornado/websocket.py", line 1102, in wrapper
    await fut
  File "/usr/lib/python3.8/asyncio/tasks.py", line 349, in __wakeup
    future.result()
tornado.iostream.StreamClosedError: Stream is closed

During handling of the above exception, another exception occurred:

Traceback (most recent call last):
  File "/usr/lib/python3.8/asyncio/tasks.py", line 282, in __step
    result = coro.throw(exc)
  File "/home/martinm/nib_ckn/venv/lib/python3.8/site-packages/tornado/websocket.py", line 1104, in wrapper
    raise WebSocketClosedError()
tornado.websocket.WebSocketClosedError
Task exception was never retrieved
future: <Task finished name='Task-2971948' coro=<WebSocketProtocol13.write_message.<locals>.wrapper() done, defined at /home/martinm/nib_ckn/venv/lib/python3.8/site-packages/tornado/websocket.py:1100> exception=WebSocketClosedError()>
Traceback (most recent call last):
  File "/home/martinm/nib_ckn/venv/lib/python3.8/site-packages/tornado/websocket.py", line 1102, in wrapper
    await fut
  File "/usr/lib/python3.8/asyncio/tasks.py", line 349, in __wakeup
    future.result()
tornado.iostream.StreamClosedError: Stream is closed

During handling of the above exception, another exception occurred:

Traceback (most recent call last):
  File "/usr/lib/python3.8/asyncio/tasks.py", line 282, in __step
    result = coro.throw(exc)
  File "/home/martinm/nib_ckn/venv/lib/python3.8/site-packages/tornado/websocket.py", line 1104, in wrapper
    raise WebSocketClosedError()
tornado.websocket.WebSocketClosedError
Task exception was never retrieved
future: <Task finished name='Task-2971949' coro=<WebSocketProtocol13.write_message.<locals>.wrapper() done, defined at /home/martinm/nib_ckn/venv/lib/python3.8/site-packages/tornado/websocket.py:1100> exception=WebSocketClosedError()>
Traceback (most recent call last):
  File "/home/martinm/nib_ckn/venv/lib/python3.8/site-packages/tornado/websocket.py", line 1102, in wrapper
    await fut
  File "/usr/lib/python3.8/asyncio/tasks.py", line 349, in __wakeup
    future.result()
tornado.iostream.StreamClosedError: Stream is closed

During handling of the above exception, another exception occurred:

Traceback (most recent call last):
  File "/usr/lib/python3.8/asyncio/tasks.py", line 282, in __step
    result = coro.throw(exc)
  File "/home/martinm/nib_ckn/venv/lib/python3.8/site-packages/tornado/websocket.py", line 1104, in wrapper
    raise WebSocketClosedError()
tornado.websocket.WebSocketClosedError
Task exception was never retrieved
future: <Task finished name='Task-2971962' coro=<WebSocketProtocol13.write_message.<locals>.wrapper() done, defined at /home/martinm/nib_ckn/venv/lib/python3.8/site-packages/tornado/websocket.py:1100> exception=WebSocketClosedError()>
Traceback (most recent call last):
  File "/home/martinm/nib_ckn/venv/lib/python3.8/site-packages/tornado/websocket.py", line 1102, in wrapper
    await fut
  File "/usr/lib/python3.8/asyncio/tasks.py", line 349, in __wakeup
    future.result()
tornado.iostream.StreamClosedError: Stream is closed

During handling of the above exception, another exception occurred:

Traceback (most recent call last):
  File "/usr/lib/python3.8/asyncio/tasks.py", line 282, in __step
    result = coro.throw(exc)
  File "/home/martinm/nib_ckn/venv/lib/python3.8/site-packages/tornado/websocket.py", line 1104, in wrapper
    raise WebSocketClosedError()
tornado.websocket.WebSocketClosedError
Task exception was never retrieved
future: <Task finished name='Task-2971963' coro=<WebSocketProtocol13.write_message.<locals>.wrapper() done, defined at /home/martinm/nib_ckn/venv/lib/python3.8/site-packages/tornado/websocket.py:1100> exception=WebSocketClosedError()>
Traceback (most recent call last):
  File "/home/martinm/nib_ckn/venv/lib/python3.8/site-packages/tornado/websocket.py", line 1102, in wrapper
    await fut
  File "/usr/lib/python3.8/asyncio/tasks.py", line 349, in __wakeup
    future.result()
tornado.iostream.StreamClosedError: Stream is closed

During handling of the above exception, another exception occurred:

Traceback (most recent call last):
  File "/usr/lib/python3.8/asyncio/tasks.py", line 282, in __step
    result = coro.throw(exc)
  File "/home/martinm/nib_ckn/venv/lib/python3.8/site-packages/tornado/websocket.py", line 1104, in wrapper
    raise WebSocketClosedError()
tornado.websocket.WebSocketClosedError
Task exception was never retrieved
future: <Task finished name='Task-2971969' coro=<WebSocketProtocol13.write_message.<locals>.wrapper() done, defined at /home/martinm/nib_ckn/venv/lib/python3.8/site-packages/tornado/websocket.py:1100> exception=WebSocketClosedError()>
Traceback (most recent call last):
  File "/home/martinm/nib_ckn/venv/lib/python3.8/site-packages/tornado/websocket.py", line 1102, in wrapper
    await fut
  File "/usr/lib/python3.8/asyncio/tasks.py", line 349, in __wakeup
    future.result()
tornado.iostream.StreamClosedError: Stream is closed

During handling of the above exception, another exception occurred:

Traceback (most recent call last):
  File "/usr/lib/python3.8/asyncio/tasks.py", line 282, in __step
    result = coro.throw(exc)
  File "/home/martinm/nib_ckn/venv/lib/python3.8/site-packages/tornado/websocket.py", line 1104, in wrapper
    raise WebSocketClosedError()
tornado.websocket.WebSocketClosedError
Task exception was never retrieved
future: <Task finished name='Task-2971979' coro=<WebSocketProtocol13.write_message.<locals>.wrapper() done, defined at /home/martinm/nib_ckn/venv/lib/python3.8/site-packages/tornado/websocket.py:1100> exception=WebSocketClosedError()>
Traceback (most recent call last):
  File "/home/martinm/nib_ckn/venv/lib/python3.8/site-packages/tornado/websocket.py", line 1102, in wrapper
    await fut
  File "/usr/lib/python3.8/asyncio/tasks.py", line 349, in __wakeup
    future.result()
tornado.iostream.StreamClosedError: Stream is closed

During handling of the above exception, another exception occurred:

Traceback (most recent call last):
  File "/usr/lib/python3.8/asyncio/tasks.py", line 282, in __step
    result = coro.throw(exc)
  File "/home/martinm/nib_ckn/venv/lib/python3.8/site-packages/tornado/websocket.py", line 1104, in wrapper
    raise WebSocketClosedError()
tornado.websocket.WebSocketClosedError
Task exception was never retrieved
future: <Task finished name='Task-2971980' coro=<WebSocketProtocol13.write_message.<locals>.wrapper() done, defined at /home/martinm/nib_ckn/venv/lib/python3.8/site-packages/tornado/websocket.py:1100> exception=WebSocketClosedError()>
Traceback (most recent call last):
  File "/home/martinm/nib_ckn/venv/lib/python3.8/site-packages/tornado/websocket.py", line 1102, in wrapper
    await fut
  File "/usr/lib/python3.8/asyncio/tasks.py", line 349, in __wakeup
    future.result()
tornado.iostream.StreamClosedError: Stream is closed

During handling of the above exception, another exception occurred:

Traceback (most recent call last):
  File "/usr/lib/python3.8/asyncio/tasks.py", line 282, in __step
    result = coro.throw(exc)
  File "/home/martinm/nib_ckn/venv/lib/python3.8/site-packages/tornado/websocket.py", line 1104, in wrapper
    raise WebSocketClosedError()
tornado.websocket.WebSocketClosedError
Task exception was never retrieved
future: <Task finished name='Task-2971989' coro=<WebSocketProtocol13.write_message.<locals>.wrapper() done, defined at /home/martinm/nib_ckn/venv/lib/python3.8/site-packages/tornado/websocket.py:1100> exception=WebSocketClosedError()>
Traceback (most recent call last):
  File "/home/martinm/nib_ckn/venv/lib/python3.8/site-packages/tornado/websocket.py", line 1102, in wrapper
    await fut
  File "/usr/lib/python3.8/asyncio/tasks.py", line 349, in __wakeup
    future.result()
tornado.iostream.StreamClosedError: Stream is closed

During handling of the above exception, another exception occurred:

Traceback (most recent call last):
  File "/usr/lib/python3.8/asyncio/tasks.py", line 282, in __step
    result = coro.throw(exc)
  File "/home/martinm/nib_ckn/venv/lib/python3.8/site-packages/tornado/websocket.py", line 1104, in wrapper
    raise WebSocketClosedError()
tornado.websocket.WebSocketClosedError
Task exception was never retrieved
future: <Task finished name='Task-2971999' coro=<WebSocketProtocol13.write_message.<locals>.wrapper() done, defined at /home/martinm/nib_ckn/venv/lib/python3.8/site-packages/tornado/websocket.py:1100> exception=WebSocketClosedError()>
Traceback (most recent call last):
  File "/home/martinm/nib_ckn/venv/lib/python3.8/site-packages/tornado/websocket.py", line 1102, in wrapper
    await fut
  File "/usr/lib/python3.8/asyncio/tasks.py", line 349, in __wakeup
    future.result()
tornado.iostream.StreamClosedError: Stream is closed

During handling of the above exception, another exception occurred:

Traceback (most recent call last):
  File "/usr/lib/python3.8/asyncio/tasks.py", line 282, in __step
    result = coro.throw(exc)
  File "/home/martinm/nib_ckn/venv/lib/python3.8/site-packages/tornado/websocket.py", line 1104, in wrapper
    raise WebSocketClosedError()
tornado.websocket.WebSocketClosedError
Task exception was never retrieved
future: <Task finished name='Task-2972006' coro=<WebSocketProtocol13.write_message.<locals>.wrapper() done, defined at /home/martinm/nib_ckn/venv/lib/python3.8/site-packages/tornado/websocket.py:1100> exception=WebSocketClosedError()>
Traceback (most recent call last):
  File "/home/martinm/nib_ckn/venv/lib/python3.8/site-packages/tornado/websocket.py", line 1102, in wrapper
    await fut
  File "/usr/lib/python3.8/asyncio/tasks.py", line 349, in __wakeup
    future.result()
tornado.iostream.StreamClosedError: Stream is closed

During handling of the above exception, another exception occurred:

Traceback (most recent call last):
  File "/usr/lib/python3.8/asyncio/tasks.py", line 282, in __step
    result = coro.throw(exc)
  File "/home/martinm/nib_ckn/venv/lib/python3.8/site-packages/tornado/websocket.py", line 1104, in wrapper
    raise WebSocketClosedError()
tornado.websocket.WebSocketClosedError
Task exception was never retrieved
future: <Task finished name='Task-2972023' coro=<WebSocketProtocol13.write_message.<locals>.wrapper() done, defined at /home/martinm/nib_ckn/venv/lib/python3.8/site-packages/tornado/websocket.py:1100> exception=WebSocketClosedError()>
Traceback (most recent call last):
  File "/home/martinm/nib_ckn/venv/lib/python3.8/site-packages/tornado/websocket.py", line 1102, in wrapper
    await fut
  File "/usr/lib/python3.8/asyncio/tasks.py", line 349, in __wakeup
    future.result()
tornado.iostream.StreamClosedError: Stream is closed

During handling of the above exception, another exception occurred:

Traceback (most recent call last):
  File "/usr/lib/python3.8/asyncio/tasks.py", line 282, in __step
    result = coro.throw(exc)
  File "/home/martinm/nib_ckn/venv/lib/python3.8/site-packages/tornado/websocket.py", line 1104, in wrapper
    raise WebSocketClosedError()
tornado.websocket.WebSocketClosedError
Task exception was never retrieved
future: <Task finished name='Task-2972029' coro=<WebSocketProtocol13.write_message.<locals>.wrapper() done, defined at /home/martinm/nib_ckn/venv/lib/python3.8/site-packages/tornado/websocket.py:1100> exception=WebSocketClosedError()>
Traceback (most recent call last):
  File "/home/martinm/nib_ckn/venv/lib/python3.8/site-packages/tornado/websocket.py", line 1102, in wrapper
    await fut
  File "/usr/lib/python3.8/asyncio/tasks.py", line 349, in __wakeup
    future.result()
tornado.iostream.StreamClosedError: Stream is closed

During handling of the above exception, another exception occurred:

Traceback (most recent call last):
  File "/usr/lib/python3.8/asyncio/tasks.py", line 282, in __step
    result = coro.throw(exc)
  File "/home/martinm/nib_ckn/venv/lib/python3.8/site-packages/tornado/websocket.py", line 1104, in wrapper
    raise WebSocketClosedError()
tornado.websocket.WebSocketClosedError
Task exception was never retrieved
future: <Task finished name='Task-2972030' coro=<WebSocketProtocol13.write_message.<locals>.wrapper() done, defined at /home/martinm/nib_ckn/venv/lib/python3.8/site-packages/tornado/websocket.py:1100> exception=WebSocketClosedError()>
Traceback (most recent call last):
  File "/home/martinm/nib_ckn/venv/lib/python3.8/site-packages/tornado/websocket.py", line 1102, in wrapper
    await fut
  File "/usr/lib/python3.8/asyncio/tasks.py", line 349, in __wakeup
    future.result()
tornado.iostream.StreamClosedError: Stream is closed

During handling of the above exception, another exception occurred:

Traceback (most recent call last):
  File "/usr/lib/python3.8/asyncio/tasks.py", line 282, in __step
    result = coro.throw(exc)
  File "/home/martinm/nib_ckn/venv/lib/python3.8/site-packages/tornado/websocket.py", line 1104, in wrapper
    raise WebSocketClosedError()
tornado.websocket.WebSocketClosedError
Task exception was never retrieved
future: <Task finished name='Task-2972040' coro=<WebSocketProtocol13.write_message.<locals>.wrapper() done, defined at /home/martinm/nib_ckn/venv/lib/python3.8/site-packages/tornado/websocket.py:1100> exception=WebSocketClosedError()>
Traceback (most recent call last):
  File "/home/martinm/nib_ckn/venv/lib/python3.8/site-packages/tornado/websocket.py", line 1102, in wrapper
    await fut
  File "/usr/lib/python3.8/asyncio/tasks.py", line 349, in __wakeup
    future.result()
tornado.iostream.StreamClosedError: Stream is closed

During handling of the above exception, another exception occurred:

Traceback (most recent call last):
  File "/usr/lib/python3.8/asyncio/tasks.py", line 282, in __step
    result = coro.throw(exc)
  File "/home/martinm/nib_ckn/venv/lib/python3.8/site-packages/tornado/websocket.py", line 1104, in wrapper
    raise WebSocketClosedError()
tornado.websocket.WebSocketClosedError
Task exception was never retrieved
future: <Task finished name='Task-2972046' coro=<WebSocketProtocol13.write_message.<locals>.wrapper() done, defined at /home/martinm/nib_ckn/venv/lib/python3.8/site-packages/tornado/websocket.py:1100> exception=WebSocketClosedError()>
Traceback (most recent call last):
  File "/home/martinm/nib_ckn/venv/lib/python3.8/site-packages/tornado/websocket.py", line 1102, in wrapper
    await fut
  File "/usr/lib/python3.8/asyncio/tasks.py", line 349, in __wakeup
    future.result()
tornado.iostream.StreamClosedError: Stream is closed

During handling of the above exception, another exception occurred:

Traceback (most recent call last):
  File "/usr/lib/python3.8/asyncio/tasks.py", line 282, in __step
    result = coro.throw(exc)
  File "/home/martinm/nib_ckn/venv/lib/python3.8/site-packages/tornado/websocket.py", line 1104, in wrapper
    raise WebSocketClosedError()
tornado.websocket.WebSocketClosedError
Task exception was never retrieved
future: <Task finished name='Task-2972058' coro=<WebSocketProtocol13.write_message.<locals>.wrapper() done, defined at /home/martinm/nib_ckn/venv/lib/python3.8/site-packages/tornado/websocket.py:1100> exception=WebSocketClosedError()>
Traceback (most recent call last):
  File "/home/martinm/nib_ckn/venv/lib/python3.8/site-packages/tornado/websocket.py", line 1102, in wrapper
    await fut
  File "/usr/lib/python3.8/asyncio/tasks.py", line 349, in __wakeup
    future.result()
tornado.iostream.StreamClosedError: Stream is closed

During handling of the above exception, another exception occurred:

Traceback (most recent call last):
  File "/usr/lib/python3.8/asyncio/tasks.py", line 282, in __step
    result = coro.throw(exc)
  File "/home/martinm/nib_ckn/venv/lib/python3.8/site-packages/tornado/websocket.py", line 1104, in wrapper
    raise WebSocketClosedError()
tornado.websocket.WebSocketClosedError
Task exception was never retrieved
future: <Task finished name='Task-2972059' coro=<WebSocketProtocol13.write_message.<locals>.wrapper() done, defined at /home/martinm/nib_ckn/venv/lib/python3.8/site-packages/tornado/websocket.py:1100> exception=WebSocketClosedError()>
Traceback (most recent call last):
  File "/home/martinm/nib_ckn/venv/lib/python3.8/site-packages/tornado/websocket.py", line 1102, in wrapper
    await fut
  File "/usr/lib/python3.8/asyncio/tasks.py", line 349, in __wakeup
    future.result()
tornado.iostream.StreamClosedError: Stream is closed

During handling of the above exception, another exception occurred:

Traceback (most recent call last):
  File "/usr/lib/python3.8/asyncio/tasks.py", line 282, in __step
    result = coro.throw(exc)
  File "/home/martinm/nib_ckn/venv/lib/python3.8/site-packages/tornado/websocket.py", line 1104, in wrapper
    raise WebSocketClosedError()
tornado.websocket.WebSocketClosedError
Task exception was never retrieved
future: <Task finished name='Task-2972064' coro=<WebSocketProtocol13.write_message.<locals>.wrapper() done, defined at /home/martinm/nib_ckn/venv/lib/python3.8/site-packages/tornado/websocket.py:1100> exception=WebSocketClosedError()>
Traceback (most recent call last):
  File "/home/martinm/nib_ckn/venv/lib/python3.8/site-packages/tornado/websocket.py", line 1102, in wrapper
    await fut
  File "/usr/lib/python3.8/asyncio/tasks.py", line 349, in __wakeup
    future.result()
tornado.iostream.StreamClosedError: Stream is closed

During handling of the above exception, another exception occurred:

Traceback (most recent call last):
  File "/usr/lib/python3.8/asyncio/tasks.py", line 282, in __step
    result = coro.throw(exc)
  File "/home/martinm/nib_ckn/venv/lib/python3.8/site-packages/tornado/websocket.py", line 1104, in wrapper
    raise WebSocketClosedError()
tornado.websocket.WebSocketClosedError
Task exception was never retrieved
future: <Task finished name='Task-2972066' coro=<WebSocketProtocol13.write_message.<locals>.wrapper() done, defined at /home/martinm/nib_ckn/venv/lib/python3.8/site-packages/tornado/websocket.py:1100> exception=WebSocketClosedError()>
Traceback (most recent call last):
  File "/home/martinm/nib_ckn/venv/lib/python3.8/site-packages/tornado/websocket.py", line 1102, in wrapper
    await fut
  File "/usr/lib/python3.8/asyncio/tasks.py", line 349, in __wakeup
    future.result()
tornado.iostream.StreamClosedError: Stream is closed

During handling of the above exception, another exception occurred:

Traceback (most recent call last):
  File "/usr/lib/python3.8/asyncio/tasks.py", line 282, in __step
    result = coro.throw(exc)
  File "/home/martinm/nib_ckn/venv/lib/python3.8/site-packages/tornado/websocket.py", line 1104, in wrapper
    raise WebSocketClosedError()
tornado.websocket.WebSocketClosedError
Task exception was never retrieved
future: <Task finished name='Task-2972084' coro=<WebSocketProtocol13.write_message.<locals>.wrapper() done, defined at /home/martinm/nib_ckn/venv/lib/python3.8/site-packages/tornado/websocket.py:1100> exception=WebSocketClosedError()>
Traceback (most recent call last):
  File "/home/martinm/nib_ckn/venv/lib/python3.8/site-packages/tornado/websocket.py", line 1102, in wrapper
    await fut
  File "/usr/lib/python3.8/asyncio/tasks.py", line 349, in __wakeup
    future.result()
tornado.iostream.StreamClosedError: Stream is closed

During handling of the above exception, another exception occurred:

Traceback (most recent call last):
  File "/usr/lib/python3.8/asyncio/tasks.py", line 282, in __step
    result = coro.throw(exc)
  File "/home/martinm/nib_ckn/venv/lib/python3.8/site-packages/tornado/websocket.py", line 1104, in wrapper
    raise WebSocketClosedError()
tornado.websocket.WebSocketClosedError
Task exception was never retrieved
future: <Task finished name='Task-2972085' coro=<WebSocketProtocol13.write_message.<locals>.wrapper() done, defined at /home/martinm/nib_ckn/venv/lib/python3.8/site-packages/tornado/websocket.py:1100> exception=WebSocketClosedError()>
Traceback (most recent call last):
  File "/home/martinm/nib_ckn/venv/lib/python3.8/site-packages/tornado/websocket.py", line 1102, in wrapper
    await fut
  File "/usr/lib/python3.8/asyncio/tasks.py", line 349, in __wakeup
    future.result()
tornado.iostream.StreamClosedError: Stream is closed

During handling of the above exception, another exception occurred:

Traceback (most recent call last):
  File "/usr/lib/python3.8/asyncio/tasks.py", line 282, in __step
    result = coro.throw(exc)
  File "/home/martinm/nib_ckn/venv/lib/python3.8/site-packages/tornado/websocket.py", line 1104, in wrapper
    raise WebSocketClosedError()
tornado.websocket.WebSocketClosedError
Task exception was never retrieved
future: <Task finished name='Task-2972098' coro=<WebSocketProtocol13.write_message.<locals>.wrapper() done, defined at /home/martinm/nib_ckn/venv/lib/python3.8/site-packages/tornado/websocket.py:1100> exception=WebSocketClosedError()>
Traceback (most recent call last):
  File "/home/martinm/nib_ckn/venv/lib/python3.8/site-packages/tornado/websocket.py", line 1102, in wrapper
    await fut
  File "/usr/lib/python3.8/asyncio/tasks.py", line 349, in __wakeup
    future.result()
tornado.iostream.StreamClosedError: Stream is closed

During handling of the above exception, another exception occurred:

Traceback (most recent call last):
  File "/usr/lib/python3.8/asyncio/tasks.py", line 282, in __step
    result = coro.throw(exc)
  File "/home/martinm/nib_ckn/venv/lib/python3.8/site-packages/tornado/websocket.py", line 1104, in wrapper
    raise WebSocketClosedError()
tornado.websocket.WebSocketClosedError
Task exception was never retrieved
future: <Task finished name='Task-2972108' coro=<WebSocketProtocol13.write_message.<locals>.wrapper() done, defined at /home/martinm/nib_ckn/venv/lib/python3.8/site-packages/tornado/websocket.py:1100> exception=WebSocketClosedError()>
Traceback (most recent call last):
  File "/home/martinm/nib_ckn/venv/lib/python3.8/site-packages/tornado/websocket.py", line 1102, in wrapper
    await fut
  File "/usr/lib/python3.8/asyncio/tasks.py", line 349, in __wakeup
    future.result()
tornado.iostream.StreamClosedError: Stream is closed

During handling of the above exception, another exception occurred:

Traceback (most recent call last):
  File "/usr/lib/python3.8/asyncio/tasks.py", line 282, in __step
    result = coro.throw(exc)
  File "/home/martinm/nib_ckn/venv/lib/python3.8/site-packages/tornado/websocket.py", line 1104, in wrapper
    raise WebSocketClosedError()
tornado.websocket.WebSocketClosedError
Task exception was never retrieved
future: <Task finished name='Task-2972109' coro=<WebSocketProtocol13.write_message.<locals>.wrapper() done, defined at /home/martinm/nib_ckn/venv/lib/python3.8/site-packages/tornado/websocket.py:1100> exception=WebSocketClosedError()>
Traceback (most recent call last):
  File "/home/martinm/nib_ckn/venv/lib/python3.8/site-packages/tornado/websocket.py", line 1102, in wrapper
    await fut
  File "/usr/lib/python3.8/asyncio/tasks.py", line 349, in __wakeup
    future.result()
tornado.iostream.StreamClosedError: Stream is closed

During handling of the above exception, another exception occurred:

Traceback (most recent call last):
  File "/usr/lib/python3.8/asyncio/tasks.py", line 282, in __step
    result = coro.throw(exc)
  File "/home/martinm/nib_ckn/venv/lib/python3.8/site-packages/tornado/websocket.py", line 1104, in wrapper
    raise WebSocketClosedError()
tornado.websocket.WebSocketClosedError
Task exception was never retrieved
future: <Task finished name='Task-2972115' coro=<WebSocketProtocol13.write_message.<locals>.wrapper() done, defined at /home/martinm/nib_ckn/venv/lib/python3.8/site-packages/tornado/websocket.py:1100> exception=WebSocketClosedError()>
Traceback (most recent call last):
  File "/home/martinm/nib_ckn/venv/lib/python3.8/site-packages/tornado/websocket.py", line 1102, in wrapper
    await fut
  File "/usr/lib/python3.8/asyncio/tasks.py", line 349, in __wakeup
    future.result()
tornado.iostream.StreamClosedError: Stream is closed

During handling of the above exception, another exception occurred:

Traceback (most recent call last):
  File "/usr/lib/python3.8/asyncio/tasks.py", line 282, in __step
    result = coro.throw(exc)
  File "/home/martinm/nib_ckn/venv/lib/python3.8/site-packages/tornado/websocket.py", line 1104, in wrapper
    raise WebSocketClosedError()
tornado.websocket.WebSocketClosedError
Task exception was never retrieved
future: <Task finished name='Task-2972116' coro=<WebSocketProtocol13.write_message.<locals>.wrapper() done, defined at /home/martinm/nib_ckn/venv/lib/python3.8/site-packages/tornado/websocket.py:1100> exception=WebSocketClosedError()>
Traceback (most recent call last):
  File "/home/martinm/nib_ckn/venv/lib/python3.8/site-packages/tornado/websocket.py", line 1102, in wrapper
    await fut
  File "/usr/lib/python3.8/asyncio/tasks.py", line 349, in __wakeup
    future.result()
tornado.iostream.StreamClosedError: Stream is closed

During handling of the above exception, another exception occurred:

Traceback (most recent call last):
  File "/usr/lib/python3.8/asyncio/tasks.py", line 282, in __step
    result = coro.throw(exc)
  File "/home/martinm/nib_ckn/venv/lib/python3.8/site-packages/tornado/websocket.py", line 1104, in wrapper
    raise WebSocketClosedError()
tornado.websocket.WebSocketClosedError
Task exception was never retrieved
future: <Task finished name='Task-2972125' coro=<WebSocketProtocol13.write_message.<locals>.wrapper() done, defined at /home/martinm/nib_ckn/venv/lib/python3.8/site-packages/tornado/websocket.py:1100> exception=WebSocketClosedError()>
Traceback (most recent call last):
  File "/home/martinm/nib_ckn/venv/lib/python3.8/site-packages/tornado/websocket.py", line 1102, in wrapper
    await fut
  File "/usr/lib/python3.8/asyncio/tasks.py", line 349, in __wakeup
    future.result()
tornado.iostream.StreamClosedError: Stream is closed

During handling of the above exception, another exception occurred:

Traceback (most recent call last):
  File "/usr/lib/python3.8/asyncio/tasks.py", line 282, in __step
    result = coro.throw(exc)
  File "/home/martinm/nib_ckn/venv/lib/python3.8/site-packages/tornado/websocket.py", line 1104, in wrapper
    raise WebSocketClosedError()
tornado.websocket.WebSocketClosedError
[I 2022-05-16 12:09:11.568 ServerApp] Uploading file to /data/AtCKN_2022-01-26_mod_v2022-05-16.tsv
[I 2022-05-16 12:09:41.330 ServerApp] Saving file at /data/AtCKN_2022-01-26_mod_v2022-05-16.tsv
[I 2022-05-16 12:16:26.787 ServerApp] Starting buffering for 61583383-730f-45ab-8624-336d68f5d3a2:25187953-def5-4ce9-a0eb-4daa3a8d8d92
[I 2022-05-16 12:16:31.980 ServerApp] Kernel started: 4331871f-920b-4db7-a2cf-65a762719bdc
[I 2022-05-16 12:18:30.855 ServerApp] Saving file at /notebooks/Old-CKN-LinkPred_5_7-.ipynb
2022-05-16 12:20:33.180219: I tensorflow/core/platform/cpu_feature_guard.cc:151] This TensorFlow binary is optimized with oneAPI Deep Neural Network Library (oneDNN) to use the following CPU instructions in performance-critical operations:  AVX2 FMA
To enable them in other operations, rebuild TensorFlow with the appropriate compiler flags.
[I 2022-05-16 12:22:04.110 ServerApp] Starting buffering for 8565f97b-4475-4ca8-b587-6b4f91e58f79:8e97ef83-3e3e-44a3-96e2-325edb6b25d4
[I 2022-05-16 12:22:31.720 ServerApp] Saving file at /notebooks/Old-CKN-LinkPred_5_7-.ipynb
[I 2022-05-16 12:52:07.909 ServerApp] Saving file at /notebooks/Old-CKN-LinkPred_5_7-.ipynb
[I 2022-05-16 13:26:08.382 ServerApp] Saving file at /notebooks/Old-CKN-LinkPred_5_7-.ipynb
[I 2022-05-16 14:52:08.342 ServerApp] Saving file at /notebooks/Old-CKN-LinkPred_5_7-.ipynb
[I 2022-05-16 14:54:08.744 ServerApp] Saving file at /notebooks/Old-CKN-LinkPred_5_7-.ipynb
[I 2022-05-16 15:10:52.443 ServerApp] Starting buffering for 61583383-730f-45ab-8624-336d68f5d3a2:e2872b6d-f049-44eb-84e9-099844d32741
[I 2022-05-16 15:22:08.115 ServerApp] Saving file at /notebooks/CKN-LinkPred_5_6.ipynb
[W 2022-05-16 15:26:35.136 ServerApp] Notebook notebooks/CKN-LinkPred_5_5.ipynb is not trusted
[I 2022-05-16 15:26:56.095 ServerApp] Starting buffering for 0b194552-6bc5-44ee-9d3f-289d15cb1a54:53775674-ac3b-4b59-b100-7773f8cc5c7e
[I 2022-05-16 15:38:09.812 ServerApp] Starting buffering for fe797c7a-c6f5-4b9d-a56a-a198786039b4:4ed5d43a-9def-49d2-9211-c90c2820b286
[I 2022-05-16 15:44:08.383 ServerApp] Saving file at /notebooks/CKN-LinkPred_5_6.ipynb
[W 2022-05-16 15:44:14.522 ServerApp] delete /notebooks/CKN-LinkPred_5_7.ipynb
[I 2022-05-16 15:46:08.691 ServerApp] Saving file at /notebooks/CKN-LinkPred_5_6.ipynb
[I 2022-05-16 15:48:09.605 ServerApp] Saving file at /notebooks/CKN-LinkPred_5_6.ipynb
[I 2022-05-16 15:50:09.844 ServerApp] Saving file at /notebooks/CKN-LinkPred_5_6.ipynb
[I 2022-05-16 15:52:10.108 ServerApp] Saving file at /notebooks/CKN-LinkPred_5_6.ipynb
[I 2022-05-16 15:54:10.820 ServerApp] Saving file at /notebooks/CKN-LinkPred_5_6.ipynb
[I 2022-05-16 15:56:11.075 ServerApp] Saving file at /notebooks/CKN-LinkPred_5_6.ipynb
[I 2022-05-16 16:00:11.378 ServerApp] Saving file at /notebooks/CKN-LinkPred_5_6.ipynb
[I 2022-05-16 16:02:11.645 ServerApp] Saving file at /notebooks/CKN-LinkPred_5_6.ipynb
[I 2022-05-16 16:04:11.919 ServerApp] Saving file at /notebooks/CKN-LinkPred_5_6.ipynb
[I 2022-05-16 16:06:12.191 ServerApp] Saving file at /notebooks/CKN-LinkPred_5_6.ipynb
[I 2022-05-16 16:08:12.626 ServerApp] Saving file at /notebooks/CKN-LinkPred_5_6.ipynb
[I 2022-05-16 16:10:13.733 ServerApp] Saving file at /notebooks/CKN-LinkPred_5_6.ipynb
[I 2022-05-16 16:12:14.131 ServerApp] Saving file at /notebooks/CKN-LinkPred_5_6.ipynb
[I 2022-05-16 16:14:14.948 ServerApp] Saving file at /notebooks/CKN-LinkPred_5_6.ipynb
[I 2022-05-16 16:16:15.229 ServerApp] Saving file at /notebooks/CKN-LinkPred_5_6.ipynb
[I 2022-05-16 16:18:15.609 ServerApp] Saving file at /notebooks/CKN-LinkPred_5_6.ipynb
[I 2022-05-16 16:20:15.920 ServerApp] Saving file at /notebooks/CKN-LinkPred_5_6.ipynb
[I 2022-05-16 16:22:16.233 ServerApp] Saving file at /notebooks/CKN-LinkPred_5_6.ipynb
[I 2022-05-16 16:24:16.454 ServerApp] Saving file at /notebooks/CKN-LinkPred_5_6.ipynb
[I 2022-05-16 16:26:17.748 ServerApp] Saving file at /notebooks/CKN-LinkPred_5_6.ipynb
[I 2022-05-16 16:28:18.152 ServerApp] Saving file at /notebooks/CKN-LinkPred_5_6.ipynb
[I 2022-05-16 16:30:18.527 ServerApp] Saving file at /notebooks/CKN-LinkPred_5_6.ipynb
[I 2022-05-16 16:32:18.826 ServerApp] Saving file at /notebooks/CKN-LinkPred_5_6.ipynb
[I 2022-05-16 16:34:19.188 ServerApp] Saving file at /notebooks/CKN-LinkPred_5_6.ipynb
[I 2022-05-16 16:36:20.052 ServerApp] Saving file at /notebooks/CKN-LinkPred_5_6.ipynb
[I 2022-05-16 16:42:20.464 ServerApp] Saving file at /notebooks/CKN-LinkPred_5_6.ipynb
[I 2022-05-16 16:44:20.828 ServerApp] Saving file at /notebooks/CKN-LinkPred_5_6.ipynb
[I 2022-05-16 16:46:21.875 ServerApp] Saving file at /notebooks/CKN-LinkPred_5_6.ipynb
[I 2022-05-16 16:48:22.350 ServerApp] Saving file at /notebooks/CKN-LinkPred_5_6.ipynb
[I 2022-05-16 16:50:23.439 ServerApp] Saving file at /notebooks/CKN-LinkPred_5_6.ipynb
[I 2022-05-16 16:52:23.835 ServerApp] Saving file at /notebooks/CKN-LinkPred_5_6.ipynb
[I 2022-05-16 16:54:24.056 ServerApp] Saving file at /notebooks/CKN-LinkPred_5_6.ipynb
[I 2022-05-16 16:58:24.363 ServerApp] Saving file at /notebooks/CKN-LinkPred_5_6.ipynb
[I 2022-05-16 17:00:24.733 ServerApp] Saving file at /notebooks/CKN-LinkPred_5_6.ipynb
[I 2022-05-16 17:02:25.071 ServerApp] Saving file at /notebooks/CKN-LinkPred_5_6.ipynb
[I 2022-05-16 17:04:25.459 ServerApp] Saving file at /notebooks/CKN-LinkPred_5_6.ipynb
[I 2022-05-16 17:06:25.775 ServerApp] Saving file at /notebooks/CKN-LinkPred_5_6.ipynb
[I 2022-05-16 17:08:26.037 ServerApp] Saving file at /notebooks/CKN-LinkPred_5_6.ipynb
[I 2022-05-16 17:10:26.339 ServerApp] Saving file at /notebooks/CKN-LinkPred_5_6.ipynb
[I 2022-05-16 17:12:26.648 ServerApp] Saving file at /notebooks/CKN-LinkPred_5_6.ipynb
[I 2022-05-16 17:14:26.976 ServerApp] Saving file at /notebooks/CKN-LinkPred_5_6.ipynb
[I 2022-05-16 17:16:27.253 ServerApp] Saving file at /notebooks/CKN-LinkPred_5_6.ipynb
[I 2022-05-16 17:18:27.535 ServerApp] Saving file at /notebooks/CKN-LinkPred_5_6.ipynb
[I 2022-05-16 17:20:29.008 ServerApp] Saving file at /notebooks/CKN-LinkPred_5_6.ipynb
[I 2022-05-16 17:22:29.434 ServerApp] Saving file at /notebooks/CKN-LinkPred_5_6.ipynb
[I 2022-05-16 17:24:29.745 ServerApp] Saving file at /notebooks/CKN-LinkPred_5_6.ipynb
[I 2022-05-16 17:26:30.926 ServerApp] Saving file at /notebooks/CKN-LinkPred_5_6.ipynb
[I 2022-05-16 17:30:31.810 ServerApp] Saving file at /notebooks/CKN-LinkPred_5_6.ipynb
[I 2022-05-16 17:32:32.072 ServerApp] Saving file at /notebooks/CKN-LinkPred_5_6.ipynb
[I 2022-05-16 17:34:10.838 ServerApp] Saving file at /notebooks/Old-CKN-LinkPred_5_7-.ipynb
Task exception was never retrieved
future: <Task finished name='Task-2971573' coro=<WebSocketProtocol13.write_message.<locals>.wrapper() done, defined at /home/martinm/nib_ckn/venv/lib/python3.8/site-packages/tornado/websocket.py:1100> exception=WebSocketClosedError()>
Traceback (most recent call last):
  File "/home/martinm/nib_ckn/venv/lib/python3.8/site-packages/tornado/websocket.py", line 1102, in wrapper
    await fut
  File "/usr/lib/python3.8/asyncio/tasks.py", line 349, in __wakeup
    future.result()
tornado.iostream.StreamClosedError: Stream is closed

During handling of the above exception, another exception occurred:

Traceback (most recent call last):
  File "/usr/lib/python3.8/asyncio/tasks.py", line 282, in __step
    result = coro.throw(exc)
  File "/home/martinm/nib_ckn/venv/lib/python3.8/site-packages/tornado/websocket.py", line 1104, in wrapper
    raise WebSocketClosedError()
tornado.websocket.WebSocketClosedError
Task exception was never retrieved
future: <Task finished name='Task-2971575' coro=<WebSocketProtocol13.write_message.<locals>.wrapper() done, defined at /home/martinm/nib_ckn/venv/lib/python3.8/site-packages/tornado/websocket.py:1100> exception=WebSocketClosedError()>
Traceback (most recent call last):
  File "/home/martinm/nib_ckn/venv/lib/python3.8/site-packages/tornado/websocket.py", line 1102, in wrapper
    await fut
  File "/usr/lib/python3.8/asyncio/tasks.py", line 349, in __wakeup
    future.result()
tornado.iostream.StreamClosedError: Stream is closed

During handling of the above exception, another exception occurred:

Traceback (most recent call last):
  File "/usr/lib/python3.8/asyncio/tasks.py", line 282, in __step
    result = coro.throw(exc)
  File "/home/martinm/nib_ckn/venv/lib/python3.8/site-packages/tornado/websocket.py", line 1104, in wrapper
    raise WebSocketClosedError()
tornado.websocket.WebSocketClosedError
[I 2022-05-16 17:34:32.498 ServerApp] Saving file at /notebooks/CKN-LinkPred_5_6.ipynb
[I 2022-05-16 17:36:11.231 ServerApp] Saving file at /notebooks/Old-CKN-LinkPred_5_7-.ipynb
[I 2022-05-16 17:36:22.151 ServerApp] Copying notebooks/CKN-LinkPred_5_6.ipynb to /notebooks
[I 2022-05-16 17:36:39.842 ServerApp] Kernel started: dda854b3-7bab-4ca2-b683-7783881be59a
[I 2022-05-16 17:37:48.871 ServerApp] Copying notebooks/CKN-LinkPred_5_7.ipynb to /notebooks
[I 2022-05-16 17:38:39.500 ServerApp] Kernel started: 7a7cef13-f8a1-4e79-8ae8-9ceb9cbd9801
[I 2022-05-16 17:40:38.619 ServerApp] Saving file at /notebooks/CKN_v2022-05-16_LinkPred_5_7.ipynb
[I 2022-05-16 17:44:39.634 ServerApp] Saving file at /notebooks/CKN-LinkPred_5_7.ipynb
[I 2022-05-16 17:46:39.897 ServerApp] Saving file at /notebooks/CKN-LinkPred_5_7.ipynb
[I 2022-05-16 17:48:40.154 ServerApp] Saving file at /notebooks/CKN-LinkPred_5_7.ipynb
[I 2022-05-16 17:50:40.717 ServerApp] Saving file at /notebooks/CKN-LinkPred_5_7.ipynb
[I 2022-05-16 17:52:39.929 ServerApp] Saving file at /notebooks/CKN_v2022-05-16_LinkPred_5_7.ipynb
[I 2022-05-16 17:54:40.191 ServerApp] Saving file at /notebooks/CKN_v2022-05-16_LinkPred_5_7.ipynb
